<?xml version="1.0" encoding="utf-8"?>

<robot name="fetch">

  <material name="white">
    <color rgba="0.1 0.1 0.1 1" />
  </material>

  <material name="grey">
    <color rgba="0.6 0.6 0.6 1" />
  </material>

  <material name="blue">
    <color rgba="0.2 0.3 0.6 1" />
  </material>

  <material name="green">
    <color rgba="0.6 0.5 0.1 1" />
  </material>

  <material name="motor">
    <color rgba="0.02 0.02 0.02 1" />
  </material>

  <link name="root">
    <inertial>
      <mass value="0"/>
      <inertia ixx="0.00" ixy="0.00" ixz="0.00" iyy="0.00" iyz="0.00" izz="0.00"/>
    </inertial>
  </link>

  <link name="root_arm_1_link_1">
    <inertial>
      <mass value="0"/>
      <inertia ixx="0.00" ixy="0.00" ixz="0.00" iyy="0.00" iyz="0.00" izz="0.00"/>
    </inertial>
  </link>

  <link name="root_arm_1_link_2">
    <inertial>
      <mass value="0"/>
      <inertia ixx="0.00" ixy="0.00" ixz="0.00" iyy="0.00" iyz="0.00" izz="0.00"/>
    </inertial>
  </link>

  <joint name="root_x_axis_joint" type="prismatic">
    <parent link="root"/>
    <child link="root_arm_1_link_1"/>
    <axis xyz="1 0 0"/>
    <limit effort="100" lower="-20" upper="20" velocity="0.50"/>
    <dynamics damping="10.0" friction="10"/>
  </joint>

  <joint name="root_y_axis_joint" type="prismatic">
    <parent link="root_arm_1_link_1"/>
    <child link="root_arm_1_link_2"/>
    <axis xyz="0 1 0"/>
    <limit effort="100" lower="-20" upper="20" velocity="0.50"/>
    <dynamics damping="10.0" friction="10"/>
  </joint>

  <joint name="root_z_rotation_joint" type="continuous">
    <parent link="root_arm_1_link_2"/>
    <child link="base_link"/>
    <axis xyz="0 0 1"/>
    <dynamics damping="10.0" friction="1"/>
  </joint>

  <link name="base_link">
    <inertial>
      <origin rpy="0 0 0" xyz="0 0.0 0.38"/>
      <mass value="70.1294"/>
      <inertia ixx="1.225" ixy="0.0099" ixz="0.0062" iyy="1.2853" iyz="-0.0034" izz="0.987"/>
    </inertial>


    <collision>
      <origin rpy="0 0 0" xyz="0 0.22 0.73"/>
      <geometry>
        <box size="0.35 0.01 0.09"/>
      </geometry>
      <material name="green">
      </material>
    </collision>

    <collision>
      <origin rpy="0 0 0" xyz="0 -0.22 0.73"/>
      <geometry>
        <box size="0.35 0.01 0.09"/>
      </geometry>
      <material name="green">
      </material>
    </collision>

    <collision>
      <origin rpy="0 0 0" xyz="0.17 0 0.73"/>
      <geometry>
        <box size="0.01 0.45 0.09"/>
      </geometry>
      <material name="green">
      </material>
    </collision>


    <collision>
      <origin rpy="0 0 0" xyz="-0.17 0 0.73"/>
      <geometry>
        <box size="0.01 0.45 0.09"/>
      </geometry>
      <material name="green">
      </material>
    </collision>
  



    <visual name="raskog">
      <origin
        xyz="-0.01668 0.55732 0.895"
        rpy="1.5708 0 0" />
      <geometry>
        <mesh filename="file://$(find xlerobot_description)/meshes/raskogbody.stl" scale="0.001 0.001 0.001" />
      </geometry>
      <material name="blue">
      </material>
    </visual>

    <visual name="raskogwheel1">
      <origin
        xyz="-0.01668 0.55732 0.895"
        rpy="1.5708 0 0" />
      <geometry>
        <mesh filename="file://$(find xlerobot_description)/meshes/raskogwheel1.stl" scale="0.001 0.001 0.001" />
      </geometry>
      <material name="grey">
      </material>
    </visual>

    <visual name="raskogwheel2">
      <origin
        xyz="-0.01668 0.55732 0.895"
        rpy="1.5708 0 0" />
      <geometry>
        <mesh filename="file://$(find xlerobot_description)/meshes/raskogwheel2.stl" scale="0.001 0.001 0.001" />
      </geometry>
      <material name="motor">
      </material>
    </visual>


    <collision>
      <origin rpy="0 0 0" xyz="0 0 0.05"/>
      <geometry>
        <box size="0.4348 0.51 0.1"/>
      </geometry>
    </collision>

    <collision>
      <origin rpy="0 0 0" xyz="0 0 0.395"/>
      <geometry>
        <box size="0.35 0.45 0.59"/>
      </geometry>
    </collision>

    <collision>
      <origin rpy="0 0 0" xyz="0 -0.24 0.44"/>
      <geometry>
        <box size="0.1 0.04 0.68"/>
      </geometry>
    </collision>

    <collision>
      <origin rpy="0 0 0" xyz="0 0.24 0.44"/>
      <geometry>
        <box size="0.1 0.04 0.68"/>
      </geometry>
    </collision>
  </link>




  <link name="Base">
    <inertial>
      <origin
        xyz="-2.45960666746703E-07 0.0311418169687909 0.0175746661003382"
        rpy="0 0 0" />
      <mass
        value="0.193184127927598" />
      <inertia
        ixx="0.000137030709467877"
        ixy="2.10136126944992E-08"
        ixz="4.24087422551286E-09"
        iyy="0.000169089551209259"
        iyz="2.26514711036514E-05"
        izz="0.000145097720857224" />
    </inertial>
    <visual name="base_link_chassis">
      <origin
        xyz="0 0 0"
        rpy="0 0 0" />
      <geometry>
        <mesh filename="file://$(find xlerobot_description)/meshes/Base.stl" />
      </geometry>
      <material name="white">
      </material>
    </visual>
    <visual name="base_link_motor">
      <origin
        xyz="0 0 0"
        rpy="0 0 0" />
      <geometry>
        <mesh
          filename="file://$(find xlerobot_description)/meshes/Base_Motor.stl" />
      </geometry>
      <material name="motor">
      </material>
    </visual>
    <collision>
      <origin
        xyz="0 0 0"
        rpy="0 0 0" />
      <geometry>
        <mesh
          filename="file://$(find xlerobot_description)/meshes/Base.stl" />
      </geometry>
    </collision>
    <collision>
      <origin
        xyz="0 0 0"
        rpy="0 0 0" />
      <geometry>
        <mesh
          filename="file://$(find xlerobot_description)/meshes/Base_Motor.stl" />
      </geometry>
    </collision>
  </link>

  <joint name="arm_base_joint" type="fixed">
    <origin rpy="0 0 1.5708" xyz="0.09 -0.15 0.77"/>
    <parent link="base_link"/>
    <child link="Base"/>
    <axis xyz="0 1 0"/>
    <limit effort="8.85" velocity="17.4"/>
  </joint>

  <link name="Rotation_Pitch">
    <inertial>
      <origin
        xyz="-9.07886224712597E-05 0.0590971820568318 0.031089016892169"
        rpy="0 0 0" />
      <mass
        value="0.119226314127197" />
      <inertia
        ixx="5.90408775624429E-05"
        ixy="4.90800532852998E-07"
        ixz="-5.90451772654387E-08"
        iyy="3.21498601038881E-05"
        iyz="-4.58026206663885E-06"
        izz="5.86058514263952E-05" />
    </inertial>
    <visual name="rotation_pitch_chassis">
      <origin
        xyz="0 0 0"
        rpy="0 0 0" />
      <geometry>
        <mesh
          filename="file://$(find xlerobot_description)/meshes/Rotation_Pitch.stl" />
      </geometry>
      <material name="white">
      </material>
    </visual>
    <visual name="rotation_pitch_motor">
      <origin
        xyz="0 0 0"
        rpy="0 0 0" />
      <geometry>
        <mesh
          filename="file://$(find xlerobot_description)/meshes/Rotation_Pitch_Motor.stl" />
      </geometry>
      <material name="motor">
      </material>
    </visual>
    <collision>
      <origin
        xyz="0 0 0"
        rpy="0 0 0" />
      <geometry>
        <mesh
          filename="file://$(find xlerobot_description)/meshes/Rotation_Pitch.stl" />
      </geometry>
    </collision>
    <collision>
      <origin
        xyz="0 0 0"
        rpy="0 0 0" />
      <geometry>
        <mesh
          filename="file://$(find xlerobot_description)/meshes/Rotation_Pitch_Motor.stl" />
      </geometry>
    </collision>
  </link>
  <joint name="Rotation" type="revolute">
    <origin
      xyz="0 -0.0452 0.0165"
      rpy="1.5708 0 0" />
    <parent
      link="Base" />
    <child
      link="Rotation_Pitch" />
    <axis
      xyz="0 -1 0" />
      <!-- note for the so100 arm there is no well defined effort/velocity limits at the moment -->
    <limit
      lower="-2.1"
      upper="2.1"
      effort="0"
      velocity="0" />
  </joint>
  <link name="Upper_Arm">
    <inertial>
      <origin
        xyz="-1.7205170190925E-05 0.0701802156327694 0.00310545118155671"
        rpy="0 0 0" />
      <mass
        value="0.162409284599177" />
      <inertia
        ixx="0.000167153146617081"
        ixy="1.03902689187701E-06"
        ixz="-1.20161820645189E-08"
        iyy="7.01946992214245E-05"
        iyz="2.11884806298698E-06"
        izz="0.000213280241160769" />
    </inertial>
    <visual name="upper_arm_chassis">
      <origin
        xyz="0 0 0"
        rpy="0 0 0" />
      <geometry>
        <mesh
          filename="file://$(find xlerobot_description)/meshes/Upper_Arm.stl" />
      </geometry>
      <material name="white">
      </material>
    </visual>
    <visual name="upper_arm_motor">
      <origin
        xyz="0 0 0"
        rpy="0 0 0" />
      <geometry>
        <mesh
          filename="file://$(find xlerobot_description)/meshes/Upper_Arm_Motor.stl" />
      </geometry>
      <material name="motor">
      </material>
    </visual>
    <collision>
      <origin
        xyz="0 0 0"
        rpy="0 0 0" />
      <geometry>
        <mesh
          filename="file://$(find xlerobot_description)/meshes/Upper_Arm.stl" />
      </geometry>
    </collision>
    <collision>
      <origin
        xyz="0 0 0"
        rpy="0 0 0" />
      <geometry>
        <mesh
          filename="file://$(find xlerobot_description)/meshes/Upper_Arm_Motor.stl" />
      </geometry>
    </collision>
  </link>
  <joint name="Pitch" type="revolute">
    <origin
      xyz="0 0.1025 0.0306"
      rpy="1.5708 0 0" />
    <parent
      link="Rotation_Pitch" />
    <child
      link="Upper_Arm" />
    <axis
      xyz="-1 0 0" />
    <limit
      lower="-0.1"
      upper="3.45"
      effort="0"
      velocity="0" />
  </joint>
  <link name="Lower_Arm">
    <inertial>
      <origin xyz="-0.00339603710186651 0.00137796353960074 0.0768006751156044" rpy="0 0 0" />
      <mass value="0.147967774582291" />
      <inertia
        ixx="0.000105333995841409"
        ixy="1.73059237226499E-07"
        ixz="-1.1720305455211E-05"
        iyy="0.000138766654485212"
        iyz="1.77429964684103E-06"
        izz="5.08741652515214E-05" />
    </inertial>
    <visual name="lower_arm_chassis">
      <origin
        xyz="0 0 0"
        rpy="0 0 0" />
      <geometry>
        <mesh
          filename="file://$(find xlerobot_description)/meshes/Lower_Arm.stl" />
      </geometry>
      <material name="white">
      </material>
    </visual>
    <visual name="lower_arm_motor">
      <origin
        xyz="0 0 0"
        rpy="0 0 0" />
      <geometry>
        <mesh
          filename="file://$(find xlerobot_description)/meshes/Lower_Arm_Motor.stl" />
      </geometry>
      <material name="motor">
      </material>
    </visual>
    <collision>
      <origin
        xyz="0 0 0"
        rpy="0 0 0" />
      <geometry>
        <mesh
          filename="file://$(find xlerobot_description)/meshes/Lower_Arm.stl" />
      </geometry>
    </collision>
    <collision>
      <origin
        xyz="0 0 0"
        rpy="0 0 0" />
      <geometry>
        <mesh
          filename="file://$(find xlerobot_description)/meshes/Lower_Arm_Motor.stl" />
      </geometry>
    </collision>
  </link>
  <joint name="Elbow" type="revolute">
    <origin xyz="0 0.11257 0.028" rpy="-1.5708 0 0" />
    <parent link="Upper_Arm" />
    <child link="Lower_Arm" />
    <axis xyz="1 0 0" />
    <limit lower="-0.2" upper="3.14159" effort="0" velocity="0" />
  </joint>
  <link name="Wrist_Pitch_Roll">
    <inertial>
      <origin xyz="-0.00852653127372418 -0.0352278997897927 -2.34622481569413E-05" rpy="0 0 0" />
      <mass value="0.066132067097723" />
      <inertia ixx="1.95717492443445E-05" ixy="-6.62714374412293E-07" ixz="5.20089016442066E-09" iyy="2.38028417569933E-05" iyz="4.09549055863776E-08" izz="3.4540143384536E-05" />
    </inertial>
    <visual name="wrist_pitch_roll_chassis">
      <origin
        xyz="0 0 0"
        rpy="0 0 0" />
      <geometry>
        <mesh
          filename="file://$(find xlerobot_description)/meshes/Wrist_Pitch_Roll.stl" />
      </geometry>
      <material name="white">
      </material>
    </visual>
    <visual name="wrist_pitch_roll_motor">
      <origin
        xyz="0 0 0"
        rpy="0 0 0" />
      <geometry>
        <mesh
          filename="file://$(find xlerobot_description)/meshes/Wrist_Pitch_Roll_Motor.stl" />
      </geometry>
      <material name="motor">
      </material>
    </visual>
    <collision>
      <origin
        xyz="0 0 0"
        rpy="0 0 0" />
      <geometry>
        <mesh
          filename="file://$(find xlerobot_description)/meshes/Wrist_Pitch_Roll.stl" />
      </geometry>
    </collision>
    <collision>
      <origin
        xyz="0 0 0"
        rpy="0 0 0" />
      <geometry>
        <mesh
          filename="file://$(find xlerobot_description)/meshes/Wrist_Pitch_Roll_Motor.stl" />
      </geometry>
    </collision>
  </link>
  <joint name="Wrist_Pitch" type="revolute">
    <origin
      xyz="0 0.0052 0.1349"
      rpy="-1.5708 0 0" />
    <parent
      link="Lower_Arm" />
    <child
      link="Wrist_Pitch_Roll" />
    <axis
      xyz="1 0 0" />
    <limit 
      lower="-1.8"
      upper="1.8"
      effort="0"
      velocity="0" />
  </joint>
  <link name="Fixed_Jaw">
    <inertial>
      <origin xyz="0.00552376906426563 -0.0280167153359021 0.000483582592841092" rpy="0 0 0" />
      <mass
        value="0.0929859131176897" />
      <inertia
        ixx="4.3328249304211E-05"
        ixy="7.09654328670947E-06"
        ixz="5.99838530879484E-07"
        iyy="3.04451747368212E-05"
        iyz="-1.58743247545413E-07"
        izz="5.02460913506734E-05" />
    </inertial>
    <visual name="fixed_jaw_chassis">
      <origin
        xyz="0 0 0"
        rpy="0 0 0" />
      <geometry>
        <mesh
          filename="file://$(find xlerobot_description)/meshes/Fixed_Jaw.stl" />
      </geometry>
      <material name="white">
      </material>
    </visual>
    <visual name="fixed_jaw_motor">
      <origin
        xyz="0 0 0"
        rpy="0 0 0" />
      <geometry>
        <mesh
          filename="file://$(find xlerobot_description)/meshes/Fixed_Jaw_Motor.stl" />
      </geometry>
      <material name="motor">
      </material>
    </visual>
    <collision>
      <origin
        xyz="0 0 0"
        rpy="0 0 0" />
      <geometry>
        <mesh
          filename="file://$(find xlerobot_description)/meshes/Fixed_Jaw_part1.ply" />
      </geometry>
    </collision>
    <collision>
      <origin
        xyz="0 0 0"
        rpy="0 0 0" />
      <geometry>
        <mesh
          filename="file://$(find xlerobot_description)/meshes/Fixed_Jaw_part2.ply" />
      </geometry>
    </collision>
  </link>
  <joint name="Wrist_Roll" type="revolute">
    <origin xyz="0 -0.0601 0" rpy="0 1.5708 0" />
    <parent link="Wrist_Pitch_Roll" />
    <child link="Fixed_Jaw" />
    <axis xyz="0 -1 0" />
    <limit lower="-3.14159" upper="3.14159" effort="0" velocity="0" />
  </joint>
  <link name="Moving_Jaw">
    <inertial>
      <origin
        xyz="-0.00161744605468241 -0.0303472584046471 0.000449645961853651"
        rpy="0 0 0" />
      <mass
        value="0.0202443794940372" />
      <inertia
        ixx="1.10911325081525E-05"
        ixy="-5.35076503033314E-07"
        ixz="-9.46105662101403E-09"
        iyy="3.03576451001973E-06"
        iyz="-1.71146075110632E-07"
        izz="8.9916083370498E-06" />
    </inertial>
    <visual name="moving_jaw_chassis">
      <origin
        xyz="0 0 0"
        rpy="0 0 0" />
      <geometry>
        <mesh
          filename="file://$(find xlerobot_description)/meshes/Moving_Jaw.stl" />
      </geometry>
      <material name="white">
      </material>
    </visual>
    <collision>
      <origin
        xyz="0 0 0"
        rpy="0 0 0" />
      <geometry>
        <mesh
          filename="file://$(find xlerobot_description)/meshes/Moving_Jaw_part1.ply" />
      </geometry>
    </collision>
    <collision>
      <origin
        xyz="0 0 0"
        rpy="0 0 0" />
      <geometry>
        <mesh
          filename="file://$(find xlerobot_description)/meshes/Moving_Jaw_part2.ply" />
      </geometry>
    </collision>
    <collision>
      <origin
        xyz="0 0 0"
        rpy="0 0 0" />
      <geometry>
        <mesh
          filename="file://$(find xlerobot_description)/meshes/Moving_Jaw_part3.ply" />
      </geometry>
    </collision>
  </link>
  <joint name="Jaw" type="revolute">
    <origin xyz="-0.0202 -0.0244 0" rpy="3.1416 0 3.33" />
    <parent link="Fixed_Jaw" />
    <child link="Moving_Jaw" />
    <axis xyz="0 0 1" />
    <limit lower="-3.14159" upper="3.14159" effort="0" velocity="0" />
  </joint>

  <!-- fake joints for useful data -->
  <joint name="Fixed_Jaw_tip_joint" type="fixed">
    <origin rpy="0 0 0" xyz="0.01 -0.097 0"/>
    <parent link="Fixed_Jaw"/>
    <child link="Fixed_Jaw_tip"/>
  </joint>
  <link name="Fixed_Jaw_tip">
    <!-- <visual>
      <origin
        xyz="0 0 0"
        rpy="0 0 0" />
      <geometry>
        <sphere radius="0.01" />
      </geometry>
      <material name="red">
        <color rgba="1 0 0 0.5"/>
      </material>
    </visual> -->
  </link>
  <joint name="Moving_Jaw_tip_joint" type="fixed">
    <origin rpy="0 0 0" xyz="-0.01 -0.073 0"/>
    <parent link="Moving_Jaw"/>
    <child link="Moving_Jaw_tip"/>
  </joint>
  <link name="Moving_Jaw_tip">
    <!-- <visual>
      <origin
        xyz="0 0 0"
        rpy="0 0 0" />
      <geometry>
        <sphere radius="0.01" />
      </geometry>
      <material name="red">
        <color rgba="1 0 0 0.5"/>
      </material>
    </visual> -->
  </link>



  <link name="Base_2">
    <inertial>
      <origin xyz="-2.45960666746703E-07 0.0311418169687909 0.0175746661003382" rpy="0 0 0" />
      <mass
        value="0.193184127927598" />
      <inertia
        ixx="0.000137030709467877"
        ixy="2.10136126944992E-08"
        ixz="4.24087422551286E-09"
        iyy="0.000169089551209259"
        iyz="2.26514711036514E-05"
        izz="0.000145097720857224" />
    </inertial>
    <visual name="base_link_chassis">
      <origin
        xyz="0 0 0"
        rpy="0 0 0" />
      <geometry>
        <mesh filename="file://$(find xlerobot_description)/meshes/Base.stl" />
      </geometry>
      <material name="white">
      </material>
    </visual>
    <visual name="base_link_motor">
      <origin
        xyz="0 0 0"
        rpy="0 0 0" />
      <geometry>
        <mesh
          filename="file://$(find xlerobot_description)/meshes/Base_Motor.stl" />
      </geometry>
      <material name="motor">
      </material>
    </visual>
    <collision>
      <origin
        xyz="0 0 0"
        rpy="0 0 0" />
      <geometry>
        <mesh
          filename="file://$(find xlerobot_description)/meshes/Base.stl" />
      </geometry>
    </collision>
    <collision>
      <origin
        xyz="0 0 0"
        rpy="0 0 0" />
      <geometry>
        <mesh
          filename="file://$(find xlerobot_description)/meshes/Base_Motor.stl" />
      </geometry>
    </collision>
  </link>

  <joint name="arm_base_joint_2" type="fixed">
    <origin rpy="0 0 1.5708" xyz="0.09 0.15 0.77"/>
    <parent link="base_link"/>
    <child link="Base_2"/>
    <axis xyz="0 1 0"/>
    <limit effort="8.85" velocity="17.4"/>
  </joint>

  <link name="Rotation_Pitch_2">
    <inertial>
      <origin
        xyz="-9.07886224712597E-05 0.0590971820568318 0.031089016892169"
        rpy="0 0 0" />
      <mass
        value="0.119226314127197" />
      <inertia
        ixx="5.90408775624429E-05"
        ixy="4.90800532852998E-07"
        ixz="-5.90451772654387E-08"
        iyy="3.21498601038881E-05"
        iyz="-4.58026206663885E-06"
        izz="5.86058514263952E-05" />
    </inertial>
    <visual name="rotation_pitch_chassis">
      <origin
        xyz="0 0 0"
        rpy="0 0 0" />
      <geometry>
        <mesh
          filename="file://$(find xlerobot_description)/meshes/Rotation_Pitch.stl" />
      </geometry>
      <material name="white">
      </material>
    </visual>
    <visual name="rotation_pitch_motor">
      <origin
        xyz="0 0 0"
        rpy="0 0 0" />
      <geometry>
        <mesh
          filename="file://$(find xlerobot_description)/meshes/Rotation_Pitch_Motor.stl" />
      </geometry>
      <material name="motor">
      </material>
    </visual>
    <collision>
      <origin
        xyz="0 0 0"
        rpy="0 0 0" />
      <geometry>
        <mesh
          filename="file://$(find xlerobot_description)/meshes/Rotation_Pitch.stl" />
      </geometry>
    </collision>
    <collision>
      <origin
        xyz="0 0 0"
        rpy="0 0 0" />
      <geometry>
        <mesh
          filename="file://$(find xlerobot_description)/meshes/Rotation_Pitch_Motor.stl" />
      </geometry>
    </collision>
  </link>
  <joint name="Rotation_2" type="revolute">
    <origin
      xyz="0 -0.0452 0.0165"
      rpy="1.5708 0 0" />
    <parent
      link="Base_2" />
    <child
      link="Rotation_Pitch_2" />
    <axis
      xyz="0 -1 0" />
      <!-- note for the so100 arm there is no well defined effort/velocity limits at the moment -->
    <limit
      lower="-2.1"
      upper="2.1"
      effort="0"
      velocity="0" />
  </joint>
  <link name="Upper_Arm_2">
    <inertial>
      <origin
        xyz="-1.7205170190925E-05 0.0701802156327694 0.00310545118155671"
        rpy="0 0 0" />
      <mass
        value="0.162409284599177" />
      <inertia
        ixx="0.000167153146617081"
        ixy="1.03902689187701E-06"
        ixz="-1.20161820645189E-08"
        iyy="7.01946992214245E-05"
        iyz="2.11884806298698E-06"
        izz="0.000213280241160769" />
    </inertial>
    <visual name="upper_arm_chassis">
      <origin
        xyz="0 0 0"
        rpy="0 0 0" />
      <geometry>
        <mesh
          filename="file://$(find xlerobot_description)/meshes/Upper_Arm.stl" />
      </geometry>
      <material name="white">
      </material>
    </visual>
    <visual name="upper_arm_motor">
      <origin
        xyz="0 0 0"
        rpy="0 0 0" />
      <geometry>
        <mesh
          filename="file://$(find xlerobot_description)/meshes/Upper_Arm_Motor.stl" />
      </geometry>
      <material name="motor">
      </material>
    </visual>
    <collision>
      <origin
        xyz="0 0 0"
        rpy="0 0 0" />
      <geometry>
        <mesh
          filename="file://$(find xlerobot_description)/meshes/Upper_Arm.stl" />
      </geometry>
    </collision>
    <collision>
      <origin
        xyz="0 0 0"
        rpy="0 0 0" />
      <geometry>
        <mesh
          filename="file://$(find xlerobot_description)/meshes/Upper_Arm_Motor.stl" />
      </geometry>
    </collision>
  </link>
  <joint name="Pitch_2" type="revolute">
    <origin xyz="0 0.1025 0.0306" rpy="1.5708 0 0" />
    <parent
      link="Rotation_Pitch_2" />
    <child
      link="Upper_Arm_2" />
    <axis
      xyz="-1 0 0" />
    <limit
      lower="-0.1"
      upper="3.45"
      effort="0"
      velocity="0" />
  </joint>
  <link name="Lower_Arm_2">
    <inertial>
      <origin xyz="-0.00339603710186651 0.00137796353960074 0.0768006751156044" rpy="0 0 0" />
      <mass value="0.147967774582291" />
      <inertia
        ixx="0.000105333995841409"
        ixy="1.73059237226499E-07"
        ixz="-1.1720305455211E-05"
        iyy="0.000138766654485212"
        iyz="1.77429964684103E-06"
        izz="5.08741652515214E-05" />
    </inertial>
    <visual name="lower_arm_chassis">
      <origin
        xyz="0 0 0"
        rpy="0 0 0" />
      <geometry>
        <mesh
          filename="file://$(find xlerobot_description)/meshes/Lower_Arm.stl" />
      </geometry>
      <material name="white">
      </material>
    </visual>
    <visual name="lower_arm_motor">
      <origin
        xyz="0 0 0"
        rpy="0 0 0" />
      <geometry>
        <mesh
          filename="file://$(find xlerobot_description)/meshes/Lower_Arm_Motor.stl" />
      </geometry>
      <material name="motor">
      </material>
    </visual>
    <collision>
      <origin
        xyz="0 0 0"
        rpy="0 0 0" />
      <geometry>
        <mesh
          filename="file://$(find xlerobot_description)/meshes/Lower_Arm.stl" />
      </geometry>
    </collision>
    <collision>
      <origin
        xyz="0 0 0"
        rpy="0 0 0" />
      <geometry>
        <mesh
          filename="file://$(find xlerobot_description)/meshes/Lower_Arm_Motor.stl" />
      </geometry>
    </collision>
  </link>
  <joint name="Elbow_2" type="revolute">
    <origin xyz="0 0.11257 0.028" rpy="-1.5708 0 0" />
    <parent link="Upper_Arm_2" />
    <child link="Lower_Arm_2" />
    <axis xyz="1 0 0" />
    <limit lower="-0.2" upper="3.14159" effort="0" velocity="0" />
  </joint>
  <link name="Wrist_Pitch_Roll_2">
    <inertial>
      <origin xyz="-0.00852653127372418 -0.0352278997897927 -2.34622481569413E-05" rpy="0 0 0" />
      <mass value="0.066132067097723" />
      <inertia ixx="1.95717492443445E-05" ixy="-6.62714374412293E-07" ixz="5.20089016442066E-09" iyy="2.38028417569933E-05" iyz="4.09549055863776E-08" izz="3.4540143384536E-05" />
    </inertial>
    <visual name="wrist_pitch_roll_chassis">
      <origin
        xyz="0 0 0"
        rpy="0 0 0" />
      <geometry>
        <mesh
          filename="file://$(find xlerobot_description)/meshes/Wrist_Pitch_Roll.stl" />
      </geometry>
      <material name="white">
      </material>
    </visual>
    <visual name="wrist_pitch_roll_motor">
      <origin
        xyz="0 0 0"
        rpy="0 0 0" />
      <geometry>
        <mesh
          filename="file://$(find xlerobot_description)/meshes/Wrist_Pitch_Roll_Motor.stl" />
      </geometry>
      <material name="motor">
      </material>
    </visual>
    <collision>
      <origin
        xyz="0 0 0"
        rpy="0 0 0" />
      <geometry>
        <mesh
          filename="file://$(find xlerobot_description)/meshes/Wrist_Pitch_Roll.stl" />
      </geometry>
    </collision>
    <collision>
      <origin
        xyz="0 0 0"
        rpy="0 0 0" />
      <geometry>
        <mesh
          filename="file://$(find xlerobot_description)/meshes/Wrist_Pitch_Roll_Motor.stl" />
      </geometry>
    </collision>
  </link>
  <joint name="Wrist_Pitch_2" type="revolute">
    <origin xyz="0 0.0052 0.1349" rpy="-1.5708 0 0" />
    <parent
      link="Lower_Arm_2" />
    <child
      link="Wrist_Pitch_Roll_2" />
    <axis
      xyz="1 0 0" />
    <limit 
      lower="-1.8"
      upper="1.8"
      effort="0"
      velocity="0" />
  </joint>
  <link name="Fixed_Jaw_2">
    <inertial>
      <origin xyz="0.00552376906426563 -0.0280167153359021 0.000483582592841092" rpy="0 0 0" />
      <mass
        value="0.0929859131176897" />
      <inertia
        ixx="4.3328249304211E-05"
        ixy="7.09654328670947E-06"
        ixz="5.99838530879484E-07"
        iyy="3.04451747368212E-05"
        iyz="-1.58743247545413E-07"
        izz="5.02460913506734E-05" />
    </inertial>
    <visual name="fixed_jaw_chassis">
      <origin
        xyz="0 0 0"
        rpy="0 0 0" />
      <geometry>
        <mesh
          filename="file://$(find xlerobot_description)/meshes/Fixed_Jaw.stl" />
      </geometry>
      <material name="white">
      </material>
    </visual>
    <visual name="fixed_jaw_motor">
      <origin
        xyz="0 0 0"
        rpy="0 0 0" />
      <geometry>
        <mesh
          filename="file://$(find xlerobot_description)/meshes/Fixed_Jaw_Motor.stl" />
      </geometry>
      <material name="motor">
      </material>
    </visual>
    <collision>
      <origin
        xyz="0 0 0"
        rpy="0 0 0" />
      <geometry>
        <mesh
          filename="file://$(find xlerobot_description)/meshes/Fixed_Jaw_part1.ply" />
      </geometry>
    </collision>
    <collision>
      <origin
        xyz="0 0 0"
        rpy="0 0 0" />
      <geometry>
        <mesh
          filename="file://$(find xlerobot_description)/meshes/Fixed_Jaw_part2.ply" />
      </geometry>
    </collision>
  </link>
  <joint name="Wrist_Roll_2" type="revolute">
    <origin xyz="0 -0.0601 0" rpy="0 1.5708 0" />
    <parent link="Wrist_Pitch_Roll_2" />
    <child link="Fixed_Jaw_2" />
    <axis xyz="0 -1 0" />
    <limit lower="-3.14159" upper="3.14159" effort="0" velocity="0" />
  </joint>
  <link name="Moving_Jaw_2">
    <inertial>
      <origin xyz="-0.00161744605468241 -0.0303472584046471 0.000449645961853651" rpy="0 0 0" />
      <mass value="0.0202443794940372" />
      <inertia
        ixx="1.10911325081525E-05"
        ixy="-5.35076503033314E-07"
        ixz="-9.46105662101403E-09"
        iyy="3.03576451001973E-06"
        iyz="-1.71146075110632E-07"
        izz="8.9916083370498E-06" />
    </inertial>
    <visual name="moving_jaw_chassis">
      <origin
        xyz="0 0 0"
        rpy="0 0 0" />
      <geometry>
        <mesh
          filename="file://$(find xlerobot_description)/meshes/Moving_Jaw.stl" />
      </geometry>
      <material name="white">
      </material>
    </visual>
    <collision>
      <origin
        xyz="0 0 0"
        rpy="0 0 0" />
      <geometry>
        <mesh
          filename="file://$(find xlerobot_description)/meshes/Moving_Jaw_part1.ply" />
      </geometry>
    </collision>
    <collision>
      <origin
        xyz="0 0 0"
        rpy="0 0 0" />
      <geometry>
        <mesh
          filename="file://$(find xlerobot_description)/meshes/Moving_Jaw_part2.ply" />
      </geometry>
    </collision>
    <collision>
      <origin
        xyz="0 0 0"
        rpy="0 0 0" />
      <geometry>
        <mesh
          filename="file://$(find xlerobot_description)/meshes/Moving_Jaw_part3.ply" />
      </geometry>
    </collision>
  </link>
  <joint name="Jaw_2" type="revolute">
    <origin xyz="-0.0202 -0.0244 0" rpy="3.1416 0 3.33" />
    <parent link="Fixed_Jaw_2" />
    <child link="Moving_Jaw_2" />
    <axis xyz="0 0 1" />
    <limit lower="-3.14159" upper="3.14159" effort="0" velocity="0" />
  </joint>

  <!-- fake joints for useful data -->
  <joint name="Fixed_Jaw_tip_joint_2" type="fixed">
    <origin rpy="0 0 0" xyz="0.01 -0.097 0"/>
    <parent link="Fixed_Jaw_2"/>
    <child link="Fixed_Jaw_tip_2"/>
  </joint>
  <link name="Fixed_Jaw_tip_2">
    <!-- <visual>
      <origin
        xyz="0 0 0"
        rpy="0 0 0" />
      <geometry>
        <sphere radius="0.01" />
      </geometry>
      <material name="red">
        <color rgba="1 0 0 0.5"/>
      </material>
    </visual> -->
  </link>
  <joint name="Moving_Jaw_tip_joint_2" type="fixed">
    <origin rpy="0 0 0" xyz="-0.01 -0.073 0"/>
    <parent link="Moving_Jaw_2"/>
    <child link="Moving_Jaw_tip_2"/>
  </joint>
  <link name="Moving_Jaw_tip_2">
    <!-- <visual>
      <origin
        xyz="0 0 0"
        rpy="0 0 0" />
      <geometry>
        <sphere radius="0.01" />
      </geometry>
      <material name="red">
        <color rgba="1 0 0 0.5"/>
      </material>
    </visual> -->
  </link>







  

  <link name="top_base_link">
    <inertial>
      <origin rpy="0 0 0" xyz="0 0 0"/>
      <mass value="4.3542"/>
      <inertia ixx="0.0045" ixy="0" ixz="0" iyy="0.005" iyz="0" izz="0.0045"/>
    </inertial>


    <visual>
      <origin rpy="0 0 0" xyz="0.11 0 0"/>
      <geometry>
        <box size="0.08 0.44 0.08"/>
      </geometry>
      <material name="white">
      </material>
    </visual>

    <collision>
      <origin rpy="0 0 0" xyz="0.11 0 0"/>
      <geometry>
        <box size="0.08 0.44 0.08"/>
      </geometry>
    </collision>





  </link>


  <joint name="top_base_joint" type="fixed">
    <origin rpy="-6.123E-17 0 0" xyz="0 0 0.73"/>
    <parent link="base_link"/>
    <child link="top_base_link"/>
    <axis xyz="0 1 0"/>
    <limit effort="8.85" velocity="17.4"/>
  </joint>



  <link name="head_pan_link">
    <inertial>
      <origin rpy="0 0 0" xyz="0 0 0"/>
      <mass value="2.2556"/>
      <inertia ixx="0.0129" ixy="0.0002" ixz="0.0007" iyy="0.0095" iyz="-0.0" izz="0.0184"/>
    </inertial>
    <!-- <visual>
      <origin rpy="0 0 0" xyz="0 0 0"/>
      <geometry>
        <box size="0.04 0.06 0.36"/>
      </geometry>
      <material name="green">
      </material>
    </visual> -->
    <!-- <collision>
      <origin rpy="0 0 0" xyz="0 0 0"/>
      <geometry>
        <box size="0.04 0.06 0.36"/>
      </geometry>
    </collision> -->
  </link>

  <joint name="head_pan_joint" type="revolute">
    <origin rpy="0 0 0" xyz="-0.125 0 0.18"/>
    <parent link="top_base_link"/>
    <child link="head_pan_link"/>
    <axis xyz="0 0 1"/>
    <limit effort="0.32" lower="-1.57" upper="1.57" velocity="1.57"/>
  </joint>
  
  <link name="head_tilt_link">
    <inertial>
      <origin rpy="0 0 0" xyz="0.0081 0.0025 0.0113"/>
      <mass value="0.9087"/>
      <inertia ixx="0.0061" ixy="-0.0" ixz="0.0002" iyy="0.0014" iyz="-0.0001" izz="0.0061"/>
    </inertial>
    <!-- <visual>
      <origin rpy="0 0 0" xyz="0 0 0"/>
      <geometry>
        <box size="0.04 0.2 0.08"/>
      </geometry>
      <material name="green">
      </material>
    </visual> -->
    <!-- <collision>
      <origin rpy="0 0 0" xyz="0 0 0"/>
      <geometry>
        <box size="0.04 0.2 0.08"/>
      </geometry>
    </collision> -->
  </link>
  <joint name="head_tilt_joint" type="revolute">
    <origin rpy="0 0 0" xyz="0.05 0 0.18"/>
    <parent link="head_pan_link"/>
    <child link="head_tilt_link"/>
    <axis xyz="0 1 0"/>
    <limit effort="0.68" lower="-0.76" upper="1.45" velocity="1.57"/>
  </joint>


  <link name="head_camera_link"/>
  <joint name="head_camera_joint" type="fixed">
    <origin rpy="0 0 0" xyz="0.055 0 0.0225"/>
    <parent link="head_tilt_link"/>
    <child link="head_camera_link"/>
  </joint>
  <link name="head_camera_rgb_frame"/>
  <joint name="head_camera_rgb_joint" type="fixed">
    <origin rpy="0 0 0" xyz="0 0.02 0"/>
    <parent link="head_camera_link"/>
    <child link="head_camera_rgb_frame"/>
  </joint>
  <link name="head_camera_rgb_optical_frame"/>
  <joint name="head_camera_rgb_optical_joint" type="fixed">
    <origin rpy="-1.57079632679 0 -1.57079632679" xyz="0 0 0"/>
    <parent link="head_camera_rgb_frame"/>
    <child link="head_camera_rgb_optical_frame"/>
  </joint>
  <link name="head_camera_depth_frame"/>
  <joint name="head_camera_depth_joint" type="fixed">
    <origin rpy="0 0 0" xyz="0 0.045 0"/>
    <parent link="head_camera_link"/>
    <child link="head_camera_depth_frame"/>
  </joint>
  <link name="head_camera_depth_optical_frame"/>
  <joint name="head_camera_depth_optical_joint" type="fixed">
    <origin rpy="-1.57079632679 0 -1.57079632679" xyz="0 0 0"/>
    <parent link="head_camera_depth_frame"/>
    <child link="head_camera_depth_optical_frame"/>
  </joint>




</robot>
