<?xml version="1.0" encoding="utf-8"?>
<robot name="mmk2">
  <link name="base_link">
    <inertial>
      <origin xyz="-0.0400313721989715 -0.0226608008968248 0.756257223317173"/>
      <mass value="33.0267456398628"/>
      <inertia ixx="3.44838378637062" ixy="-0.00207943141138886" ixz="-0.0103091786755565" iyy="3.49493780774117"
               iyz="-0.00146679448998739" izz="0.21980548376876"/>
    </inertial>
    <visual>
      <geometry>
        <mesh filename="file://$(find airbot_mmk2_description)/meshes/base_link.obj"/>
      </geometry>
    </visual>
    <collision>
      <geometry>
        <mesh filename="file://$(find airbot_mmk2_description)/meshes/base_link.obj"/>
      </geometry>
    </collision>
  </link>

  <link name="rgt_wheel_link">
    <inertial>
      <origin xyz="5.20143266670436E-06 5.37603125005695E-07 -0.0018711144360713"/>
      <mass value="1.15656808640541"/>
      <inertia ixx="0.0021044922532766" ixy="1.88606601059021E-10" ixz="-3.50324127667933E-07" iyy="0.00210448664280546"
               iyz="-3.619495141978E-08" izz="0.00355284737378788"/>
    </inertial>
    <visual>
      <geometry>
        <mesh filename="file://$(find airbot_mmk2_description)/meshes/rgt_wheel_link.STL"/>
      </geometry>
      <material name="">
        <color rgba="0.752941176470588 0.752941176470588 0.752941176470588 1"/>
      </material>
    </visual>
    <collision>
      <geometry>
        <mesh
            filename="file://$(find airbot_mmk2_description)/meshes/rgt_wheel_link.STL"/>
      </geometry>
    </collision>
  </link>

  <joint name="rgt_wheel_joint" type="revolute">
    <origin xyz="0 -0.16325 0.08401" rpy="1.5708 1.5708 0"/>
    <parent link="base_link"/>
    <child link="rgt_wheel_link"/>
    <axis xyz="0 0 1"/>
    <limit lower="-3.1416" upper="3.1416" effort="6.5" velocity="0.7"/>
  </joint>

  <link name="lft_wheel_link">
    <inertial>
      <origin xyz="1.28756699316335E-06 -5.0575586944921E-06 0.00187111444199509"/>
      <mass value="1.15656808621832"/>
      <inertia ixx="0.00210448719172768" ixy="-1.67788115008943E-09" ixz="8.7251015028674E-08" iyy="0.00210449170378954"
               iyz="-3.41206350459015E-07" izz="0.00355284737380655"/>
    </inertial>
    <visual>
      <geometry>
        <mesh filename="file://$(find airbot_mmk2_description)/meshes/lft_wheel_link.STL"/>
      </geometry>
      <material name="">
        <color rgba="0.752941176470588 0.752941176470588 0.752941176470588 1"/>
      </material>
    </visual>
    <collision>
      <geometry>
        <mesh filename="file://$(find airbot_mmk2_description)/meshes/lft_wheel_link.STL"/>
      </geometry>
    </collision>
  </link>

  <joint name="lft_wheel_joint" type="revolute">
    <origin xyz="0 0.16325 0.08401" rpy="1.5708 1.5708 0"/>
    <parent link="base_link"/>
    <child link="lft_wheel_link"/>
    <axis xyz="0 0 1"/>
    <limit lower="-3.1416" upper="3.1416" effort="6.5" velocity="0.7"/>
  </joint>

  <link name="slide_link">
    <inertial>
      <origin xyz="-7.90494393625066E-05 0.067355217450789 0.10519083626064"/>
      <mass value="2.87043102920673"/>
      <inertia ixx="0.00899755064402379" ixy="6.09937870252811E-07" ixz="2.90775161414524E-06" iyy="0.0119634133355932"
               iyz="-0.000250919444280722" izz="0.00864817587777869"/>
    </inertial>
    <visual>
      <geometry>
        <mesh filename="file://$(find airbot_mmk2_description)/meshes/slide.obj"/>
      </geometry>
      <material name="">
        <color rgba="0.752941176470588 0.752941176470588 0.752941176470588 1"/>
      </material>
    </visual>
    <collision>
      <geometry>
        <mesh filename="file://$(find airbot_mmk2_description)/meshes/slide.obj"/>
      </geometry>
    </collision>
  </link>

  <joint name="slide_joint" type="prismatic">
    <origin xyz="0.033942 -0.00025 1.406" rpy="3.1416 0 1.5708"/>
    <parent link="base_link"/>
    <child link="slide_link"/>
    <axis xyz="0 0 1"/>
    <limit lower="-0.04" upper="0.87" effort="5" velocity="0.3"/>
  </joint>

  <link name="head_yaw_link">
    <inertial>
      <origin xyz="0.0118490941462296 0.000491254783341499 0.0390231494943873"/>
      <mass value="0.263127360420809"/>
      <inertia ixx="0.000185798854547827" ixy="2.64309797822853E-07" ixz="-2.93582511724902E-05"
               iyy="0.000173833362201622" iyz="-2.8054841555532E-06" izz="9.38655776831082E-05"/>
    </inertial>
    <visual>
      <geometry>
        <mesh filename="file://$(find airbot_mmk2_description)/meshes/head_yaw.obj"/>
      </geometry>
      <material name="">
        <color rgba="0.752941176470588 0.752941176470588 0.752941176470588 1"/>
      </material>
    </visual>
    <collision>
      <geometry>
        <mesh filename="file://$(find airbot_mmk2_description)/meshes/head_yaw.obj"/>
      </geometry>
    </collision>
  </link>

  <joint name="head_yaw_joint" type="revolute">
    <origin xyz="0 0.1735 0.07242" rpy="3.1416 0 0"/>
    <parent link="slide_link"/>
    <child link="head_yaw_link"/>
    <axis xyz="0 0 1"/>
    <limit lower="-0.5" upper="0.5" effort="2" velocity="0.2"/>
  </joint>

  <link name="head_pitch_link">
    <inertial>
      <origin xyz="0.0244659096221799 -0.108421751901101 -0.00311687659834824"/>
      <mass value="0.500765947013434"/>
      <inertia ixx="0.00157924187002826" ixy="2.16781765858799E-05" ixz="-1.02638171835218E-06"
               iyy="0.000804096450222595" iyz="1.48815549401623E-05" izz="0.00113048749298996"/>
    </inertial>
    <visual>
      <geometry>
        <mesh filename="file://$(find airbot_mmk2_description)/meshes/head_pitch.obj"/>
      </geometry>
      <material name="">
        <color rgba="0.752941176470588 0.752941176470588 0.752941176470588 1"/>
      </material>
    </visual>
    <collision>
      <geometry>
        <mesh filename="file://$(find airbot_mmk2_description)/meshes/head_pitch.obj"/>
      </geometry>
    </collision>
  </link>

  <joint name="head_pitch_joint" type="revolute">
    <origin xyz="0.00099952 3.1059E-05 0.058" rpy="-1.5708 0 -1.5397"/>
    <parent link="head_yaw_link"/>
    <child link="head_pitch_link"/>
    <axis xyz="0 0 1"/>
    <limit lower="-0.16" upper="1.18" effort="2" velocity="0.2"/>
  </joint>
</robot>