<?xml version="1.0" ?>
<!-- =================================================================================== -->
<!-- |    This document was autogenerated by xacro from robot.xacro                    | -->
<!-- |    EDITING THIS FILE BY HAND IS NOT RECOMMENDED                                 | -->
<!-- =================================================================================== -->
<robot name="AgileX Aloha">
  <link name="base_link"/>
  <joint name="base_link_joint" type="fixed">
    <parent link="base_link"/>
    <child link="base"/>
    <origin xyz="0 0 0.33"/>
  </joint>
  <link name="base">
    <inertial>
      <origin xyz="-0.0242698272228022 -0.0030308024613212 0.0544267444673498"/>
      <mass value="10"/>
      <inertia ixx="0.1354" ixy="0.0" ixz="0.0" iyy="0.2417" iyz="0.0" izz="0.3085"/>
    </inertial>
    <visual>
      <geometry>
        <mesh filename="package://agilex_aloha_description/meshes/ranger_mini/base.obj"/>
      </geometry>
    </visual>
    <collision>
      <origin xyz="0 0 -0.1"/>
      <geometry>
        <box size="0.5 0.35 0.2"/>
      </geometry>
    </collision>
  </link>
  <link name="fr_steering_wheel_link">
    <inertial>
      <origin xyz="1.8493E-05 1.2713E-06 0.043679"/>
      <mass value="1"/>
      <inertia ixx="0.0063625" ixy="-1.0581E-07" ixz="-4.0831E-07" iyy="0.006363" iyz="-3.4944E-08" izz="0.010465"/>
    </inertial>
    <visual>
      <geometry>
        <mesh filename="package://agilex_aloha_description/meshes/ranger_mini/steering_wheel.obj"/>
      </geometry>
    </visual>
  </link>
  <joint name="fr_steering_joint" type="revolute">
    <origin xyz="0.241 -0.185 -0.115"/>
    <parent link="base"/>
    <child link="fr_steering_wheel_link"/>
    <axis xyz="0 0 -1"/>
    <limit effort="5" lower="-2.1" upper="2.1" velocity="6.28"/>
  </joint>
  <link name="fr_wheel_link">
    <inertial>
      <mass value="8"/>
      <inertia ixx="0.02047" ixy="0.0" ixz="0.0" iyy="0.02047" iyz="0.0" izz="0.0324"/>
    </inertial>
    <visual>
      <origin rpy="3.14 0 0" xyz="0 0 0"/>
      <geometry>
        <mesh filename="package://agilex_aloha_description/meshes/ranger_mini/wheel.obj"/>
      </geometry>
    </visual>
    <collision>
      <origin rpy="1.57 0 0" xyz="0 0 -0.005"/>
      <geometry>
        <cylinder length="0.08" radius="0.09"/>
      </geometry>
    </collision>
  </link>
  <joint name="fr_wheel" type="continuous">
    <origin xyz="0.0 0.0 -0.12"/>
    <parent link="fr_steering_wheel_link"/>
    <child link="fr_wheel_link"/>
    <axis xyz="0 1 0"/>
  </joint>
  <link name="fl_steering_wheel_link">
    <inertial>
      <origin xyz="-0.0017956 -9.6304E-08 0.043642"/>
      <mass value="1"/>
      <inertia ixx="0.0063695" ixy="-2.1067E-08" ixz="-0.00016867" iyy="0.006363" iyz="-1.0301E-08" izz="0.010458"/>
    </inertial>
    <visual>
      <origin rpy="0 0 3.14"/>
      <geometry>
        <mesh filename="package://agilex_aloha_description/meshes/ranger_mini/steering_wheel.obj"/>
      </geometry>
    </visual>
  </link>
  <joint name="fl_steering_joint" type="revolute">
    <origin xyz="0.241 0.185 -0.115"/>
    <parent link="base"/>
    <child link="fl_steering_wheel_link"/>
    <axis xyz="0 0 -1"/>
    <limit effort="5" lower="-2.1" upper="2.1" velocity="6.28"/>
  </joint>
  <link name="fl_wheel_link">
    <inertial>
      <mass value="8"/>
      <inertia ixx="0.02047" ixy="0.0" ixz="0.0" iyy="0.02047" iyz="0.0" izz="0.0324"/>
    </inertial>
    <visual>
      <geometry>
        <mesh filename="package://agilex_aloha_description/meshes/ranger_mini/wheel.obj"/>
      </geometry>
    </visual>
    <collision>
      <origin rpy="1.57 0 0" xyz="0 0 -0.005"/>
      <geometry>
        <cylinder length="0.08" radius="0.09"/>
      </geometry>
    </collision>
  </link>
  <joint name="fl_wheel" type="continuous">
    <origin xyz="0.0 0.0 -0.12"/>
    <parent link="fl_steering_wheel_link"/>
    <child link="fl_wheel_link"/>
    <axis xyz="0 1 0"/>
  </joint>
  <link name="rl_steering_wheel_link">
    <inertial>
      <origin xyz="-0.00017093 6.1255E-08 0.043678"/>
      <mass value="1"/>
      <inertia ixx="0.0063627" ixy="-2.1069E-08" ixz="-1.587E-05" iyy="0.006363" iyz="9.3201E-09" izz="0.010465"/>
    </inertial>
    <visual>
      <origin rpy="0 0 3.14"/>
      <geometry>
        <mesh filename="package://agilex_aloha_description/meshes/ranger_mini/steering_wheel.obj"/>
      </geometry>
    </visual>
  </link>
  <joint name="rl_steering_joint" type="revolute">
    <origin xyz="-0.253 0.185 -0.115"/>
    <parent link="base"/>
    <child link="rl_steering_wheel_link"/>
    <axis xyz="0 0 -1"/>
    <limit effort="5" lower="-2.1" upper="2.1" velocity="6.28"/>
  </joint>
  <link name="rl_wheel_link">
    <inertial>
      <mass value="8"/>
      <inertia ixx="0.02047" ixy="0.0" ixz="0.0" iyy="0.02047" iyz="0.0" izz="0.0324"/>
    </inertial>
    <visual>
      <geometry>
        <mesh filename="package://agilex_aloha_description/meshes/ranger_mini/wheel.obj"/>
      </geometry>
    </visual>
    <collision>
      <origin rpy="1.57 0 0" xyz="0.00 0.00 -0.005"/>
      <geometry>
        <cylinder length="0.08" radius="0.09"/>
      </geometry>
    </collision>
  </link>
  <joint name="rl_wheel" type="continuous">
    <origin xyz="0.0 0.0 -0.12 "/>
    <parent link="rl_steering_wheel_link"/>
    <child link="rl_wheel_link"/>
    <axis xyz="0 1 0"/>
  </joint>
  <link name="rr_steering_wheel_link">
    <inertial>
      <mass value="1"/>
      <inertia ixx="0.01" ixy="0.0" ixz="0.0" iyy="0.01" iyz="0.0" izz="0.01"/>
    </inertial>
    <visual>
      <geometry>
        <mesh filename="package://agilex_aloha_description/meshes/ranger_mini/steering_wheel.obj"/>
      </geometry>
    </visual>
  </link>
  <joint name="rr_steering_joint" type="revolute">
    <origin xyz="-0.253 -0.185 -0.115"/>
    <parent link="base"/>
    <child link="rr_steering_wheel_link"/>
    <axis xyz="0 0 -1"/>
    <limit effort="5" lower="-2.1" upper="2.1" velocity="6.28"/>
  </joint>
  <link name="rr_wheel_link">
    <inertial>
      <mass value="8"/>
      <inertia ixx="0.02047" ixy="0.0" ixz="0.0" iyy="0.02047" iyz="0.0" izz="0.0324"/>
    </inertial>
    <visual>
      <origin rpy="3.14 0 0"/>
      <geometry>
        <mesh filename="package://agilex_aloha_description/meshes/ranger_mini/wheel.obj"/>
      </geometry>
    </visual>
    <collision>
      <origin rpy="1.57 0 0" xyz="0.00 0 -0.005"/>
      <geometry>
        <cylinder length="0.08" radius="0.09"/>
      </geometry>
    </collision>
  </link>
  <joint name="rr_wheel" type="continuous">
    <origin xyz="0.0 0.0 -0.12 "/>
    <parent link="rr_steering_wheel_link"/>
    <child link="rr_wheel_link"/>
    <axis xyz="0 1 0"/>
  </joint>
  <link name="box_link">
    <inertial>
      <origin xyz="0.10921 -0.0087718 0.52779"/>
      <mass value="27.261"/>
      <inertia ixx="1.8122" ixy="4.558E-05" ixz="0.014722" iyy="1.7779" iyz="-4.0693E-05" izz="0.28053"/>
    </inertial>
    <visual>
      <geometry>
        <mesh filename="package://agilex_aloha_description/meshes/aloha_split/box_link.obj"/>
      </geometry>
    </visual>
    <collision>
      <geometry>
        <mesh filename="package://agilex_aloha_description/meshes/aloha_split/box_link.obj"/>
      </geometry>
    </collision>
  </link>
  <joint name="box_joint" type="fixed">
    <parent link="base"/>
    <child link="box_link"/>
  </joint>
  <link name="front_camera_link">
    <inertial>
      <origin xyz="-0.011443 0.0003607 -0.0012124"/>
      <mass value="0.020053"/>
      <inertia ixx="1.1182E-05" ixy="2.589E-09" ixz="5.6552E-08" iyy="2.2729E-06" iyz="-6.7447E-07" izz="1.0081E-05"/>
    </inertial>
    <visual>
      <geometry>
        <mesh filename="package://agilex_aloha_description/meshes/aloha_split/camera.obj"/>
      </geometry>
    </visual>
    <collision>
      <geometry>
        <mesh filename="package://agilex_aloha_description/meshes/aloha_split/camera.obj"/>
      </geometry>
    </collision>
  </link>
  <joint name="front_camera_joint" type="fixed">
    <origin rpy="0 0.6606 -0.0051043" xyz="0.35679 0 0.15819"/>
    <parent link="box_link"/>
    <child link="front_camera_link"/>
  </joint>
  <link name="lidar_link">
    <inertial>
      <origin xyz="-0.0022133 -0.00090659 0.025996"/>
      <mass value="0.048617"/>
      <inertia ixx="1.0358E-05" ixy="9.2377E-09" ixz="-2.6386E-07" iyy="1.0387E-05" iyz="-2.6377E-07" izz="1.7919E-05"/>
    </inertial>
    <visual>
      <geometry>
        <mesh filename="package://agilex_aloha_description/meshes/aloha_split/mid360.obj"/>
      </geometry>
    </visual>
    <collision>
      <geometry>
        <mesh filename="package://agilex_aloha_description/meshes/aloha_split/mid360.obj"/>
      </geometry>
    </collision>
  </link>
  <joint name="lidar_joint" type="fixed">
    <origin rpy="-0.035132 0.20001 -0.001242" xyz="0.31755 0 0.036188"/>
    <parent link="box_link"/>
    <child link="lidar_link"/>
  </joint>
  <link name="lifting_link">
    <inertial>
      <origin xyz="0.071327 0.00032985 0.10599"/>
      <mass value="0.47066"/>
      <inertia ixx="0.010952" ixy="-5.2124E-06" ixz="-0.00046317" iyy="0.0018329" iyz="-4.6428E-06" izz="0.010201"/>
    </inertial>
    <visual>
      <geometry>
        <mesh filename="package://agilex_aloha_description/meshes/aloha_split/lift_link.obj"/>
      </geometry>
    </visual>
    <collision>
      <geometry>
        <mesh filename="package://agilex_aloha_description/meshes/aloha_split/lift_link.obj"/>
      </geometry>
    </collision>
  </link>
  <joint name="lifting_joint" type="prismatic">
    <origin xyz="0.22448 0 1.1147"/>
    <parent link="box_link"/>
    <child link="lifting_link"/>
    <axis xyz="0 0 1"/>
    <limit effort="1000" lower="-0.6" upper="0.0" velocity="10.0"/>
  </joint>
  <link name="top_camera_link">
    <inertial>
      <origin xyz="-0.011443 2.4833E-05 -0.0012615"/>
      <mass value="0.020053"/>
      <inertia ixx="1.1181E-05" ixy="1.204E-07" ixz="4.9068E-08" iyy="2.2587E-06" iyz="5.7637E-07" izz="1.0097E-05"/>
    </inertial>
    <visual>
      <geometry>
        <mesh filename="package://agilex_aloha_description/meshes/aloha_split/camera.obj"/>
      </geometry>
    </visual>
    <collision>
      <geometry>
        <mesh filename="package://agilex_aloha_description/meshes/aloha_split/camera.obj"/>
      </geometry>
    </collision>
  </link>
  <joint name="top_camera_joint" type="fixed">
    <origin rpy="0 0.00080758 -0.01623" xyz="0.16194 0 0.29838"/>
    <parent link="lifting_link"/>
    <child link="top_camera_link"/>
  </joint>
  <link name="top_camera_support">
    <visual>
      <geometry>
        <mesh filename="package://agilex_aloha_description/meshes/aloha_split/camera_support.obj"/>
      </geometry>
    </visual>
  </link>
  <joint name="top_camera_support_joint" type="fixed">
    <origin rpy="0 0.00080758 -0.01623" xyz="0.16194 0 0.29838"/>
    <parent link="lifting_link"/>
    <child link="top_camera_support"/>
  </joint>
  <link name="left_base_link">
    <inertial>
      <origin xyz="-0.00473641164191482 2.56829134630247E-05 0.041451518036016"/>
      <mass value="1.02"/>
      <inertia ixx="0.00267433" ixy="-0.00000073" ixz="-0.00017389" iyy="0.00282612" iyz="0.0000004" izz="0.00089624"/>
    </inertial>
    <visual>
      <geometry>
        <mesh filename="package://piper_description/meshes/base_link.obj"/>
      </geometry>
    </visual>
    <collision>
      <geometry>
        <mesh filename="package://piper_description/meshes/base_link.obj"/>
      </geometry>
    </collision>
  </link>
  <link name="left_link1">
    <inertial>
      <origin xyz="0.000121504734057468 0.000104632162460536 -0.00438597309559853"/>
      <mass value="0.71"/>
      <inertia ixx="0.00048916" ixy="-0.00000036" ixz="-0.00000224" iyy="0.00040472" iyz="-0.00000242" izz="0.00043982"/>
    </inertial>
    <visual>
      <geometry>
        <mesh filename="package://piper_description/meshes/link1.obj"/>
      </geometry>
    </visual>
    <collision>
      <geometry>
        <mesh filename="package://piper_description/meshes/link1.obj"/>
      </geometry>
    </collision>
  </link>
  <joint name="left_joint1" type="revolute">
    <origin rpy="0 0 0" xyz="0 0 0.123"/>
    <parent link="left_base_link"/>
    <child link="left_link1"/>
    <axis xyz="0 0 1"/>
    <limit effort="100" lower="-2.618" upper="2.618" velocity="5"/>
  </joint>
  <link name="left_link2">
    <inertial>
      <origin rpy="0 0 0" xyz="0.198666145229743 -0.010926924140076 0.00142121714502687"/>
      <mass value="1.17"/>
      <inertia ixx="0.00116918" ixy="-0.00180037" ixz="0.00025146" iyy="0.06785384" iyz="-0.00000455" izz="0.06774489"/>
    </inertial>
    <visual>
      <geometry>
        <mesh filename="package://piper_description/meshes/link2.obj"/>
      </geometry>
    </visual>
    <collision>
      <geometry>
        <mesh filename="package://piper_description/meshes/link2.obj"/>
      </geometry>
    </collision>
  </link>
  <joint name="left_joint2" type="revolute">
    <origin rpy="1.5708 -0.1359 -3.1416" xyz="0 0 0"/>
    <parent link="left_link1"/>
    <child link="left_link2"/>
    <axis xyz="0 0 1"/>
    <limit effort="100" lower="0" upper="3.14" velocity="5"/>
  </joint>
  <link name="left_link3">
    <inertial>
      <origin rpy="0 0 0" xyz="-0.0202737662122021 -0.133914995944595 -0.000458682652737356"/>
      <mass value="0.5"/>
      <inertia ixx="0.01361711" ixy="0.00165794" ixz="-0.00000048" iyy="0.00045024" iyz="-0.00000045" izz="0.01380322"/>
    </inertial>
    <visual>
      <geometry>
        <mesh filename="package://piper_description/meshes/link3.obj"/>
      </geometry>
    </visual>
    <collision>
      <geometry>
        <mesh filename="package://piper_description/meshes/link3.obj"/>
      </geometry>
    </collision>
  </link>
  <joint name="left_joint3" type="revolute">
    <origin rpy="0 0 -1.7939" xyz="0.28503 0 0"/>
    <parent link="left_link2"/>
    <child link="left_link3"/>
    <axis xyz="0 0 1"/>
    <limit effort="100" lower="-2.967" upper="0" velocity="5"/>
  </joint>
  <link name="left_link4">
    <inertial>
      <origin rpy="0 0 0" xyz="-9.66635791618542E-05 0.000876064475651083 -0.00496880904640868"/>
      <mass value="0.38"/>
      <inertia ixx="0.00018501" ixy="0.00000054" ixz="0.00000120" iyy="0.00018965" iyz="-0.00000841" izz="0.00015484"/>
    </inertial>
    <visual>
      <geometry>
        <mesh filename="package://piper_description/meshes/link4.obj"/>
      </geometry>
    </visual>
    <collision>
      <geometry>
        <mesh filename="package://piper_description/meshes/link4.obj"/>
      </geometry>
    </collision>
  </link>
  <joint name="left_joint4" type="revolute">
    <origin rpy="1.5708 0 0" xyz="-0.021984 -0.25075 0"/>
    <parent link="left_link3"/>
    <child link="left_link4"/>
    <axis xyz="0 0 1"/>
    <limit effort="100" lower="-1.745" upper="1.745" velocity="5"/>
  </joint>
  <link name="left_link5">
    <inertial>
      <origin rpy="0 0 0" xyz="-4.10554118924211E-05 -0.0566486692356075 -0.0037205791677906"/>
      <mass value="0.383"/>
      <inertia ixx="0.00166169" ixy="0.00000006" ixz="-0.00000007" iyy="0.00018510" iyz="0.00001026" izz="0.00164321"/>
    </inertial>
    <visual>
      <geometry>
        <mesh filename="package://piper_description/meshes/link5.obj"/>
      </geometry>
    </visual>
    <collision>
      <geometry>
        <mesh filename="package://piper_description/meshes/link5.obj"/>
      </geometry>
    </collision>
  </link>
  <joint name="left_joint5" type="revolute">
    <origin rpy="-1.5708 0 0" xyz="0 0 0"/>
    <parent link="left_link4"/>
    <child link="left_link5"/>
    <axis xyz="0 0 1"/>
    <limit effort="100" lower="-1.22" upper="1.22" velocity="5"/>
  </joint>
  <joint name="left_joint6" type="revolute">
    <origin rpy="1.5708 0 0" xyz="0 -0.091 0"/>
    <parent link="left_link5"/>
    <child link="left_link6"/>
    <axis xyz="0 0 1"/>
    <limit effort="100" lower="-2.0944" upper="2.0944" velocity="3"/>
  </joint>
  <link name="left_link6">
    <inertial>
      <origin xyz="-0.000183807162235591 8.05033155577911E-05 0.0321436689908876"/>
      <mass value="0.657"/>
      <inertia ixx="0.00092934" ixy="0.00000034" ixz="-0.00000738" iyy="0.00071447" iyz="0.00000005" izz="0.00039442"/>
    </inertial>
    <visual>
      <geometry>
        <mesh filename="package://piper_description/meshes/link6.obj"/>
      </geometry>
    </visual>
    <collision>
      <geometry>
        <mesh filename="package://piper_description/meshes/link6.obj"/>
      </geometry>
    </collision>
  </link>
  <link name="left_link7">
    <inertial>
      <origin rpy="0 0 0" xyz="0.00065123185041968 -0.0491929869131989 0.00972258769184025"/>
      <mass value="0.025"/>
      <inertia ixx="0.00007371" ixy="-0.00000113" ixz="0.00000021" iyy="0.00000781" iyz="-0.00001372" izz="0.0000747"/>
    </inertial>
    <visual>
      <geometry>
        <mesh filename="package://piper_description/meshes/link7.obj"/>
      </geometry>
    </visual>
    <collision>
      <geometry>
        <mesh filename="package://piper_description/meshes/link7.obj"/>
      </geometry>
    </collision>
  </link>
  <joint name="left_gripper_joint" type="prismatic">
    <origin xyz="0 0 0.1358"/>
    <parent link="left_link6"/>
    <child link="left_link7"/>
    <axis xyz="0 -1 0"/>
    <limit effort="10" lower="0" upper="0.035" velocity="1"/>
  </joint>
  <link name="left_link8">
    <inertial>
      <origin xyz="0.000651231850419722 -0.0491929869131991 0.00972258769184024"/>
      <mass value="0.025"/>
      <inertia ixx="0.00007371" ixy="-0.00000113" ixz="0.00000021" iyy="0.00000781" iyz="-0.00001372" izz="0.0000747"/>
    </inertial>
    <visual>
      <geometry>
        <mesh filename="package://piper_description/meshes/link8.obj"/>
      </geometry>
    </visual>
    <collision>
      <geometry>
        <mesh filename="package://piper_description/meshes/link8.obj"/>
      </geometry>
    </collision>
  </link>
  <joint name="left_joint8" type="prismatic">
    <origin xyz="0 0 0.1358"/>
    <parent link="left_link6"/>
    <child link="left_link8"/>
    <mimic joint="left_gripper_joint" multiplier="1" offset="0"/>
    <axis xyz="0 1 0"/>
    <limit effort="10" lower="0" upper="0.035" velocity="1"/>
  </joint>
  <link name="left_gripper_center"/>
  <joint name="left_gripper_center_fixed" type="fixed">
    <parent link="left_link6"/>
    <child link="left_gripper_center"/>
    <origin rpy="0 -1.57 0" xyz="0 0 0.1358"/>
  </joint>
  <link name="left_camera"/>
  <joint name="left_camera_fixed" type="fixed">
    <origin rpy="0 -1.22 0" xyz="-0.073 0 0.041"/>
    <parent link="left_link6"/>
    <child link="left_camera"/>
  </joint>
  <joint name="arm_and_lifting_left" type="fixed">
    <origin xyz="0.144 0.306 0.138"/>
    <parent link="lifting_link"/>
    <child link="left_base_link"/>
    <axis xyz="0.0 0.0 0.0"/>
    <limit effort="0.0" lower="0.0" upper="0.0" velocity="0.0"/>
  </joint>
  <link name="right_base_link">
    <inertial>
      <origin xyz="-0.00473641164191482 2.56829134630247E-05 0.041451518036016"/>
      <mass value="1.02"/>
      <inertia ixx="0.00267433" ixy="-0.00000073" ixz="-0.00017389" iyy="0.00282612" iyz="0.0000004" izz="0.00089624"/>
    </inertial>
    <visual>
      <geometry>
        <mesh filename="package://piper_description/meshes/base_link.obj"/>
      </geometry>
    </visual>
    <collision>
      <geometry>
        <mesh filename="package://piper_description/meshes/base_link.obj"/>
      </geometry>
    </collision>
  </link>
  <link name="right_link1">
    <inertial>
      <origin xyz="0.000121504734057468 0.000104632162460536 -0.00438597309559853"/>
      <mass value="0.71"/>
      <inertia ixx="0.00048916" ixy="-0.00000036" ixz="-0.00000224" iyy="0.00040472" iyz="-0.00000242" izz="0.00043982"/>
    </inertial>
    <visual>
      <geometry>
        <mesh filename="package://piper_description/meshes/link1.obj"/>
      </geometry>
    </visual>
    <collision>
      <geometry>
        <mesh filename="package://piper_description/meshes/link1.obj"/>
      </geometry>
    </collision>
  </link>
  <joint name="right_joint1" type="revolute">
    <origin rpy="0 0 0" xyz="0 0 0.123"/>
    <parent link="right_base_link"/>
    <child link="right_link1"/>
    <axis xyz="0 0 1"/>
    <limit effort="100" lower="-2.618" upper="2.618" velocity="5"/>
  </joint>
  <link name="right_link2">
    <inertial>
      <origin rpy="0 0 0" xyz="0.198666145229743 -0.010926924140076 0.00142121714502687"/>
      <mass value="1.17"/>
      <inertia ixx="0.00116918" ixy="-0.00180037" ixz="0.00025146" iyy="0.06785384" iyz="-0.00000455" izz="0.06774489"/>
    </inertial>
    <visual>
      <geometry>
        <mesh filename="package://piper_description/meshes/link2.obj"/>
      </geometry>
    </visual>
    <collision>
      <geometry>
        <mesh filename="package://piper_description/meshes/link2.obj"/>
      </geometry>
    </collision>
  </link>
  <joint name="right_joint2" type="revolute">
    <origin rpy="1.5708 -0.1359 -3.1416" xyz="0 0 0"/>
    <parent link="right_link1"/>
    <child link="right_link2"/>
    <axis xyz="0 0 1"/>
    <limit effort="100" lower="0" upper="3.14" velocity="5"/>
  </joint>
  <link name="right_link3">
    <inertial>
      <origin rpy="0 0 0" xyz="-0.0202737662122021 -0.133914995944595 -0.000458682652737356"/>
      <mass value="0.5"/>
      <inertia ixx="0.01361711" ixy="0.00165794" ixz="-0.00000048" iyy="0.00045024" iyz="-0.00000045" izz="0.01380322"/>
    </inertial>
    <visual>
      <geometry>
        <mesh filename="package://piper_description/meshes/link3.obj"/>
      </geometry>
    </visual>
    <collision>
      <geometry>
        <mesh filename="package://piper_description/meshes/link3.obj"/>
      </geometry>
    </collision>
  </link>
  <joint name="right_joint3" type="revolute">
    <origin rpy="0 0 -1.7939" xyz="0.28503 0 0"/>
    <parent link="right_link2"/>
    <child link="right_link3"/>
    <axis xyz="0 0 1"/>
    <limit effort="100" lower="-2.967" upper="0" velocity="5"/>
  </joint>
  <link name="right_link4">
    <inertial>
      <origin rpy="0 0 0" xyz="-9.66635791618542E-05 0.000876064475651083 -0.00496880904640868"/>
      <mass value="0.38"/>
      <inertia ixx="0.00018501" ixy="0.00000054" ixz="0.00000120" iyy="0.00018965" iyz="-0.00000841" izz="0.00015484"/>
    </inertial>
    <visual>
      <geometry>
        <mesh filename="package://piper_description/meshes/link4.obj"/>
      </geometry>
    </visual>
    <collision>
      <geometry>
        <mesh filename="package://piper_description/meshes/link4.obj"/>
      </geometry>
    </collision>
  </link>
  <joint name="right_joint4" type="revolute">
    <origin rpy="1.5708 0 0" xyz="-0.021984 -0.25075 0"/>
    <parent link="right_link3"/>
    <child link="right_link4"/>
    <axis xyz="0 0 1"/>
    <limit effort="100" lower="-1.745" upper="1.745" velocity="5"/>
  </joint>
  <link name="right_link5">
    <inertial>
      <origin rpy="0 0 0" xyz="-4.10554118924211E-05 -0.0566486692356075 -0.0037205791677906"/>
      <mass value="0.383"/>
      <inertia ixx="0.00166169" ixy="0.00000006" ixz="-0.00000007" iyy="0.00018510" iyz="0.00001026" izz="0.00164321"/>
    </inertial>
    <visual>
      <geometry>
        <mesh filename="package://piper_description/meshes/link5.obj"/>
      </geometry>
    </visual>
    <collision>
      <geometry>
        <mesh filename="package://piper_description/meshes/link5.obj"/>
      </geometry>
    </collision>
  </link>
  <joint name="right_joint5" type="revolute">
    <origin rpy="-1.5708 0 0" xyz="0 0 0"/>
    <parent link="right_link4"/>
    <child link="right_link5"/>
    <axis xyz="0 0 1"/>
    <limit effort="100" lower="-1.22" upper="1.22" velocity="5"/>
  </joint>
  <joint name="right_joint6" type="revolute">
    <origin rpy="1.5708 0 0" xyz="0 -0.091 0"/>
    <parent link="right_link5"/>
    <child link="right_link6"/>
    <axis xyz="0 0 1"/>
    <limit effort="100" lower="-2.0944" upper="2.0944" velocity="3"/>
  </joint>
  <link name="right_link6">
    <inertial>
      <origin xyz="-0.000183807162235591 8.05033155577911E-05 0.0321436689908876"/>
      <mass value="0.657"/>
      <inertia ixx="0.00092934" ixy="0.00000034" ixz="-0.00000738" iyy="0.00071447" iyz="0.00000005" izz="0.00039442"/>
    </inertial>
    <visual>
      <geometry>
        <mesh filename="package://piper_description/meshes/link6.obj"/>
      </geometry>
    </visual>
    <collision>
      <geometry>
        <mesh filename="package://piper_description/meshes/link6.obj"/>
      </geometry>
    </collision>
  </link>
  <link name="right_link7">
    <inertial>
      <origin rpy="0 0 0" xyz="0.00065123185041968 -0.0491929869131989 0.00972258769184025"/>
      <mass value="0.025"/>
      <inertia ixx="0.00007371" ixy="-0.00000113" ixz="0.00000021" iyy="0.00000781" iyz="-0.00001372" izz="0.0000747"/>
    </inertial>
    <visual>
      <geometry>
        <mesh filename="package://piper_description/meshes/link7.obj"/>
      </geometry>
    </visual>
    <collision>
      <geometry>
        <mesh filename="package://piper_description/meshes/link7.obj"/>
      </geometry>
    </collision>
  </link>
  <joint name="right_gripper_joint" type="prismatic">
    <origin xyz="0 0 0.1358"/>
    <parent link="right_link6"/>
    <child link="right_link7"/>
    <axis xyz="0 -1 0"/>
    <limit effort="10" lower="0" upper="0.035" velocity="1"/>
  </joint>
  <link name="right_link8">
    <inertial>
      <origin xyz="0.000651231850419722 -0.0491929869131991 0.00972258769184024"/>
      <mass value="0.025"/>
      <inertia ixx="0.00007371" ixy="-0.00000113" ixz="0.00000021" iyy="0.00000781" iyz="-0.00001372" izz="0.0000747"/>
    </inertial>
    <visual>
      <geometry>
        <mesh filename="package://piper_description/meshes/link8.obj"/>
      </geometry>
    </visual>
    <collision>
      <geometry>
        <mesh filename="package://piper_description/meshes/link8.obj"/>
      </geometry>
    </collision>
  </link>
  <joint name="right_joint8" type="prismatic">
    <origin xyz="0 0 0.1358"/>
    <parent link="right_link6"/>
    <child link="right_link8"/>
    <mimic joint="right_gripper_joint" multiplier="1" offset="0"/>
    <axis xyz="0 1 0"/>
    <limit effort="10" lower="0" upper="0.035" velocity="1"/>
  </joint>
  <link name="right_gripper_center"/>
  <joint name="right_gripper_center_fixed" type="fixed">
    <parent link="right_link6"/>
    <child link="right_gripper_center"/>
    <origin rpy="0 -1.57 0" xyz="0 0 0.1358"/>
  </joint>
  <link name="right_camera"/>
  <joint name="right_camera_fixed" type="fixed">
    <origin rpy="0 -1.22 0" xyz="-0.073 0 0.041"/>
    <parent link="right_link6"/>
    <child link="right_camera"/>
  </joint>
  <joint name="arm_and_lifting_right" type="fixed">
    <origin xyz="0.144 -0.306 0.138"/>
    <parent link="lifting_link"/>
    <child link="right_base_link"/>
    <axis xyz="0.0 0.0 0.0"/>
    <limit effort="0.0" lower="0.0" upper="0.0" velocity="0.0"/>
  </joint>
</robot>
