<?xml version="1.0" ?>
<!-- =================================================================================== -->
<!-- |    This document was autogenerated by xacro from robot.xacro                    | -->
<!-- |    EDITING THIS FILE BY HAND IS NOT RECOMMENDED                                 | -->
<!-- =================================================================================== -->
<robot name="rm65">
  <link name="base_link">
    <inertial>
      <origin xyz="-0.00049840293879996 -5.19350047653785E-05 0.0600202841321701"/>
      <mass value="0.838885281114303"/>
      <inertia ixx="0.00172321229549441" ixy="3.09076898315635E-06" ixz="-3.7922126488402E-05" iyy="0.00170514762495823" iyz="1.38793642017112E-06" izz="0.000901589030906685"/>
    </inertial>
    <visual>
      <geometry>
        <mesh filename="package://rm65_description/meshes/base_link.dae"/>
      </geometry>
    </visual>
    <collision>
      <geometry>
        <mesh filename="package://rm65_description/meshes/base_link.dae"/>
      </geometry>
    </collision>
  </link>
  <link name="link1">
    <inertial>
      <origin xyz="-2.9675E-07 0.021107 -0.025188"/>
      <mass value="0.59353"/>
      <inertia ixx="0.0012661" ixy="-5.363E-09" ixz="-2.109E-09" iyy="0.0011816" iyz="-0.00021118" izz="0.00056131"/>
    </inertial>
    <visual>
      <geometry>
        <mesh filename="package://rm65_description/meshes/link1.dae"/>
      </geometry>
    </visual>
    <collision>
      <geometry>
        <mesh filename="package://rm65_description/meshes/link1.dae"/>
      </geometry>
    </collision>
  </link>
  <link name="link2">
    <inertial>
      <origin xyz="0.15226 2.3916E-07 -0.0062027"/>
      <mass value="0.86416"/>
      <inertia ixx="0.00063253" ixy="2.0103E-09" ixz="0.00042162" iyy="0.0020527" iyz="3.5857E-09" izz="0.0019528"/>
    </inertial>
    <visual>
      <geometry>
        <mesh filename="package://rm65_description/meshes/link2.dae"/>
      </geometry>
    </visual>
    <collision>
      <geometry>
        <mesh filename="package://rm65_description/meshes/link2.dae"/>
      </geometry>
    </collision>
  </link>
  <link name="link3">
    <inertial>
      <origin xyz="4.7194E-06 -0.059592 0.010268"/>
      <mass value="0.28963"/>
      <inertia ixx="0.00063737" ixy="-6.2601E-08" ixz="-3.5046E-08" iyy="0.00015649" iyz="-0.00014461" izz="0.00061418"/>
    </inertial>
    <visual>
      <geometry>
        <mesh filename="package://rm65_description/meshes/link3.dae"/>
      </geometry>
    </visual>
    <collision>
      <geometry>
        <mesh filename="package://rm65_description/meshes/link3.dae"/>
      </geometry>
    </collision>
  </link>
  <link name="link4">
    <inertial>
      <origin xyz="2.9186E-07 -0.018042 -0.02154"/>
      <mass value="0.23942"/>
      <inertia ixx="0.00028595" ixy="-2.3562E-09" ixz="1.3938E-09" iyy="0.00026273" iyz="4.424E-05" izz="0.0001199"/>
    </inertial>
    <visual>
      <geometry>
        <mesh filename="package://rm65_description/meshes/link4.dae"/>
      </geometry>
    </visual>
    <collision>
      <geometry>
        <mesh filename="package://rm65_description/meshes/link4.dae"/>
      </geometry>
    </collision>
  </link>
  <link name="link5">
    <inertial>
      <origin xyz="4.2301E-06 -0.059381 0.0070671"/>
      <mass value="0.21879"/>
      <inertia ixx="0.00035053" ixy="-2.8554E-08" ixz="-1.67E-08" iyy="0.00010492" iyz="-7.824E-05" izz="0.00033447"/>
    </inertial>
    <visual>
      <geometry>
        <mesh filename="package://rm65_description/meshes/link5.dae"/>
      </geometry>
    </visual>
    <collision>
      <geometry>
        <mesh filename="package://rm65_description/meshes/link5.dae"/>
      </geometry>
    </collision>
  </link>
  <link name="link6">
    <inertial>
      <origin xyz="0.028764 -5.1529E-06 0.025085"/>
      <mass value="0.22147"/>
      <inertia ixx="0.0001376" ixy="-5.7488E-08" ixz="-1.6634E-05" iyy="0.00026855" iyz="1.7799E-08" izz="0.00035277"/>
    </inertial>
    <visual>
      <geometry>
        <mesh filename="package://rm65_description/meshes/link6.obj"/>
      </geometry>
    </visual>
    <collision>
      <geometry>
        <mesh filename="package://rm65_description/meshes/link6.obj"/>
      </geometry>
    </collision>
  </link>
  <joint name="joint1" type="revolute">
    <origin xyz="0 0 0.2405"/>
    <parent link="base_link"/>
    <child link="link1"/>
    <axis xyz="0 0 1"/>
    <limit effort="60" lower="-3.11" upper="3.11" velocity="3.14"/>
  </joint>
  <joint name="joint2" type="revolute">
    <origin rpy="1.5708 -1.5708 0" xyz="0 0 0"/>
    <parent link="link1"/>
    <child link="link2"/>
    <axis xyz="0 0 1"/>
    <limit effort="60" lower="-2.27" upper="2.27" velocity="3.14"/>
  </joint>
  <joint name="joint3" type="revolute">
    <origin rpy="0 0 1.5708" xyz="0.256 0 0"/>
    <parent link="link2"/>
    <child link="link3"/>
    <axis xyz="0 0 1"/>
    <limit effort="30" lower="-2.36" upper="2.36" velocity="3.925"/>
  </joint>
  <joint name="joint4" type="revolute">
    <origin rpy="1.5708 0 0" xyz="0 -0.21 -0.00030007"/>
    <parent link="link3"/>
    <child link="link4"/>
    <axis xyz="0 0 1"/>
    <limit effort="10" lower="-3.11" upper="3.11" velocity="3.925"/>
  </joint>
  <joint name="joint5" type="revolute">
    <origin rpy="-1.5708 0 0" xyz="0 0 0"/>
    <parent link="link4"/>
    <child link="link5"/>
    <axis xyz="0 0 1"/>
    <limit effort="10" lower="-2.23" upper="2.23" velocity="3.925"/>
  </joint>
  <joint name="joint6" type="revolute">
    <origin rpy="-1.5708 0 0" xyz="0 -0.115 0"/>
    <parent link="link5"/>
    <child link="link6"/>
    <axis xyz="0 0 -1"/>
    <limit effort="10" lower="-6.28" upper="6.28" velocity="3.925"/>
  </joint>
  <link name="gripper_plate">
    <visual>
      <geometry>
        <mesh filename="package://rm65_description/meshes/gripper_plate.obj"/>
      </geometry>
    </visual>
    <collision>
      <geometry>
        <mesh filename="package://rm65_description/meshes/gripper_plate.obj"/>
      </geometry>
    </collision>
  </link>
  <joint name="ee_joint" type="fixed">
    <origin rpy="3.14159 0 1.5708" xyz="0 0 -0.043"/>
    <parent link="link6"/>
    <child link="gripper_plate"/>
  </joint>
  <link name="gripper_base">
    <inertial>
      <origin xyz="1.5645E-05 -4.1838E-06 0.038"/>
      <mass value="0.072633"/>
      <inertia ixx="5.095E-05" ixy="-7.3167E-13" ixz="2.0229E-08" iyy="6.0883E-05" iyz="-4.5583E-09" izz="1.933E-05"/>
    </inertial>
    <visual>
      <geometry>
        <mesh filename="package://inspire_description/meshes/EG2-4C2/baselink.obj"/>
      </geometry>
    </visual>
    <collision>
      <geometry>
        <mesh filename="package://inspire_description/meshes/EG2-4C2/baselink.obj"/>
      </geometry>
    </collision>
  </link>
  <link name="left_outer_link">
    <inertial>
      <origin xyz="0.0087669 0.009 0.013992"/>
      <mass value="0.0024292"/>
      <inertia ixx="5.1061E-07" ixy="-8.6739E-19" ixz="-2.508E-07" iyy="5.7398E-07" iyz="-1.3667E-18" izz="2.6747E-07"/>
    </inertial>
    <visual>
      <geometry>
        <mesh filename="package://inspire_description/meshes/EG2-4C2/outer_link.obj"/>
      </geometry>
    </visual>
    <collision>
      <geometry>
        <mesh filename="package://inspire_description/meshes/EG2-4C2/outer_link.obj"/>
      </geometry>
    </collision>
  </link>
  <joint name="gripper_joint" type="revolute">
    <origin xyz="-0.04 -0.009 0.079"/>
    <parent link="gripper_base"/>
    <child link="left_outer_link"/>
    <axis xyz="0 -1 0"/>
    <limit effort="1" lower="0" upper="0.82" velocity="1"/>
  </joint>
  <link name="left_inner_link">
    <inertial>
      <origin xyz="0.0087435 0.009 0.013955"/>
      <mass value="0.0038971"/>
      <inertia ixx="5.6941E-07" ixy="-1.0711E-18" ixz="-2.6891E-07" iyy="6.2305E-07" iyz="-1.6845E-18" izz="3.0871E-07"/>
    </inertial>
    <visual>
      <geometry>
        <mesh filename="package://inspire_description/meshes/EG2-4C2/inner_link.obj"/>
      </geometry>
    </visual>
    <collision>
      <geometry>
        <mesh filename="package://inspire_description/meshes/EG2-4C2/inner_link.obj"/>
      </geometry>
    </collision>
  </link>
  <joint name="left_inner_joint" type="revolute">
    <origin xyz="-0.03 -0.009 0.081"/>
    <parent link="gripper_base"/>
    <child link="left_inner_link"/>
    <axis xyz="0 -1 0"/>
    <limit effort="1" lower="0" upper="0.82" velocity="1"/>
    <mimic joint="gripper_joint"/>
  </joint>
  <link name="right_inner_link">
    <inertial>
      <origin xyz="-0.0087435 0.009 0.013955"/>
      <mass value="0.0038971"/>
      <inertia ixx="5.6941E-07" ixy="1.0666E-18" ixz="2.6891E-07" iyy="6.2305E-07" iyz="-1.8084E-18" izz="3.0871E-07"/>
    </inertial>
    <visual>
      <geometry>
        <mesh filename="package://inspire_description/meshes/EG2-4C2/inner_link.obj" scale="-1 1 1"/>
      </geometry>
    </visual>
    <collision>
      <geometry>
        <mesh filename="package://inspire_description/meshes/EG2-4C2/inner_link.obj" scale="-1 1 1"/>
      </geometry>
    </collision>
  </link>
  <joint name="right_inner_joint" type="revolute">
    <origin xyz="0.03 -0.009 0.081"/>
    <parent link="gripper_base"/>
    <child link="right_inner_link"/>
    <axis xyz="0 -1 0"/>
    <limit effort="1" lower="-0.82" upper="0" velocity="1"/>
    <mimic joint="gripper_joint" multiplier="-1" offset="0"/>
  </joint>
  <link name="right_outer_link">
    <inertial>
      <origin xyz="-0.0087669 0.009 0.013992"/>
      <mass value="0.0024292"/>
      <inertia ixx="5.1061E-07" ixy="-9.5279E-19" ixz="2.508E-07" iyy="5.7398E-07" iyz="7.6863E-19" izz="2.6747E-07"/>
    </inertial>
    <visual>
      <geometry>
        <mesh filename="package://inspire_description/meshes/EG2-4C2/outer_link.obj" scale="-1 1 1"/>
      </geometry>
    </visual>
    <collision>
      <geometry>
        <mesh filename="package://inspire_description/meshes/EG2-4C2/outer_link.obj" scale="-1 1 1"/>
      </geometry>
    </collision>
  </link>
  <joint name="right_outer_joint" type="revolute">
    <origin xyz="0.04 -0.009 0.079"/>
    <parent link="gripper_base"/>
    <child link="right_outer_link"/>
    <axis xyz="0 -1 0"/>
    <limit effort="1" lower="-0.82" upper="0" velocity="1"/>
    <mimic joint="gripper_joint" multiplier="-1" offset="0"/>
  </joint>
  <link name="left_pad">
    <inertial>
      <origin xyz="0.011864 0.006 0.011367"/>
      <mass value="0.0045068"/>
      <inertia ixx="5.1288E-07" ixy="-9.8137E-14" ixz="-9.4703E-08" iyy="5.3203E-07" iyz="-6.212E-14" izz="2.009E-07"/>
    </inertial>
    <visual>
      <geometry>
        <mesh filename="package://inspire_description/meshes/EG2-4C2/pad.obj"/>
      </geometry>
    </visual>
    <collision>
      <geometry>
        <mesh filename="package://inspire_description/meshes/EG2-4C2/pad.obj"/>
      </geometry>
    </collision>
  </link>
  <joint name="left_pad_joint" type="revolute">
    <origin xyz="0.0223 0.003 0.035591"/>
    <parent link="left_outer_link"/>
    <child link="left_pad"/>
    <axis xyz="0 1 0"/>
    <limit effort="1" lower="0" upper="0.82" velocity="1"/>
    <mimic joint="gripper_joint"/>
  </joint>
  <link name="right_pad">
    <inertial>
      <origin xyz="-0.011864 0.006 0.011367"/>
      <mass value="0.0045068"/>
      <inertia ixx="5.1288E-07" ixy="-9.8137E-14" ixz="9.4703E-08" iyy="5.3203E-07" iyz="6.2119E-14" izz="2.009E-07"/>
    </inertial>
    <visual>
      <geometry>
        <mesh filename="package://inspire_description/meshes/EG2-4C2/pad.obj" scale="-1 1 1"/>
      </geometry>
    </visual>
    <collision>
      <geometry>
        <mesh filename="package://inspire_description/meshes/EG2-4C2/pad.obj" scale="-1 1 1"/>
      </geometry>
    </collision>
  </link>
  <joint name="right_pad_joint" type="revolute">
    <origin xyz="-0.0223 0.003 0.035591"/>
    <parent link="right_outer_link"/>
    <child link="right_pad"/>
    <axis xyz="0 -1 0"/>
    <limit effort="1" lower="0" upper="0.82" velocity="1"/>
    <mimic joint="gripper_joint"/>
  </joint>
  <joint name="gripper_base_joint" type="fixed">
    <origin xyz="0 0 0.0043"/>
    <parent link="gripper_plate"/>
    <child link="gripper_base"/>
  </joint>
</robot>
