<?xml version="1.0" ?>
<!-- =================================================================================== -->
<!-- |    This document was autogenerated by xacro from robot.xacro                    | -->
<!-- |    EDITING THIS FILE BY HAND IS NOT RECOMMENDED                                 | -->
<!-- =================================================================================== -->
<robot name="A1 Single">
  <link name="base_link">
    <inertial>
      <origin xyz="-0.0005634 0.038934 3.1874E-06"/>
      <mass value="1.658"/>
      <inertia ixx="0.0010597" ixy="1.9821E-05" ixz="-1.6752E-07" iyy="0.0011787" iyz="-1.9146E-07" izz="0.0010647"/>
    </inertial>
    <visual>
      <geometry>
        <mesh filename="package://galaxea_a1_description/meshes/a1/base_link.obj"/>
      </geometry>
    </visual>
    <collision>
      <geometry>
        <mesh filename="package://galaxea_a1_description/meshes/a1/base_link.obj"/>
      </geometry>
    </collision>
  </link>
  <link name="link1">
    <inertial>
      <origin xyz="0.000015 0.105259 -0.001954"/>
      <mass value="1.164"/>
      <inertia ixx="0.001125" ixy="0.0" ixz="0.0" iyy="0.001084" iyz="-0.000023" izz="0.001158"/>
    </inertial>
    <visual>
      <geometry>
        <mesh filename="package://galaxea_a1_description/meshes/a1/link1.obj"/>
      </geometry>
    </visual>
    <collision>
      <geometry>
        <mesh filename="package://galaxea_a1_description/meshes/a1/link1.obj"/>
      </geometry>
    </collision>
  </link>
  <joint name="joint1" type="revolute">
    <origin xyz="-0.0011147 0 0.0446"/>
    <parent link="base_link"/>
    <child link="link1"/>
    <axis xyz="0 0 1"/>
    <limit effort="40" lower="-2.8798" upper="2.8798" velocity="20.944"/>
  </joint>
  <link name="link2">
    <inertial>
      <origin rpy="0 0 0" xyz="-0.23622 0.016352 -0.00013275"/>
      <mass value="1.3"/>
      <inertia ixx="0.00060638" ixy="0.00041817" ixz="0.00014956" iyy="0.0075936" iyz="-8.0916E-06" izz="0.0075712"/>
    </inertial>
    <visual>
      <geometry>
        <mesh filename="package://galaxea_a1_description/meshes/a1/link2.obj"/>
      </geometry>
    </visual>
    <collision>
      <geometry>
        <mesh filename="package://galaxea_a1_description/meshes/a1/link2.obj"/>
      </geometry>
    </collision>
  </link>
  <joint name="joint2" type="revolute">
    <origin rpy="1.5708 0 0" xyz="0 0 0.1061"/>
    <parent link="link1"/>
    <child link="link2"/>
    <axis xyz="0 0 -1"/>
    <limit effort="40" lower="0" upper="3.2289" velocity="20.944"/>
  </joint>
  <link name="link3">
    <inertial>
      <origin rpy="0 0 0" xyz="0.045114 0.054616 -0.00045593"/>
      <mass value="0.818"/>
      <inertia ixx="0.00060107" ixy="-0.00022467" ixz="-7.1194E-06" iyy="0.0013959" iyz="-9.7503E-06" izz="0.0015027"/>
    </inertial>
    <visual>
      <origin rpy="0 0 0" xyz="0 0 0"/>
      <geometry>
        <mesh filename="package://galaxea_a1_description/meshes/a1/link3.obj"/>
      </geometry>
      <material name="">
        <color rgba="0.79216 0.81961 0.93333 1"/>
      </material>
    </visual>
    <collision>
      <origin rpy="0 0 0" xyz="0 0 0"/>
      <geometry>
        <mesh filename="package://galaxea_a1_description/meshes/a1/link3.obj"/>
      </geometry>
    </collision>
  </link>
  <joint name="joint3" type="revolute">
    <origin rpy="0 0 0" xyz="-0.34928 0.019998 0"/>
    <parent link="link2"/>
    <child link="link3"/>
    <axis xyz="0 0 -1"/>
    <limit effort="27" lower="-3.3161" upper="0" velocity="7.5398"/>
  </joint>
  <link name="link4">
    <inertial>
      <origin rpy="0 0 0" xyz="0.24285 0.0023784 1.279E-06"/>
      <mass value="0.698"/>
      <inertia ixx="8.45E-05" ixy="-8.2627E-07" ixz="-2.2607E-09" iyy="0.00010174" iyz="5.3612E-09" izz="9.7044E-05"/>
    </inertial>
    <visual>
      <origin rpy="0 0 0" xyz="0 0 0"/>
      <geometry>
        <mesh filename="package://galaxea_a1_description/meshes/a1/link4.obj"/>
      </geometry>
      <material name="">
        <color rgba="1 1 1 1"/>
      </material>
    </visual>
    <collision>
      <origin rpy="0 0 0" xyz="0 0 0"/>
      <geometry>
        <mesh filename="package://galaxea_a1_description/meshes/a1/link4.obj"/>
      </geometry>
    </collision>
  </link>
  <joint name="joint4" type="revolute">
    <origin rpy="0 0 0" xyz="0.02735 0.069767 0"/>
    <parent link="link3"/>
    <child link="link4"/>
    <axis xyz="1 0 0"/>
    <limit effort="7" lower="-2.8798" upper="2.8798" velocity="25.133"/>
  </joint>
  <link name="link5">
    <inertial>
      <origin rpy="0 0 0" xyz="0.054309 0.0041811 4.0699E-06"/>
      <mass value="0.417"/>
      <inertia ixx="8.3999E-05" ixy="1.6234E-05" ixz="7.4127E-08" iyy="9.8498E-05" iyz="-1.3811E-08" izz="0.00011333"/>
    </inertial>
    <visual>
      <origin rpy="0 0 0" xyz="0 0 0"/>
      <geometry>
        <mesh filename="package://galaxea_a1_description/meshes/a1/link5.obj"/>
      </geometry>
      <material name="">
        <color rgba="1 1 1 1"/>
      </material>
    </visual>
    <collision>
      <origin rpy="0 0 0" xyz="0 0 0"/>
      <geometry>
        <mesh filename="package://galaxea_a1_description/meshes/a1/link5.obj"/>
      </geometry>
    </collision>
  </link>
  <joint name="joint5" type="revolute">
    <origin rpy="0 0 0" xyz="0.2463 -0.00049894 0"/>
    <parent link="link4"/>
    <child link="link5"/>
    <axis xyz="0 1 0"/>
    <limit effort="7" lower="-1.6581" upper="1.6581" velocity="25.133"/>
  </joint>
  <link name="link6">
    <inertial>
      <origin rpy="0 0 0" xyz="0.028138 1.2134E-07 5.4049E-08"/>
      <mass value="0.037"/>
      <inertia ixx="3.5662E-06" ixy="6.6514E-12" ixz="2.9628E-12" iyy="2.0238E-06" iyz="-4.1666E-12" izz="2.0238E-06"/>
    </inertial>
    <visual>
      <origin rpy="0 0 0" xyz="0 0 0"/>
      <geometry>
        <mesh filename="package://galaxea_a1_description/meshes/a1/link6.obj"/>
      </geometry>
      <material name="">
        <color rgba="0.82353 0.82353 1 1"/>
      </material>
    </visual>
    <collision>
      <origin rpy="0 0 0" xyz="0 0 0"/>
      <geometry>
        <mesh filename="package://galaxea_a1_description/meshes/a1/link6.obj"/>
      </geometry>
    </collision>
  </link>
  <joint name="joint6" type="revolute">
    <origin rpy="0 0 0" xyz="0.058249 0.00050025 0"/>
    <parent link="link5"/>
    <child link="link6"/>
    <axis xyz="1 0 0"/>
    <limit effort="7" lower="-2.8798" upper="2.8798" velocity="25.133"/>
  </joint>
  <link name="gripper_base">
    <inertial>
      <origin xyz="-0.0311072323899603 1.17979991887118E-08 7.93394685505433E-08"/>
      <mass value="0.604"/>
      <inertia ixx="0.000175881544189539" ixy="-6.06026450851008E-11" ixz="5.30643405624365E-10" iyy="9.86379407701341E-05" iyz="-8.18686692495892E-08" izz="0.000165121280580029"/>
    </inertial>
    <visual>
      <geometry>
        <mesh filename="package://galaxea_a1_description/meshes/gripper/gripper_link.obj"/>
      </geometry>
    </visual>
    <collision>
      <geometry>
        <mesh filename="package://galaxea_a1_description/meshes/gripper/gripper_link.obj"/>
      </geometry>
    </collision>
  </link>
  <link name="finger1">
    <inertial>
      <origin xyz="-0.0195895895552112 -0.0151136845490034 0.00542254359093075"/>
      <mass value="0.027"/>
      <inertia ixx="2.40569358477209E-06" ixy="3.9898459609048E-07" ixz="5.12152762183641E-08" iyy="5.71079298307516E-06" iyz="6.19467902008363E-08" izz="6.48482183930358E-06"/>
    </inertial>
    <visual>
      <geometry>
        <mesh filename="package://galaxea_a1_description/meshes/gripper/finger.obj"/>
      </geometry>
    </visual>
    <collision>
      <geometry>
        <mesh filename="package://galaxea_a1_description/meshes/gripper/finger.obj"/>
      </geometry>
    </collision>
  </link>
  <joint name="gripper_joint" type="prismatic">
    <origin xyz="0.03689 0.013453 0.00012059"/>
    <parent link="gripper_base"/>
    <child link="finger1"/>
    <axis xyz="0 1 0"/>
    <limit effort="100" lower="0" upper="0.05" velocity="0.25"/>
  </joint>
  <link name="finger2">
    <inertial>
      <origin xyz="-0.0195895857999098 0.0151136893508115 -0.00542254357246619"/>
      <mass value="0.027"/>
      <inertia ixx="2.40569340151687E-06" ixy="-3.98983784827124E-07" ixz="-5.12152683073981E-08" iyy="5.71079321589929E-06" iyz="6.19467953006536E-08" izz="6.48482187274222E-06"/>
    </inertial>
    <visual>
      <geometry>
        <mesh filename="package://galaxea_a1_description/meshes/gripper/finger.obj" scale="1 -1 -1"/>
      </geometry>
    </visual>
    <collision>
      <geometry>
        <mesh filename="package://galaxea_a1_description/meshes/gripper/finger.obj" scale="1 -1 -1"/>
      </geometry>
    </collision>
  </link>
  <joint name="gripper_joint2" type="prismatic">
    <origin xyz="0.03689 -0.013453 -0.00012059"/>
    <parent link="gripper_base"/>
    <child link="finger2"/>
    <axis xyz="0 -1 0"/>
    <limit effort="100" lower="0" upper="0.05" velocity="0.25"/>
    <mimic joint="gripper_joint" multiplier="1" offset="0"/>
  </joint>
  <link name="gripper_center"/>
  <joint name="gripper_center_joint" type="fixed">
    <origin xyz="0.03689 0 -0.00012059"/>
    <parent link="gripper_base"/>
    <child link="gripper_center"/>
  </joint>
  <origin rpy="-1.5708 0 0" xyz="0.1039 0 0"/>
  <joint name="gripper_base_joint" type="fixed">
    <origin rpy="-1.5708 0 0" xyz="0.1039 0 0"/>
    <parent link="link6"/>
    <child link="gripper_base"/>
  </joint>
</robot>
