<?xml version="1.0" ?>
<!-- =================================================================================== -->
<!-- |    This document was autogenerated by xacro from robot.xacro                    | -->
<!-- |    EDITING THIS FILE BY HAND IS NOT RECOMMENDED                                 | -->
<!-- =================================================================================== -->
<robot name="A1 Single">
  <!-- Base Link -->
  <link name="base_link">
    <inertial>
      <origin xyz="0.00303246421307354 -0.000695340443194854 0.0297996781638517"/>
      <mass value="0.786"/>
      <inertia ixx="0.000209631286775999" ixy="1.3987766340865E-06" ixz="5.68764766805313E-06" iyy="0.000199785107628426" iyz="-3.65982104907021E-06" izz="0.000237444184695321"/>
    </inertial>
    <visual>
      <geometry>
        <mesh filename="package://galaxea_a1_description/meshes/a1_xy/base_link.obj"/>
      </geometry>
    </visual>
    <collision>
      <geometry>
        <mesh filename="package://galaxea_a1_description/meshes/a1_xy/base_link.obj"/>
      </geometry>
    </collision>
  </link>
  <!-- Link 1 -->
  <link name="link1">
    <inertial>
      <origin xyz="4.1065175135883E-07 -0.00198628171247454 0.0468863413356551"/>
      <mass value="0.839"/>
      <inertia ixx="0.000224135392915726" ixy="-1.28206810172038E-09" ixz="7.50235402650185E-09" iyy="0.00026979982869931" iyz="7.49527197322758E-09" izz="0.000218724360467532"/>
    </inertial>
    <visual>
      <origin xyz="0 0 0"/>
      <geometry>
        <mesh filename="package://galaxea_a1_description/meshes/a1_xy/link1.obj"/>
      </geometry>
      <material name="">
        <color rgba="0.823529411764706 0.823529411764706 1 1"/>
      </material>
    </visual>
    <collision>
      <origin xyz="0 0 0"/>
      <geometry>
        <mesh filename="package://galaxea_a1_description/meshes/a1_xy/link1.obj"/>
      </geometry>
    </collision>
  </link>
  <!-- Joint 1: Base to Link1 -->
  <joint name="joint1" type="revolute">
    <origin xyz="0 0 0.08605"/>
    <parent link="base_link"/>
    <child link="link1"/>
    <axis xyz="0 0 1"/>
    <limit effort="27" lower="-2.879795" upper="2.879795" velocity="10.4720"/>
  </joint>
  <!-- Link 2 -->
  <link name="link2">
    <inertial>
      <origin xyz="-0.122673818397923 -0.0295401461831619 0.00364838977156251"/>
      <mass value="1.09"/>
      <inertia ixx="0.000388311522528777" ixy="-2.18086613093501E-05" ixz="8.77434895649448E-06" iyy="0.00274683151904258" iyz="1.19756607314247E-06" izz="0.00278055331308976"/>
    </inertial>
    <visual>
      <origin xyz="0 0 0"/>
      <geometry>
        <mesh filename="package://galaxea_a1_description/meshes/a1_xy/link2.obj"/>
      </geometry>
      <material name="">
        <color rgba="0.823529411764706 0.823529411764706 1 1"/>
      </material>
    </visual>
    <collision>
      <origin xyz="0 0 0"/>
      <geometry>
        <mesh filename="package://galaxea_a1_description/meshes/a1_xy/link2.obj"/>
      </geometry>
    </collision>
  </link>
  <!-- Joint 2: Link1 to Link2 -->
  <joint name="joint2" type="revolute">
    <origin xyz="0 0.03075 0.04925"/>
    <parent link="link1"/>
    <child link="link2"/>
    <axis xyz="0 1 0"/>
    <limit effort="50" lower="0" upper="3.1416" velocity="12.5664"/>
  </joint>
  <link name="link3">
    <inertial>
      <origin xyz="0.0795681449160072 -0.0327357454565678 0.065177920553168"/>
      <mass value="0.762"/>
      <inertia ixx="0.000282703505875711" ixy="-4.06256349285171E-06" ixz="-7.63228373259732E-05" iyy="0.000329835410245831" iyz="-1.03493005263955E-05" izz="0.000237652038430906"/>
    </inertial>
    <visual>
      <geometry>
        <mesh filename="package://galaxea_a1_description/meshes/a1_xy/a1_y/link3.obj"/>
      </geometry>
    </visual>
    <collision>
      <geometry>
        <mesh filename="package://galaxea_a1_description/meshes/a1_xy/a1_y/link3.obj"/>
      </geometry>
    </collision>
  </link>
  <joint name="joint3" type="revolute">
    <origin rpy="0 0 0" xyz="-0.3 0.00024449 0"/>
    <parent link="link2"/>
    <child link="link3"/>
    <axis xyz="0 1 0"/>
    <limit effort="27" lower="-3.316127" upper="0" velocity="10.4720"/>
  </joint>
  <link name="link4">
    <inertial>
      <origin rpy="0 0 0" xyz="0.0388578803222686 0.000937806543809841 -1.15721572034322E-05"/>
      <mass value="0.353"/>
      <inertia ixx="5.97701758868814E-05" ixy="-6.87774799668449E-10" ixz="-2.14372946639157E-10" iyy="6.0587917049985E-05" iyz="-5.98401601618766E-11" izz="5.98342278178533E-05"/>
    </inertial>
    <visual>
      <geometry>
        <mesh filename="package://galaxea_a1_description/meshes/a1_xy/a1_y/link4.obj"/>
      </geometry>
    </visual>
    <collision>
      <geometry>
        <mesh filename="package://galaxea_a1_description/meshes/a1_xy/a1_y/link4.obj"/>
      </geometry>
    </collision>
  </link>
  <joint name="joint4" type="revolute">
    <origin rpy="0 0 0" xyz="0.1544 -0.030998 0.075485"/>
    <parent link="link3"/>
    <child link="link4"/>
    <axis xyz="1 0 0"/>
    <limit effort="14" lower="-2.879795" upper="2.879795" velocity="32.9867"/>
  </joint>
  <link name="link5">
    <inertial>
      <origin rpy="0 0 0" xyz="0.0526293728146609 -0.0197387756630963 7.38547745043894E-06"/>
      <mass value="0.366"/>
      <inertia ixx="5.87226827172217E-05" ixy="3.94835644387525E-09" ixz="-1.57113932950695E-12" iyy="6.96559934519655E-05" iyz="7.55674102061766E-09" izz="6.85055623583414E-05"/>
    </inertial>
    <visual>
      <geometry>
        <mesh filename="package://galaxea_a1_description/meshes/a1_xy/a1_y/link5.obj"/>
      </geometry>
    </visual>
    <collision>
      <geometry>
        <mesh filename="package://galaxea_a1_description/meshes/a1_xy/a1_y/link5.obj"/>
      </geometry>
    </collision>
  </link>
  <joint name="joint5" type="revolute">
    <origin rpy="0 0 0" xyz="0.0418 0.023501 0"/>
    <parent link="link4"/>
    <child link="link5"/>
    <axis xyz="0 1 0"/>
    <limit effort="14" lower="-1.832597" upper="1.832597" velocity="32.9867"/>
  </joint>
  <link name="link6">
    <inertial>
      <origin rpy="0 0 0" xyz="0.00709944781467154 1.26586535489642E-07 -3.8262881471296E-05"/>
      <mass value="0.031"/>
      <inertia ixx="3.44528457425794E-06" ixy="2.98138934982256E-11" ixz="-1.26128084918303E-09" iyy="1.82573408455416E-06" iyz="1.17092872453752E-14" izz="1.8173151968758E-06"/>
    </inertial>
    <visual>
      <geometry>
        <mesh filename="package://galaxea_a1_description/meshes/a1_xy/link6.obj"/>
      </geometry>
    </visual>
    <collision>
      <geometry>
        <mesh filename="package://galaxea_a1_description/meshes/a1_xy/link6.obj"/>
      </geometry>
    </collision>
  </link>
  <joint name="joint6" type="revolute">
    <origin rpy="0 0 0" xyz="0.081 -0.023499 0"/>
    <parent link="link5"/>
    <child link="link6"/>
    <axis xyz="1 0 0"/>
    <limit effort="14" lower="-2.879795" upper="2.879795" velocity="32.9867"/>
  </joint>
  <link name="gripper_base">
    <inertial>
      <origin xyz="-0.0311072323899603 1.17979991887118E-08 7.93394685505433E-08"/>
      <mass value="0.604"/>
      <inertia ixx="0.000175881544189539" ixy="-6.06026450851008E-11" ixz="5.30643405624365E-10" iyy="9.86379407701341E-05" iyz="-8.18686692495892E-08" izz="0.000165121280580029"/>
    </inertial>
    <visual>
      <geometry>
        <mesh filename="package://galaxea_a1_description/meshes/gripper/gripper_link.obj"/>
      </geometry>
    </visual>
    <collision>
      <geometry>
        <mesh filename="package://galaxea_a1_description/meshes/gripper/gripper_link.obj"/>
      </geometry>
    </collision>
  </link>
  <link name="finger1">
    <inertial>
      <origin xyz="-0.0195895895552112 -0.0151136845490034 0.00542254359093075"/>
      <mass value="0.027"/>
      <inertia ixx="2.40569358477209E-06" ixy="3.9898459609048E-07" ixz="5.12152762183641E-08" iyy="5.71079298307516E-06" iyz="6.19467902008363E-08" izz="6.48482183930358E-06"/>
    </inertial>
    <visual>
      <geometry>
        <mesh filename="package://galaxea_a1_description/meshes/gripper/finger.obj"/>
      </geometry>
    </visual>
    <collision>
      <geometry>
        <mesh filename="package://galaxea_a1_description/meshes/gripper/finger.obj"/>
      </geometry>
    </collision>
  </link>
  <joint name="gripper_joint" type="prismatic">
    <origin xyz="0.03689 0.013453 0.00012059"/>
    <parent link="gripper_base"/>
    <child link="finger1"/>
    <axis xyz="0 1 0"/>
    <limit effort="100" lower="0" upper="0.05" velocity="0.25"/>
  </joint>
  <link name="finger2">
    <inertial>
      <origin xyz="-0.0195895857999098 0.0151136893508115 -0.00542254357246619"/>
      <mass value="0.027"/>
      <inertia ixx="2.40569340151687E-06" ixy="-3.98983784827124E-07" ixz="-5.12152683073981E-08" iyy="5.71079321589929E-06" iyz="6.19467953006536E-08" izz="6.48482187274222E-06"/>
    </inertial>
    <visual>
      <geometry>
        <mesh filename="package://galaxea_a1_description/meshes/gripper/finger.obj" scale="1 -1 -1"/>
      </geometry>
    </visual>
    <collision>
      <geometry>
        <mesh filename="package://galaxea_a1_description/meshes/gripper/finger.obj" scale="1 -1 -1"/>
      </geometry>
    </collision>
  </link>
  <joint name="gripper_joint2" type="prismatic">
    <origin xyz="0.03689 -0.013453 -0.00012059"/>
    <parent link="gripper_base"/>
    <child link="finger2"/>
    <axis xyz="0 -1 0"/>
    <limit effort="100" lower="0" upper="0.05" velocity="0.25"/>
    <mimic joint="gripper_joint" multiplier="1" offset="0"/>
  </joint>
  <link name="gripper_center"/>
  <joint name="gripper_center_joint" type="fixed">
    <origin xyz="0.03689 0 -0.00012059"/>
    <parent link="gripper_base"/>
    <child link="gripper_center"/>
  </joint>
  <joint name="gripper_base_joint" type="fixed">
    <origin xyz="0.08165 0 0"/>
    <parent link="link6"/>
    <child link="gripper_base"/>
  </joint>
</robot>
