<?xml version="1.0" ?>
<!-- =================================================================================== -->
<!-- |    This document was autogenerated by xacro from robot.xacro                    | -->
<!-- |    EDITING THIS FILE BY HAND IS NOT RECOMMENDED                                 | -->
<!-- =================================================================================== -->
<robot name="Piper single">
  <link name="base_link">
    <inertial>
      <origin xyz="-0.00473641164191482 2.56829134630247E-05 0.041451518036016"/>
      <mass value="1.02"/>
      <inertia ixx="0.00267433" ixy="-0.00000073" ixz="-0.00017389" iyy="0.00282612" iyz="0.0000004" izz="0.00089624"/>
    </inertial>
    <visual>
      <geometry>
        <mesh filename="package://piper_description/meshes/base_link.obj"/>
      </geometry>
    </visual>
    <collision>
      <geometry>
        <mesh filename="package://piper_description/meshes/base_link.obj"/>
      </geometry>
    </collision>
  </link>
  <link name="link1">
    <inertial>
      <origin xyz="0.000121504734057468 0.000104632162460536 -0.00438597309559853"/>
      <mass value="0.71"/>
      <inertia ixx="0.00048916" ixy="-0.00000036" ixz="-0.00000224" iyy="0.00040472" iyz="-0.00000242" izz="0.00043982"/>
    </inertial>
    <visual>
      <geometry>
        <mesh filename="package://piper_description/meshes/link1.obj"/>
      </geometry>
    </visual>
    <collision>
      <geometry>
        <mesh filename="package://piper_description/meshes/link1.obj"/>
      </geometry>
    </collision>
  </link>
  <joint name="joint1" type="revolute">
    <origin rpy="0 0 0" xyz="0 0 0.123"/>
    <parent link="base_link"/>
    <child link="link1"/>
    <axis xyz="0 0 1"/>
    <limit effort="100" lower="-2.618" upper="2.618" velocity="5"/>
  </joint>
  <link name="link2">
    <inertial>
      <origin rpy="0 0 0" xyz="0.198666145229743 -0.010926924140076 0.00142121714502687"/>
      <mass value="1.17"/>
      <inertia ixx="0.00116918" ixy="-0.00180037" ixz="0.00025146" iyy="0.06785384" iyz="-0.00000455" izz="0.06774489"/>
    </inertial>
    <visual>
      <geometry>
        <mesh filename="package://piper_description/meshes/link2.obj"/>
      </geometry>
    </visual>
    <collision>
      <geometry>
        <mesh filename="package://piper_description/meshes/link2.obj"/>
      </geometry>
    </collision>
  </link>
  <joint name="joint2" type="revolute">
    <origin rpy="1.5708 -0.1359 -3.1416" xyz="0 0 0"/>
    <parent link="link1"/>
    <child link="link2"/>
    <axis xyz="0 0 1"/>
    <limit effort="100" lower="0" upper="3.14" velocity="5"/>
  </joint>
  <link name="link3">
    <inertial>
      <origin rpy="0 0 0" xyz="-0.0202737662122021 -0.133914995944595 -0.000458682652737356"/>
      <mass value="0.5"/>
      <inertia ixx="0.01361711" ixy="0.00165794" ixz="-0.00000048" iyy="0.00045024" iyz="-0.00000045" izz="0.01380322"/>
    </inertial>
    <visual>
      <geometry>
        <mesh filename="package://piper_description/meshes/link3.obj"/>
      </geometry>
    </visual>
    <collision>
      <geometry>
        <mesh filename="package://piper_description/meshes/link3.obj"/>
      </geometry>
    </collision>
  </link>
  <joint name="joint3" type="revolute">
    <origin rpy="0 0 -1.7939" xyz="0.28503 0 0"/>
    <parent link="link2"/>
    <child link="link3"/>
    <axis xyz="0 0 1"/>
    <limit effort="100" lower="-2.967" upper="0" velocity="5"/>
  </joint>
  <link name="link4">
    <inertial>
      <origin rpy="0 0 0" xyz="-9.66635791618542E-05 0.000876064475651083 -0.00496880904640868"/>
      <mass value="0.38"/>
      <inertia ixx="0.00018501" ixy="0.00000054" ixz="0.00000120" iyy="0.00018965" iyz="-0.00000841" izz="0.00015484"/>
    </inertial>
    <visual>
      <geometry>
        <mesh filename="package://piper_description/meshes/link4.obj"/>
      </geometry>
    </visual>
    <collision>
      <geometry>
        <mesh filename="package://piper_description/meshes/link4.obj"/>
      </geometry>
    </collision>
  </link>
  <joint name="joint4" type="revolute">
    <origin rpy="1.5708 0 0" xyz="-0.021984 -0.25075 0"/>
    <parent link="link3"/>
    <child link="link4"/>
    <axis xyz="0 0 1"/>
    <limit effort="100" lower="-1.745" upper="1.745" velocity="5"/>
  </joint>
  <link name="link5">
    <inertial>
      <origin rpy="0 0 0" xyz="-4.10554118924211E-05 -0.0566486692356075 -0.0037205791677906"/>
      <mass value="0.383"/>
      <inertia ixx="0.00166169" ixy="0.00000006" ixz="-0.00000007" iyy="0.00018510" iyz="0.00001026" izz="0.00164321"/>
    </inertial>
    <visual>
      <geometry>
        <mesh filename="package://piper_description/meshes/link5.obj"/>
      </geometry>
    </visual>
    <collision>
      <geometry>
        <mesh filename="package://piper_description/meshes/link5.obj"/>
      </geometry>
    </collision>
  </link>
  <joint name="joint5" type="revolute">
    <origin rpy="-1.5708 0 0" xyz="0 0 0"/>
    <parent link="link4"/>
    <child link="link5"/>
    <axis xyz="0 0 1"/>
    <limit effort="100" lower="-1.22" upper="1.22" velocity="5"/>
  </joint>
  <joint name="joint6" type="revolute">
    <origin rpy="1.5708 0 0" xyz="0 -0.091 0"/>
    <parent link="link5"/>
    <child link="link6"/>
    <axis xyz="0 0 1"/>
    <limit effort="100" lower="-2.0944" upper="2.0944" velocity="3"/>
  </joint>
  <link name="link6">
    <inertial>
      <origin xyz="-0.000183807162235591 8.05033155577911E-05 0.0321436689908876"/>
      <mass value="0.657"/>
      <inertia ixx="0.00092934" ixy="0.00000034" ixz="-0.00000738" iyy="0.00071447" iyz="0.00000005" izz="0.00039442"/>
    </inertial>
    <visual>
      <geometry>
        <mesh filename="package://piper_description/meshes/link6.obj"/>
      </geometry>
    </visual>
    <collision>
      <geometry>
        <mesh filename="package://piper_description/meshes/link6.obj"/>
      </geometry>
    </collision>
  </link>
  <link name="link7">
    <inertial>
      <origin rpy="0 0 0" xyz="0.00065123185041968 -0.0491929869131989 0.00972258769184025"/>
      <mass value="0.025"/>
      <inertia ixx="0.00007371" ixy="-0.00000113" ixz="0.00000021" iyy="0.00000781" iyz="-0.00001372" izz="0.0000747"/>
    </inertial>
    <visual>
      <geometry>
        <mesh filename="package://piper_description/meshes/link7.obj"/>
      </geometry>
    </visual>
    <collision>
      <geometry>
        <mesh filename="package://piper_description/meshes/link7.obj"/>
      </geometry>
    </collision>
  </link>
  <joint name="gripper_joint" type="prismatic">
    <origin xyz="0 0 0.1358"/>
    <parent link="link6"/>
    <child link="link7"/>
    <axis xyz="0 -1 0"/>
    <limit effort="10" lower="0" upper="0.035" velocity="1"/>
  </joint>
  <link name="link8">
    <inertial>
      <origin xyz="0.000651231850419722 -0.0491929869131991 0.00972258769184024"/>
      <mass value="0.025"/>
      <inertia ixx="0.00007371" ixy="-0.00000113" ixz="0.00000021" iyy="0.00000781" iyz="-0.00001372" izz="0.0000747"/>
    </inertial>
    <visual>
      <geometry>
        <mesh filename="package://piper_description/meshes/link8.obj"/>
      </geometry>
    </visual>
    <collision>
      <geometry>
        <mesh filename="package://piper_description/meshes/link8.obj"/>
      </geometry>
    </collision>
  </link>
  <joint name="joint8" type="prismatic">
    <origin xyz="0 0 0.1358"/>
    <parent link="link6"/>
    <child link="link8"/>
    <mimic joint="gripper_joint" multiplier="1" offset="0"/>
    <axis xyz="0 1 0"/>
    <limit effort="10" lower="0" upper="0.035" velocity="1"/>
  </joint>
  <link name="gripper_center"/>
  <joint name="gripper_center_fixed" type="fixed">
    <parent link="link6"/>
    <child link="gripper_center"/>
    <origin rpy="0 -1.57 0" xyz="0 0 0.1358"/>
  </joint>
  <link name="camera"/>
  <joint name="camera_fixed" type="fixed">
    <origin rpy="0 -1.22 0" xyz="-0.073 0 0.041"/>
    <parent link="link6"/>
    <child link="camera"/>
  </joint>
</robot>
