<?xml version="1.0" ?>
<!-- =================================================================================== -->
<!-- |    This document was autogenerated by xacro from robot.xacro                    | -->
<!-- |    EDITING THIS FILE BY HAND IS NOT RECOMMENDED                                 | -->
<!-- =================================================================================== -->
<robot name="arx_lift">
  <link name="left_base_link">
    <inertial>
      <origin xyz="-0.00013359 6.672E-05 0.031672"/>
      <mass value="0.42272"/>
      <inertia ixx="0.00019" ixy="0.00000" ixz="0.00000" iyy="0.00019" iyz="0.00000" izz="0.00020"/>
    </inertial>
    <visual>
      <geometry>
        <mesh filename="package://arx5_description/meshes/r5/base_link.obj"/>
      </geometry>
    </visual>
    <collision>
      <geometry>
        <mesh filename="package://arx5_description/meshes/r5/base_link.obj"/>
      </geometry>
    </collision>
  </link>
  <link name="left_link1">
    <inertial>
      <origin xyz="0.0050395 -0.0077407 0.020897"/>
      <mass value="0.096804"/>
      <inertia ixx="0.00011" ixy="-0.00001" ixz="0.00001" iyy="0.00005" iyz="-0.00001" izz="0.00010"/>
    </inertial>
    <visual>
      <geometry>
        <mesh filename="package://arx5_description/meshes/r5/link1.obj"/>
      </geometry>
    </visual>
    <collision>
      <geometry>
        <mesh filename="package://arx5_description/meshes/r5/link1.obj"/>
      </geometry>
    </collision>
  </link>
  <joint name="left_joint1" type="revolute">
    <origin xyz="0 0 0.0565"/>
    <parent link="left_base_link"/>
    <child link="left_link1"/>
    <axis xyz="0 0 1"/>
    <limit effort="100" lower="-2.618" upper="2.168" velocity="5"/>
  </joint>
  <link name="left_link2">
    <inertial>
      <origin xyz="-0.12992 -0.0011822 -2.6366E-05"/>
      <mass value="1.1988"/>
      <inertia ixx="0.00065" ixy="0.00008" ixz="0.00000" iyy="0.01647" iyz="0.00000" izz="0.01646"/>
    </inertial>
    <visual>
      <geometry>
        <mesh filename="package://arx5_description/meshes/r5/link2.obj"/>
      </geometry>
    </visual>
    <collision>
      <geometry>
        <mesh filename="package://arx5_description/meshes/r5/link2.obj"/>
      </geometry>
    </collision>
  </link>
  <joint name="left_joint2" type="revolute">
    <origin xyz="0.02 0 0.047"/>
    <parent link="left_link1"/>
    <child link="left_link2"/>
    <axis xyz="0 1 0"/>
    <limit effort="100" lower="0" upper="3.66" velocity="5"/>
  </joint>
  <link name="left_link3">
    <inertial>
      <origin xyz="0.16181 0.0011723 -0.05455"/>
      <mass value="0.84082"/>
      <inertia ixx="0.00082" ixy="0.00008" ixz="-0.00074" iyy="0.00849" iyz="0.00001" izz="0.00834"/>
    </inertial>
    <visual>
      <geometry>
        <mesh filename="package://arx5_description/meshes/r5/link3.obj"/>
      </geometry>
    </visual>
    <collision>
      <geometry>
        <mesh filename="package://arx5_description/meshes/r5/link3.obj"/>
      </geometry>
    </collision>
  </link>
  <joint name="left_joint3" type="revolute">
    <origin rpy="-3.1416 0 0" xyz="-0.264 0 0"/>
    <parent link="left_link2"/>
    <child link="left_link3"/>
    <axis xyz="0 1 0"/>
    <limit effort="100" lower="0" upper="3.14" velocity="5"/>
  </joint>
  <link name="left_link4">
    <inertial>
      <origin xyz="0.041751 0.0054236 -0.03337"/>
      <mass value="0.12432"/>
      <inertia ixx="0.00022" ixy="-0.00002" ixz="-0.00009" iyy="0.00025" iyz="0.00002" izz="0.00017"/>
    </inertial>
    <visual>
      <geometry>
        <mesh filename="package://arx5_description/meshes/r5/link4.obj"/>
      </geometry>
    </visual>
    <collision>
      <geometry>
        <mesh filename="package://arx5_description/meshes/r5/link4.obj"/>
      </geometry>
    </collision>
  </link>
  <joint name="left_joint4" type="revolute">
    <origin xyz="0.245 -5E-05 -0.06"/>
    <parent link="left_link3"/>
    <child link="left_link4"/>
    <axis xyz="0 1 0"/>
    <limit effort="100" lower="-1.57" upper="1.57" velocity="5"/>
  </joint>
  <link name="left_link5">
    <inertial>
      <origin xyz="-8.3435E-05 -1.5428E-05 0.052216"/>
      <mass value="0.63601"/>
      <inertia ixx="0.00084" ixy="0.00000" ixz="0.00007" iyy="0.00082" iyz="0.00000" izz="0.00026"/>
    </inertial>
    <visual>
      <geometry>
        <mesh filename="package://arx5_description/meshes/r5/link5.obj"/>
      </geometry>
    </visual>
    <collision>
      <geometry>
        <mesh filename="package://arx5_description/meshes/r5/link5.obj"/>
      </geometry>
    </collision>
  </link>
  <joint name="left_joint5" type="revolute">
    <origin xyz="0.0702 5E-05 -0.083391"/>
    <parent link="left_link4"/>
    <child link="left_link5"/>
    <axis xyz="0 0 1"/>
    <limit effort="100" lower="-1.57" upper="1.57" velocity="5"/>
  </joint>
  <link name="left_link6">
    <inertial>
      <origin xyz="0.041697 2.4368E-05 0.00014464"/>
      <mass value="0.44089"/>
      <inertia ixx="0.00038" ixy="0.00000" ixz="0.00000" iyy="0.00028" iyz="0.00000" izz="0.00050"/>
    </inertial>
    <visual>
      <geometry>
        <mesh filename="package://arx5_description/meshes/r5/link6.obj"/>
      </geometry>
    </visual>
    <collision>
      <geometry>
        <mesh filename="package://arx5_description/meshes/r5/link6.obj"/>
      </geometry>
    </collision>
  </link>
  <joint name="left_joint6" type="revolute">
    <origin rpy="3.1416 0 0" xyz="0.025286 0 0.083391"/>
    <parent link="left_link5"/>
    <child link="left_link6"/>
    <axis xyz="1 0 0"/>
    <limit effort="100" lower="-1.57" upper="1.57" velocity="5"/>
  </joint>
  <link name="left_link7">
    <inertial>
      <origin xyz="-0.00035522 -0.007827 -0.0029883"/>
      <mass value="0.064798"/>
      <inertia ixx="0.00002" ixy="0.00000" ixz="0.00000" iyy="0.00003" iyz="0.00000" izz="0.00003"/>
    </inertial>
    <visual>
      <geometry>
        <mesh filename="package://arx5_description/meshes/r5/link7.obj"/>
      </geometry>
    </visual>
    <collision>
      <geometry>
        <mesh filename="package://arx5_description/meshes/r5/link7.obj"/>
      </geometry>
    </collision>
  </link>
  <joint name="left_gripper_joint" type="prismatic">
    <origin xyz="0.08657 0.024896 -0.0002436"/>
    <parent link="left_link6"/>
    <child link="left_link7"/>
    <axis xyz="0 1 0"/>
    <limit effort="100" lower="0" upper="0.044" velocity="5"/>
  </joint>
  <link name="left_link8">
    <inertial>
      <origin xyz="-0.000355223470270755 0.00782768751820277 0.00242005642879778"/>
      <mass value="0.0647981725781684"/>
      <inertia ixx="0.00002" ixy="0.00000" ixz="0.00000" iyy="0.00003" iyz="0.00000" izz="0.00003"/>
    </inertial>
    <visual>
      <geometry>
        <mesh filename="package://arx5_description/meshes/r5/link8.obj"/>
      </geometry>
    </visual>
    <collision>
      <geometry>
        <mesh filename="package://arx5_description/meshes/r5/link8.obj"/>
      </geometry>
    </collision>
  </link>
  <joint name="left_joint8" type="prismatic">
    <origin xyz="0.08657 -0.0249 -0.00024366"/>
    <parent link="left_link6"/>
    <child link="left_link8"/>
    <axis xyz="0 -1 0"/>
    <limit effort="100" lower="0" upper="0.044" velocity="5"/>
    <mimic joint="left_gripper_joint" multiplier="1" offset="0"/>
  </joint>
  <link name="left_gripper_center"/>
  <joint name="left_gripper_center_fixed" type="fixed">
    <parent link="left_link6"/>
    <child link="left_gripper_center"/>
    <origin xyz="0.08657 0 0"/>
  </joint>
  <link name="left_left_pad"/>
  <joint name="left_left_pad_joint" type="fixed">
    <parent link="left_link7"/>
    <child link="left_left_pad"/>
    <origin xyz="0.05843 -0.0249 0"/>
  </joint>
  <link name="left_right_pad"/>
  <joint name="left_right_pad_joint" type="fixed">
    <parent link="left_link8"/>
    <child link="left_right_pad"/>
    <origin xyz="0.05843 0.0249 0"/>
  </joint>
  <link name="left_camera_support">
    <visual>
      <geometry>
        <mesh filename="package://arx5_description/meshes/camera_support.obj"/>
      </geometry>
    </visual>
  </link>
  <joint name="left_camera_support_fixed" type="fixed">
    <parent link="left_link6"/>
    <child link="left_camera_support"/>
    <origin xyz="0.045 0 0.021"/>
  </joint>
  <link name="left_camera">
    <visual>
      <geometry>
        <mesh filename="package://arx5_description/meshes/d405.obj"/>
      </geometry>
    </visual>
  </link>
  <joint name="left_camera_fixed" type="fixed">
    <origin rpy="0 0.523 0" xyz="0.0385 0 0.0475"/>
    <parent link="left_camera_support"/>
    <child link="left_camera"/>
  </joint>
  <link name="right_base_link">
    <inertial>
      <origin xyz="-0.00013359 6.672E-05 0.031672"/>
      <mass value="0.42272"/>
      <inertia ixx="0.00019" ixy="0.00000" ixz="0.00000" iyy="0.00019" iyz="0.00000" izz="0.00020"/>
    </inertial>
    <visual>
      <geometry>
        <mesh filename="package://arx5_description/meshes/r5/base_link.obj"/>
      </geometry>
    </visual>
    <collision>
      <geometry>
        <mesh filename="package://arx5_description/meshes/r5/base_link.obj"/>
      </geometry>
    </collision>
  </link>
  <link name="right_link1">
    <inertial>
      <origin xyz="0.0050395 -0.0077407 0.020897"/>
      <mass value="0.096804"/>
      <inertia ixx="0.00011" ixy="-0.00001" ixz="0.00001" iyy="0.00005" iyz="-0.00001" izz="0.00010"/>
    </inertial>
    <visual>
      <geometry>
        <mesh filename="package://arx5_description/meshes/r5/link1.obj"/>
      </geometry>
    </visual>
    <collision>
      <geometry>
        <mesh filename="package://arx5_description/meshes/r5/link1.obj"/>
      </geometry>
    </collision>
  </link>
  <joint name="right_joint1" type="revolute">
    <origin xyz="0 0 0.0565"/>
    <parent link="right_base_link"/>
    <child link="right_link1"/>
    <axis xyz="0 0 1"/>
    <limit effort="100" lower="-2.618" upper="2.168" velocity="5"/>
  </joint>
  <link name="right_link2">
    <inertial>
      <origin xyz="-0.12992 -0.0011822 -2.6366E-05"/>
      <mass value="1.1988"/>
      <inertia ixx="0.00065" ixy="0.00008" ixz="0.00000" iyy="0.01647" iyz="0.00000" izz="0.01646"/>
    </inertial>
    <visual>
      <geometry>
        <mesh filename="package://arx5_description/meshes/r5/link2.obj"/>
      </geometry>
    </visual>
    <collision>
      <geometry>
        <mesh filename="package://arx5_description/meshes/r5/link2.obj"/>
      </geometry>
    </collision>
  </link>
  <joint name="right_joint2" type="revolute">
    <origin xyz="0.02 0 0.047"/>
    <parent link="right_link1"/>
    <child link="right_link2"/>
    <axis xyz="0 1 0"/>
    <limit effort="100" lower="0" upper="3.66" velocity="5"/>
  </joint>
  <link name="right_link3">
    <inertial>
      <origin xyz="0.16181 0.0011723 -0.05455"/>
      <mass value="0.84082"/>
      <inertia ixx="0.00082" ixy="0.00008" ixz="-0.00074" iyy="0.00849" iyz="0.00001" izz="0.00834"/>
    </inertial>
    <visual>
      <geometry>
        <mesh filename="package://arx5_description/meshes/r5/link3.obj"/>
      </geometry>
    </visual>
    <collision>
      <geometry>
        <mesh filename="package://arx5_description/meshes/r5/link3.obj"/>
      </geometry>
    </collision>
  </link>
  <joint name="right_joint3" type="revolute">
    <origin rpy="-3.1416 0 0" xyz="-0.264 0 0"/>
    <parent link="right_link2"/>
    <child link="right_link3"/>
    <axis xyz="0 1 0"/>
    <limit effort="100" lower="0" upper="3.14" velocity="5"/>
  </joint>
  <link name="right_link4">
    <inertial>
      <origin xyz="0.041751 0.0054236 -0.03337"/>
      <mass value="0.12432"/>
      <inertia ixx="0.00022" ixy="-0.00002" ixz="-0.00009" iyy="0.00025" iyz="0.00002" izz="0.00017"/>
    </inertial>
    <visual>
      <geometry>
        <mesh filename="package://arx5_description/meshes/r5/link4.obj"/>
      </geometry>
    </visual>
    <collision>
      <geometry>
        <mesh filename="package://arx5_description/meshes/r5/link4.obj"/>
      </geometry>
    </collision>
  </link>
  <joint name="right_joint4" type="revolute">
    <origin xyz="0.245 -5E-05 -0.06"/>
    <parent link="right_link3"/>
    <child link="right_link4"/>
    <axis xyz="0 1 0"/>
    <limit effort="100" lower="-1.57" upper="1.57" velocity="5"/>
  </joint>
  <link name="right_link5">
    <inertial>
      <origin xyz="-8.3435E-05 -1.5428E-05 0.052216"/>
      <mass value="0.63601"/>
      <inertia ixx="0.00084" ixy="0.00000" ixz="0.00007" iyy="0.00082" iyz="0.00000" izz="0.00026"/>
    </inertial>
    <visual>
      <geometry>
        <mesh filename="package://arx5_description/meshes/r5/link5.obj"/>
      </geometry>
    </visual>
    <collision>
      <geometry>
        <mesh filename="package://arx5_description/meshes/r5/link5.obj"/>
      </geometry>
    </collision>
  </link>
  <joint name="right_joint5" type="revolute">
    <origin xyz="0.0702 5E-05 -0.083391"/>
    <parent link="right_link4"/>
    <child link="right_link5"/>
    <axis xyz="0 0 1"/>
    <limit effort="100" lower="-1.57" upper="1.57" velocity="5"/>
  </joint>
  <link name="right_link6">
    <inertial>
      <origin xyz="0.041697 2.4368E-05 0.00014464"/>
      <mass value="0.44089"/>
      <inertia ixx="0.00038" ixy="0.00000" ixz="0.00000" iyy="0.00028" iyz="0.00000" izz="0.00050"/>
    </inertial>
    <visual>
      <geometry>
        <mesh filename="package://arx5_description/meshes/r5/link6.obj"/>
      </geometry>
    </visual>
    <collision>
      <geometry>
        <mesh filename="package://arx5_description/meshes/r5/link6.obj"/>
      </geometry>
    </collision>
  </link>
  <joint name="right_joint6" type="revolute">
    <origin rpy="3.1416 0 0" xyz="0.025286 0 0.083391"/>
    <parent link="right_link5"/>
    <child link="right_link6"/>
    <axis xyz="1 0 0"/>
    <limit effort="100" lower="-1.57" upper="1.57" velocity="5"/>
  </joint>
  <link name="right_link7">
    <inertial>
      <origin xyz="-0.00035522 -0.007827 -0.0029883"/>
      <mass value="0.064798"/>
      <inertia ixx="0.00002" ixy="0.00000" ixz="0.00000" iyy="0.00003" iyz="0.00000" izz="0.00003"/>
    </inertial>
    <visual>
      <geometry>
        <mesh filename="package://arx5_description/meshes/r5/link7.obj"/>
      </geometry>
    </visual>
    <collision>
      <geometry>
        <mesh filename="package://arx5_description/meshes/r5/link7.obj"/>
      </geometry>
    </collision>
  </link>
  <joint name="right_gripper_joint" type="prismatic">
    <origin xyz="0.08657 0.024896 -0.0002436"/>
    <parent link="right_link6"/>
    <child link="right_link7"/>
    <axis xyz="0 1 0"/>
    <limit effort="100" lower="0" upper="0.044" velocity="5"/>
  </joint>
  <link name="right_link8">
    <inertial>
      <origin xyz="-0.000355223470270755 0.00782768751820277 0.00242005642879778"/>
      <mass value="0.0647981725781684"/>
      <inertia ixx="0.00002" ixy="0.00000" ixz="0.00000" iyy="0.00003" iyz="0.00000" izz="0.00003"/>
    </inertial>
    <visual>
      <geometry>
        <mesh filename="package://arx5_description/meshes/r5/link8.obj"/>
      </geometry>
    </visual>
    <collision>
      <geometry>
        <mesh filename="package://arx5_description/meshes/r5/link8.obj"/>
      </geometry>
    </collision>
  </link>
  <joint name="right_joint8" type="prismatic">
    <origin xyz="0.08657 -0.0249 -0.00024366"/>
    <parent link="right_link6"/>
    <child link="right_link8"/>
    <axis xyz="0 -1 0"/>
    <limit effort="100" lower="0" upper="0.044" velocity="5"/>
    <mimic joint="right_gripper_joint" multiplier="1" offset="0"/>
  </joint>
  <link name="right_gripper_center"/>
  <joint name="right_gripper_center_fixed" type="fixed">
    <parent link="right_link6"/>
    <child link="right_gripper_center"/>
    <origin xyz="0.08657 0 0"/>
  </joint>
  <link name="right_left_pad"/>
  <joint name="right_left_pad_joint" type="fixed">
    <parent link="right_link7"/>
    <child link="right_left_pad"/>
    <origin xyz="0.05843 -0.0249 0"/>
  </joint>
  <link name="right_right_pad"/>
  <joint name="right_right_pad_joint" type="fixed">
    <parent link="right_link8"/>
    <child link="right_right_pad"/>
    <origin xyz="0.05843 0.0249 0"/>
  </joint>
  <link name="right_camera_support">
    <visual>
      <geometry>
        <mesh filename="package://arx5_description/meshes/camera_support.obj"/>
      </geometry>
    </visual>
  </link>
  <joint name="right_camera_support_fixed" type="fixed">
    <parent link="right_link6"/>
    <child link="right_camera_support"/>
    <origin xyz="0.045 0 0.021"/>
  </joint>
  <link name="right_camera">
    <visual>
      <geometry>
        <mesh filename="package://arx5_description/meshes/d405.obj"/>
      </geometry>
    </visual>
  </link>
  <joint name="right_camera_fixed" type="fixed">
    <origin rpy="0 0.523 0" xyz="0.0385 0 0.0475"/>
    <parent link="right_camera_support"/>
    <child link="right_camera"/>
  </joint>
  <link name="base_link"/>
  <joint name="base_joint" type="fixed">
    <origin rpy="0 0 3.14159"/>
    <parent link="base_link"/>
    <child link="base"/>
  </joint>
  <link name="base">
    <inertial>
      <origin xyz="0.015300075250394498 -0.0039712791148939055 0.21685783167580347"/>
      <mass value="67.7696558151508"/>
      <inertia ixx="7.900786" ixy="-0.021075" ixz="0.25289" iyy="8.068966" iyz="0.12408" izz="2.254894"/>
    </inertial>
    <visual>
      <geometry>
        <mesh filename="package://arx_lift_description/meshes/base_link.obj"/>
      </geometry>
    </visual>
    <collision>
      <geometry>
        <mesh filename="package://arx_lift_description/meshes/base_link.obj"/>
      </geometry>
    </collision>
  </link>
  <link name="wheel_1">
    <inertial>
      <origin xyz="-0.0013052205916280202 0.0022598671755268973 1.318970376112949e-07"/>
      <mass value="4.24803000494366"/>
      <inertia ixx="0.008031" ixy="-0.002428" ixz="0.0" iyy="0.010834" iyz="0.0" izz="0.006629"/>
    </inertial>
  </link>
  <link name="wheel_2">
    <inertial>
      <origin xyz="-0.0013052205916208315 -0.0022598671755325594 -1.318970357273852e-07"/>
      <mass value="4.24803000494366"/>
      <inertia ixx="0.008031" ixy="0.002428" ixz="-0.0" iyy="0.010834" iyz="0.0" izz="0.006629"/>
    </inertial>
  </link>
  <link name="wheel_3">
    <inertial>
      <origin xyz="0.0026089441594678298 -1.3189703553351252e-07 2.8695680726054107e-07"/>
      <mass value="4.24803000494366"/>
      <inertia ixx="0.012235" ixy="-0.0" ixz="0.0" iyy="0.006629" iyz="0.0" izz="0.006629"/>
    </inertial>
  </link>
  <joint name="joint_wheel1" type="fixed">
    <origin xyz="-0.182349 0.315838 0.03"/>
    <parent link="base"/>
    <child link="wheel_1"/>
  </joint>
  <joint name="joint_wheel2" type="fixed">
    <origin xyz="-0.182349 -0.315838 0.03"/>
    <parent link="base"/>
    <child link="wheel_2"/>
    <axis xyz="-0.5 -0.866025 0.0"/>
  </joint>
  <joint name="joint_wheel3" type="fixed">
    <origin xyz="0.364699 0.0 0.03"/>
    <parent link="base"/>
    <child link="wheel_3"/>
    <axis xyz="1.0 0.0 -0.0"/>
  </joint>
  <link name="lift_link">
    <inertial>
      <origin xyz="-0.13956899916103924 0 0.07323798891482189"/>
      <mass value="17.38744536890084"/>
      <inertia ixx="0.187458" ixy="-0.000206" ixz="0.023942" iyy="0.178157" iyz="-0.000153" izz="0.29708"/>
    </inertial>
    <visual>
      <geometry>
        <mesh filename="package://arx_lift_description/meshes/lift.obj"/>
      </geometry>
    </visual>
    <collision>
      <geometry>
        <mesh filename="package://arx_lift_description/meshes/lift.obj"/>
      </geometry>
    </collision>
  </link>
  <joint name="joint_lift" type="prismatic">
    <origin xyz="0.022199 0 0.233"/>
    <parent link="base"/>
    <child link="lift_link"/>
    <axis xyz="0.0 0.0 1.0"/>
    <limit effort="100" lower="0.0" upper="0.86" velocity="100"/>
  </joint>
  <link name="h_base_link">
    <inertial>
      <origin xyz="-0.0020743076738515215 -1.5307881645835308e-08 -0.024619861716967787"/>
      <mass value="0.9930933606993821"/>
      <inertia ixx="0.000391" ixy="-0.0" ixz="1.7e-05" iyy="0.000452" iyz="0.0" izz="0.000532"/>
    </inertial>
    <visual>
      <geometry>
        <mesh filename="package://arx_lift_description/meshes/h_base.obj"/>
      </geometry>
    </visual>
    <collision>
      <geometry>
        <mesh filename="package://arx_lift_description/meshes/h_base.obj"/>
      </geometry>
    </collision>
  </link>
  <link name="h_link1_1">
    <inertial>
      <origin xyz="-1.3121512495483172e-08 -0.0017956601536253606 -0.0404485568834118"/>
      <mass value="1.1585686692835446"/>
      <inertia ixx="0.000714" ixy="-0.0" ixz="0.0" iyy="0.000677" iyz="3.4e-05" izz="0.000524"/>
    </inertial>
    <visual>
      <geometry>
        <mesh filename="package://arx_lift_description/meshes/h_link1.obj"/>
      </geometry>
    </visual>
    <collision>
      <geometry>
        <mesh filename="package://arx_lift_description/meshes/h_link1.obj"/>
      </geometry>
    </collision>
  </link>
  <link name="h_link2_1">
    <inertial>
      <origin xyz="0.03081593597576142 -0.022504711493597663 -0.0659240377971316"/>
      <mass value="1.5752562353484625"/>
      <inertia ixx="0.004555" ixy="0.000214" ixz="0.000252" iyy="0.004541" iyz="-0.000299" izz="0.00636"/>
    </inertial>
    <visual>
      <geometry>
        <mesh filename="package://arx_lift_description/meshes/h_link2.obj"/>
      </geometry>
    </visual>
    <collision>
      <geometry>
        <mesh filename="package://arx_lift_description/meshes/h_link2.obj"/>
      </geometry>
    </collision>
  </link>
  <joint name="joint_h_1" type="continuous">
    <origin xyz="0.0 0.0 -0.046"/>
    <parent link="h_base_link"/>
    <child link="h_link1_1"/>
    <axis xyz="0.0 -0.0 1.0"/>
    <limit effort="100" lower="-1.570796" upper="1.570796" velocity="100"/>
  </joint>
  <joint name="joint_h_2" type="continuous">
    <origin xyz="0.0 0.025 -0.047"/>
    <parent link="h_link1_1"/>
    <child link="h_link2_1"/>
    <axis xyz="-0.0 -1.0 0.0"/>
    <limit effort="100" lower="-0.785398" upper="0.785398" velocity="100"/>
  </joint>
  <joint name="h_fixed" type="fixed">
    <parent link="lift_link"/>
    <child link="h_base_link"/>
    <origin rpy="0 3.1415926 0" xyz="-0.258786 0 0.220008"/>
  </joint>
  <joint name="arm_left_fixed" type="fixed">
    <parent link="lift_link"/>
    <child link="left_base_link"/>
    <origin rpy="0 0 3.1415926" xyz="-0.208 -0.25000 0.092"/>
  </joint>
  <joint name="arm_right_fixed" type="fixed">
    <parent link="lift_link"/>
    <child link="right_base_link"/>
    <origin rpy="0 0 3.1415926" xyz="-0.208 0.25000 0.092"/>
  </joint>
</robot>
