<?xml version="1.0" ?>
<!-- =================================================================================== -->
<!-- |    This document was autogenerated by xacro from robot.xacro                    | -->
<!-- |    EDITING THIS FILE BY HAND IS NOT RECOMMENDED                                 | -->
<!-- =================================================================================== -->
<robot name="mmk2">
  <link name="base_link">
    <inertial>
      <origin xyz="-0.0400313721989715 -0.0226608008968248 0.756257223317173"/>
      <mass value="33.0267456398628"/>
      <inertia ixx="3.44838378637062" ixy="-0.00207943141138886" ixz="-0.0103091786755565" iyy="3.49493780774117" iyz="-0.00146679448998739" izz="0.21980548376876"/>
    </inertial>
    <visual>
      <geometry>
        <mesh filename="package://airbot_mmk2_description/meshes/base_link.obj"/>
      </geometry>
    </visual>
    <collision>
      <geometry>
        <mesh filename="package://airbot_mmk2_description/meshes/base_link.obj"/>
      </geometry>
    </collision>
  </link>
  <link name="lft_wheel_link">
    <inertial>
      <origin xyz="2.9309E-07 5.2077E-06 -0.029871"/>
      <mass value="1.1566"/>
      <inertia ixx="0.0021045" ixy="6.963E-10" ixz="-1.9831E-08" iyy="0.0021045" iyz="-3.5159E-07" izz="0.0035528"/>
    </inertial>
    <visual>
      <geometry>
        <mesh filename="package://airbot_mmk2_description/meshes/drive_wheel.obj"/>
      </geometry>
    </visual>
    <collision>
      <geometry>
        <mesh filename="package://airbot_mmk2_description/meshes/drive_wheel.obj"/>
      </geometry>
    </collision>
  </link>
  <joint name="lft_wheel_joint" type="continuous">
    <origin rpy="1.5708 1.5708 0" xyz="0 0.16325 0.08401"/>
    <parent link="base_link"/>
    <child link="lft_wheel_link"/>
    <axis xyz="0 0 -1"/>
  </joint>
  <link name="rgt_wheel_link">
    <inertial>
      <origin xyz="2.9312E-07 5.2196E-06 0.029871"/>
      <mass value="1.1566"/>
      <inertia ixx="0.0021045" ixy="-8.6762E-11" ixz="1.9824E-08" iyy="0.0021045" iyz="3.5159E-07" izz="0.0035528"/>
    </inertial>
    <visual>
      <geometry>
        <mesh filename="package://airbot_mmk2_description/meshes/drive_wheel.obj" scale="1 1 -1"/>
      </geometry>
    </visual>
    <collision>
      <geometry>
        <mesh filename="package://airbot_mmk2_description/meshes/drive_wheel.obj" scale="1 1 -1"/>
      </geometry>
    </collision>
  </link>
  <joint name="rgt_wheel_joint" type="revolute">
    <origin rpy="1.5708 1.5708 0" xyz="0 -0.16325 0.08401"/>
    <parent link="base_link"/>
    <child link="rgt_wheel_link"/>
    <axis xyz="0 0 1"/>
    <limit effort="6.5" lower="-3.1416" upper="3.1416" velocity="0.7"/>
  </joint>
  <link name="rgt_behind_wheel_link">
    <inertial>
      <origin xyz="0.0098797 -0.26998 -0.044087"/>
      <mass value="0.15002"/>
      <inertia ixx="0.00016534" ixy="1.4827E-07" ixz="-2.9264E-07" iyy="0.00014609" iyz="4.0633E-05" izz="9.3638E-05"/>
    </inertial>
    <visual>
      <geometry>
        <mesh filename="package://airbot_mmk2_description/meshes/support_wheel.obj"/>
      </geometry>
    </visual>
    <collision>
      <geometry>
        <mesh filename="package://airbot_mmk2_description/meshes/support_wheel.obj"/>
      </geometry>
    </collision>
  </link>
  <joint name="rgt_behind_wheel_joint" type="fixed">
    <origin xyz="-0.1315 0.1 0.097"/>
    <parent link="base_link"/>
    <child link="rgt_behind_wheel_link"/>
  </joint>
  <link name="lft_behind_wheel_link">
    <inertial>
      <origin xyz="-0.01012 -0.26998 -0.044087"/>
      <mass value="0.15002"/>
      <inertia ixx="0.00016534" ixy="1.4827E-07" ixz="-2.9264E-07" iyy="0.00014609" iyz="4.0633E-05" izz="9.3638E-05"/>
    </inertial>
    <visual>
      <geometry>
        <mesh filename="package://airbot_mmk2_description/meshes/support_wheel.obj"/>
      </geometry>
    </visual>
    <collision>
      <geometry>
        <mesh filename="package://airbot_mmk2_description/meshes/support_wheel.obj"/>
      </geometry>
    </collision>
  </link>
  <joint name="lft_behind_wheel_joint" type="fixed">
    <origin xyz="-0.1315 -0.1 0.097"/>
    <parent link="base_link"/>
    <child link="lft_behind_wheel_link"/>
  </joint>
  <link name="rgt_front_wheel_link">
    <inertial>
      <origin xyz="-0.01012 0.30602 -0.044087"/>
      <mass value="0.15002"/>
      <inertia ixx="0.00016534" ixy="1.4827E-07" ixz="-2.9264E-07" iyy="0.00014609" iyz="4.0633E-05" izz="9.3637E-05"/>
    </inertial>
    <visual>
      <geometry>
        <mesh filename="package://airbot_mmk2_description/meshes/support_wheel.obj"/>
      </geometry>
    </visual>
    <collision>
      <geometry>
        <mesh filename="package://airbot_mmk2_description/meshes/support_wheel.obj"/>
      </geometry>
    </collision>
  </link>
  <joint name="rgt_front_wheel_joint" type="fixed">
    <origin xyz="0.15482 -0.0895 0.097"/>
    <parent link="base_link"/>
    <child link="rgt_front_wheel_link"/>
  </joint>
  <link name="lft_front_wheel_link">
    <inertial>
      <origin xyz="0.0098797 0.30602 -0.044087"/>
      <mass value="0.15002"/>
      <inertia ixx="0.00016534" ixy="1.4827E-07" ixz="-2.9264E-07" iyy="0.00014609" iyz="4.0633E-05" izz="9.3637E-05"/>
    </inertial>
    <visual>
      <geometry>
        <mesh filename="package://airbot_mmk2_description/meshes/support_wheel.obj"/>
      </geometry>
    </visual>
    <collision>
      <geometry>
        <mesh filename="package://airbot_mmk2_description/meshes/support_wheel.obj"/>
      </geometry>
    </collision>
  </link>
  <joint name="lft_front_wheel_joint" type="fixed">
    <origin xyz="0.15482 0.0895 0.097"/>
    <parent link="base_link"/>
    <child link="lft_front_wheel_link"/>
  </joint>
  <link name="slide_link">
    <inertial>
      <origin xyz="-7.90494393625066E-05 0.067355217450789 0.10519083626064"/>
      <mass value="2.87043102920673"/>
      <inertia ixx="0.00899755064402379" ixy="6.09937870252811E-07" ixz="2.90775161414524E-06" iyy="0.0119634133355932" iyz="-0.000250919444280722" izz="0.00864817587777869"/>
    </inertial>
    <visual>
      <geometry>
        <mesh filename="package://airbot_mmk2_description/meshes/slide.obj"/>
      </geometry>
      <material name="">
        <color rgba="0.752941176470588 0.752941176470588 0.752941176470588 1"/>
      </material>
    </visual>
    <collision>
      <geometry>
        <mesh filename="package://airbot_mmk2_description/meshes/slide.obj"/>
      </geometry>
    </collision>
  </link>
  <joint name="slide_joint" type="prismatic">
    <origin rpy="3.1416 0 1.5708" xyz="0.033942 -0.00025 1.406"/>
    <parent link="base_link"/>
    <child link="slide_link"/>
    <axis xyz="0 0 1"/>
    <limit effort="5" lower="-0.04" upper="0.87" velocity="0.3"/>
  </joint>
  <link name="head_yaw_link">
    <inertial>
      <origin xyz="0.0118490941462296 0.000491254783341499 0.0390231494943873"/>
      <mass value="0.263127360420809"/>
      <inertia ixx="0.000185798854547827" ixy="2.64309797822853E-07" ixz="-2.93582511724902E-05" iyy="0.000173833362201622" iyz="-2.8054841555532E-06" izz="9.38655776831082E-05"/>
    </inertial>
    <visual>
      <geometry>
        <mesh filename="package://airbot_mmk2_description/meshes/head_yaw.obj"/>
      </geometry>
      <material name="">
        <color rgba="0.752941176470588 0.752941176470588 0.752941176470588 1"/>
      </material>
    </visual>
    <collision>
      <geometry>
        <mesh filename="package://airbot_mmk2_description/meshes/head_yaw.obj"/>
      </geometry>
    </collision>
  </link>
  <joint name="head_yaw_joint" type="revolute">
    <origin rpy="3.1416 0 0" xyz="0 0.1735 0.07242"/>
    <parent link="slide_link"/>
    <child link="head_yaw_link"/>
    <axis xyz="0 0 1"/>
    <limit effort="2" lower="-0.5" upper="0.5" velocity="0.2"/>
  </joint>
  <link name="head_pitch_link">
    <inertial>
      <origin xyz="0.0244659096221799 -0.108421751901101 -0.00311687659834824"/>
      <mass value="0.500765947013434"/>
      <inertia ixx="0.00157924187002826" ixy="2.16781765858799E-05" ixz="-1.02638171835218E-06" iyy="0.000804096450222595" iyz="1.48815549401623E-05" izz="0.00113048749298996"/>
    </inertial>
    <visual>
      <geometry>
        <mesh filename="package://airbot_mmk2_description/meshes/head_pitch.obj"/>
      </geometry>
      <material name="">
        <color rgba="0.752941176470588 0.752941176470588 0.752941176470588 1"/>
      </material>
    </visual>
    <collision>
      <geometry>
        <mesh filename="package://airbot_mmk2_description/meshes/head_pitch.obj"/>
      </geometry>
    </collision>
  </link>
  <joint name="head_pitch_joint" type="revolute">
    <origin rpy="-1.5708 0 -1.5397" xyz="0.00099952 3.1059E-05 0.058"/>
    <parent link="head_yaw_link"/>
    <child link="head_pitch_link"/>
    <axis xyz="0 0 1"/>
    <limit effort="2" lower="-0.16" upper="1.18" velocity="0.2"/>
  </joint>
  <!-- left arm -->
  <joint name="left_arm_fixed_joint" type="fixed">
    <origin rpy="1.57079633 0 2.356194490192345" xyz="0.10174 0.02283 0.09475"/>
    <parent link="slide_link"/>
    <child link="left_base_link"/>
  </joint>
  <link name="left_base_link">
    <inertial>
      <origin xyz="-0.010729 -0.00017015 0.041712"/>
      <mass value="0.77705"/>
      <inertia ixx="0.0008454" ixy="-7.5E-06" ixz="2.06E-05" iyy="0.0011821" iyz="-6.4E-06" izz="0.0012443"/>
    </inertial>
    <visual>
      <geometry>
        <mesh filename="package://airbot_play_description/meshes/arm_base.obj"/>
      </geometry>
    </visual>
    <collision>
      <geometry>
        <mesh filename="package://airbot_play_description/meshes/arm_base.obj"/>
      </geometry>
    </collision>
  </link>
  <link name="left_link1">
    <inertial>
      <origin xyz="7.9126E-05 -0.002527 -0.0041359"/>
      <mass value="0.54639"/>
      <inertia ixx="0.0003462" ixy="0" ixz="-1.4E-06" iyy="0.0002863" iyz="-1.1E-06" izz="0.0003255"/>
    </inertial>
    <visual>
      <geometry>
        <mesh filename="package://airbot_play_description/meshes/link1.obj"/>
      </geometry>
    </visual>
    <collision>
      <geometry>
        <mesh filename="package://airbot_play_description/meshes/link1.obj"/>
      </geometry>
    </collision>
  </link>
  <joint name="left_joint1" type="revolute">
    <origin xyz="0 0 0.1172"/>
    <parent link="left_base_link"/>
    <child link="left_link1"/>
    <axis xyz="0 0 1"/>
    <limit effort="18" lower="-3.14" upper="2.09" velocity="3.14"/>
  </joint>
  <link name="left_link2">
    <inertial>
      <origin xyz="0.22493 0.0047721 0.008023"/>
      <mass value="0.64621"/>
      <inertia ixx="0.0004901" ixy="0.0005229" ixz="-0.0002434" iyy="0.0050391" iyz="-2.95E-05" izz="0.0051052"/>
    </inertial>
    <visual>
      <geometry>
        <mesh filename="package://airbot_play_description/meshes/link2.obj"/>
      </geometry>
    </visual>
    <collision>
      <geometry>
        <mesh filename="package://airbot_play_description/meshes/link2.obj"/>
      </geometry>
    </collision>
  </link>
  <joint name="left_joint2" type="revolute">
    <origin rpy="1.5708 -2.7549 0"/>
    <parent link="left_link1"/>
    <child link="left_link2"/>
    <axis xyz="0 0 1"/>
    <limit effort="18" lower="-2.96" upper="0.17" velocity="3.14"/>
  </joint>
  <link name="left_link3">
    <inertial>
      <origin xyz="0.16813 -5.5576E-05 0.0031184"/>
      <mass value="0.26829"/>
      <inertia ixx="0.000245" ixy="-4E-07" ixz="-0.0001263" iyy="0.0031527" iyz="-1E-07" izz="0.0030895"/>
    </inertial>
    <visual>
      <geometry>
        <mesh filename="package://airbot_play_description/meshes/link3.obj"/>
      </geometry>
    </visual>
    <collision>
      <geometry>
        <mesh filename="package://airbot_play_description/meshes/link3.obj"/>
      </geometry>
    </collision>
  </link>
  <joint name="left_joint3" type="revolute">
    <origin rpy="0 0 -2.7549" xyz="0.27009 0 0"/>
    <parent link="left_link2"/>
    <child link="left_link3"/>
    <axis xyz="0 0 1"/>
    <limit effort="18" lower="-0.087" upper="3.14" velocity="3.14"/>
  </joint>
  <link name="left_link4">
    <inertial>
      <origin xyz="5.2436E-06 0.00040412 -0.03228"/>
      <mass value="0.34876"/>
      <inertia ixx="0.0004235" ixy="0" ixz="4.7E-06" iyy="0.000412" iyz="-1E-07" izz="0.0001269"/>
    </inertial>
    <visual>
      <geometry>
        <mesh filename="package://airbot_play_description/meshes/link4.obj"/>
      </geometry>
    </visual>
    <collision>
      <geometry>
        <mesh filename="package://airbot_play_description/meshes/link4.obj"/>
      </geometry>
    </collision>
  </link>
  <joint name="left_joint4" type="revolute">
    <origin rpy="3.1416 -1.5708 0" xyz="0.29015 0 0"/>
    <parent link="left_link3"/>
    <child link="left_link4"/>
    <axis xyz="0 0 1"/>
    <limit effort="300" lower="-2.96" upper="2.96" velocity="6.28"/>
  </joint>
  <link name="left_link5">
    <inertial>
      <origin xyz="8.3328E-06 0.026148 0.002525"/>
      <mass value="0.36132"/>
      <inertia ixx="0.0001825" ixy="0" ixz="-3.29E-05" iyy="0.0004677" iyz="0" izz="0.0004286"/>
    </inertial>
    <visual>
      <geometry>
        <mesh filename="package://airbot_play_description/meshes/link5.obj"/>
      </geometry>
    </visual>
    <collision>
      <geometry>
        <mesh filename="package://airbot_play_description/meshes/link5.obj"/>
      </geometry>
    </collision>
  </link>
  <joint name="left_joint5" type="revolute">
    <origin rpy="1.5708 0 0"/>
    <parent link="left_link4"/>
    <child link="left_link5"/>
    <axis xyz="0 0 1"/>
    <limit effort="300" lower="-1.74" upper="1.74" velocity="6.28"/>
  </joint>
  <link name="left_link6">
    <inertial>
      <origin xyz="-0.0047053 7.3857E-05 -0.12293"/>
      <mass value="0.53855"/>
      <inertia ixx="5E-05" ixy="0" ixz="0" iyy="5E-05" iyz="0" izz="3.85E-05"/>
    </inertial>
    <visual>
      <geometry>
        <mesh filename="package://airbot_play_description/meshes/link6.obj"/>
      </geometry>
    </visual>
    <collision>
      <geometry>
        <mesh filename="package://airbot_play_description/meshes/link6.obj"/>
      </geometry>
    </collision>
  </link>
  <joint name="left_joint6" type="revolute">
    <origin rpy="-1.5708 1.5708 0" xyz="0 0.23645 0"/>
    <parent link="left_link5"/>
    <child link="left_link6"/>
    <axis xyz="0 0 1"/>
    <limit effort="300" lower="-3.14" upper="3.14" velocity="6.28"/>
  </joint>
  <link name="left_left">
    <inertial>
      <origin xyz="-0.049039 -0.0096764 0.00038868"/>
      <mass value="0.061803"/>
      <inertia ixx="1.8946E-05" ixy="-1.3168E-06" ixz="-6.5528E-07" iyy="2.7277E-05" iyz="-2.0801E-07" izz="1.1981E-05"/>
    </inertial>
    <visual>
      <geometry>
        <mesh filename="package://airbot_play_description/meshes/gripper.obj" scale="1 -1 1"/>
      </geometry>
    </visual>
    <collision>
      <geometry>
        <mesh filename="package://airbot_play_description/meshes/gripper.obj" scale="1 -1 1"/>
      </geometry>
    </collision>
  </link>
  <joint name="left_gripper_joint" type="prismatic">
    <origin rpy="0 -1.5708 0"/>
    <parent link="left_link6"/>
    <child link="left_left"/>
    <axis xyz="0 1 0"/>
    <limit effort="100" lower="0" upper="0.04" velocity="2"/>
  </joint>
  <link name="left_right">
    <inertial>
      <origin xyz="-0.048742 0.0096369 0.00044322"/>
      <mass value="0.0626"/>
      <inertia ixx="1.915E-05" ixy="1.343E-06" ixz="-6.8259E-07" iyy="2.7722E-05" iyz="2.0748E-07" izz="1.2248E-05"/>
    </inertial>
    <visual>
      <geometry>
        <mesh filename="package://airbot_play_description/meshes/gripper.obj"/>
      </geometry>
    </visual>
    <collision>
      <geometry>
        <mesh filename="package://airbot_play_description/meshes/gripper.obj"/>
      </geometry>
    </collision>
  </link>
  <joint name="left_endright" type="prismatic">
    <origin rpy="0 -1.5708 0"/>
    <parent link="left_link6"/>
    <child link="left_right"/>
    <axis xyz="0 -1 0"/>
    <limit effort="100" lower="0" upper="0.04" velocity="2"/>
    <mimic joint="left_gripper_joint" multiplier="1" offset="0"/>
  </joint>
  <link name="left_gripper_center"/>
  <joint name="left_joint_custom_end" type="fixed">
    <origin rpy="0 -1.5708 0" xyz="0 0 0.02"/>
    <parent link="left_link6"/>
    <child link="left_gripper_center"/>
  </joint>
  <link name="left_camera_link"/>
  <joint name="left_camera_joint" type="fixed">
    <origin rpy="0 -1.046 0" xyz="-0.105 0 -0.111"/>
    <parent link="left_link6"/>
    <child link="left_camera_link"/>
  </joint>
  <!-- right arm -->
  <joint name="right_arm_fixed_joint" type="fixed">
    <origin rpy="-1.57079633 0 0.7853981633974483" xyz="-0.10174 0.02283 0.09475"/>
    <parent link="slide_link"/>
    <child link="right_base_link"/>
  </joint>
  <link name="right_base_link">
    <inertial>
      <origin xyz="-0.010729 -0.00017015 0.041712"/>
      <mass value="0.77705"/>
      <inertia ixx="0.0008454" ixy="-7.5E-06" ixz="2.06E-05" iyy="0.0011821" iyz="-6.4E-06" izz="0.0012443"/>
    </inertial>
    <visual>
      <geometry>
        <mesh filename="package://airbot_play_description/meshes/arm_base.obj"/>
      </geometry>
    </visual>
    <collision>
      <geometry>
        <mesh filename="package://airbot_play_description/meshes/arm_base.obj"/>
      </geometry>
    </collision>
  </link>
  <link name="right_link1">
    <inertial>
      <origin xyz="7.9126E-05 -0.002527 -0.0041359"/>
      <mass value="0.54639"/>
      <inertia ixx="0.0003462" ixy="0" ixz="-1.4E-06" iyy="0.0002863" iyz="-1.1E-06" izz="0.0003255"/>
    </inertial>
    <visual>
      <geometry>
        <mesh filename="package://airbot_play_description/meshes/link1.obj"/>
      </geometry>
    </visual>
    <collision>
      <geometry>
        <mesh filename="package://airbot_play_description/meshes/link1.obj"/>
      </geometry>
    </collision>
  </link>
  <joint name="right_joint1" type="revolute">
    <origin xyz="0 0 0.1172"/>
    <parent link="right_base_link"/>
    <child link="right_link1"/>
    <axis xyz="0 0 1"/>
    <limit effort="18" lower="-3.14" upper="2.09" velocity="3.14"/>
  </joint>
  <link name="right_link2">
    <inertial>
      <origin xyz="0.22493 0.0047721 0.008023"/>
      <mass value="0.64621"/>
      <inertia ixx="0.0004901" ixy="0.0005229" ixz="-0.0002434" iyy="0.0050391" iyz="-2.95E-05" izz="0.0051052"/>
    </inertial>
    <visual>
      <geometry>
        <mesh filename="package://airbot_play_description/meshes/link2.obj"/>
      </geometry>
    </visual>
    <collision>
      <geometry>
        <mesh filename="package://airbot_play_description/meshes/link2.obj"/>
      </geometry>
    </collision>
  </link>
  <joint name="right_joint2" type="revolute">
    <origin rpy="1.5708 -2.7549 0"/>
    <parent link="right_link1"/>
    <child link="right_link2"/>
    <axis xyz="0 0 1"/>
    <limit effort="18" lower="-2.96" upper="0.17" velocity="3.14"/>
  </joint>
  <link name="right_link3">
    <inertial>
      <origin xyz="0.16813 -5.5576E-05 0.0031184"/>
      <mass value="0.26829"/>
      <inertia ixx="0.000245" ixy="-4E-07" ixz="-0.0001263" iyy="0.0031527" iyz="-1E-07" izz="0.0030895"/>
    </inertial>
    <visual>
      <geometry>
        <mesh filename="package://airbot_play_description/meshes/link3.obj"/>
      </geometry>
    </visual>
    <collision>
      <geometry>
        <mesh filename="package://airbot_play_description/meshes/link3.obj"/>
      </geometry>
    </collision>
  </link>
  <joint name="right_joint3" type="revolute">
    <origin rpy="0 0 -2.7549" xyz="0.27009 0 0"/>
    <parent link="right_link2"/>
    <child link="right_link3"/>
    <axis xyz="0 0 1"/>
    <limit effort="18" lower="-0.087" upper="3.14" velocity="3.14"/>
  </joint>
  <link name="right_link4">
    <inertial>
      <origin xyz="5.2436E-06 0.00040412 -0.03228"/>
      <mass value="0.34876"/>
      <inertia ixx="0.0004235" ixy="0" ixz="4.7E-06" iyy="0.000412" iyz="-1E-07" izz="0.0001269"/>
    </inertial>
    <visual>
      <geometry>
        <mesh filename="package://airbot_play_description/meshes/link4.obj"/>
      </geometry>
    </visual>
    <collision>
      <geometry>
        <mesh filename="package://airbot_play_description/meshes/link4.obj"/>
      </geometry>
    </collision>
  </link>
  <joint name="right_joint4" type="revolute">
    <origin rpy="3.1416 -1.5708 0" xyz="0.29015 0 0"/>
    <parent link="right_link3"/>
    <child link="right_link4"/>
    <axis xyz="0 0 1"/>
    <limit effort="300" lower="-2.96" upper="2.96" velocity="6.28"/>
  </joint>
  <link name="right_link5">
    <inertial>
      <origin xyz="8.3328E-06 0.026148 0.002525"/>
      <mass value="0.36132"/>
      <inertia ixx="0.0001825" ixy="0" ixz="-3.29E-05" iyy="0.0004677" iyz="0" izz="0.0004286"/>
    </inertial>
    <visual>
      <geometry>
        <mesh filename="package://airbot_play_description/meshes/link5.obj"/>
      </geometry>
    </visual>
    <collision>
      <geometry>
        <mesh filename="package://airbot_play_description/meshes/link5.obj"/>
      </geometry>
    </collision>
  </link>
  <joint name="right_joint5" type="revolute">
    <origin rpy="1.5708 0 0"/>
    <parent link="right_link4"/>
    <child link="right_link5"/>
    <axis xyz="0 0 1"/>
    <limit effort="300" lower="-1.74" upper="1.74" velocity="6.28"/>
  </joint>
  <link name="right_link6">
    <inertial>
      <origin xyz="-0.0047053 7.3857E-05 -0.12293"/>
      <mass value="0.53855"/>
      <inertia ixx="5E-05" ixy="0" ixz="0" iyy="5E-05" iyz="0" izz="3.85E-05"/>
    </inertial>
    <visual>
      <geometry>
        <mesh filename="package://airbot_play_description/meshes/link6.obj"/>
      </geometry>
    </visual>
    <collision>
      <geometry>
        <mesh filename="package://airbot_play_description/meshes/link6.obj"/>
      </geometry>
    </collision>
  </link>
  <joint name="right_joint6" type="revolute">
    <origin rpy="-1.5708 1.5708 0" xyz="0 0.23645 0"/>
    <parent link="right_link5"/>
    <child link="right_link6"/>
    <axis xyz="0 0 1"/>
    <limit effort="300" lower="-3.14" upper="3.14" velocity="6.28"/>
  </joint>
  <link name="right_left">
    <inertial>
      <origin xyz="-0.049039 -0.0096764 0.00038868"/>
      <mass value="0.061803"/>
      <inertia ixx="1.8946E-05" ixy="-1.3168E-06" ixz="-6.5528E-07" iyy="2.7277E-05" iyz="-2.0801E-07" izz="1.1981E-05"/>
    </inertial>
    <visual>
      <geometry>
        <mesh filename="package://airbot_play_description/meshes/gripper.obj" scale="1 -1 1"/>
      </geometry>
    </visual>
    <collision>
      <geometry>
        <mesh filename="package://airbot_play_description/meshes/gripper.obj" scale="1 -1 1"/>
      </geometry>
    </collision>
  </link>
  <joint name="right_gripper_joint" type="prismatic">
    <origin rpy="0 -1.5708 0"/>
    <parent link="right_link6"/>
    <child link="right_left"/>
    <axis xyz="0 1 0"/>
    <limit effort="100" lower="0" upper="0.04" velocity="2"/>
  </joint>
  <link name="right_right">
    <inertial>
      <origin xyz="-0.048742 0.0096369 0.00044322"/>
      <mass value="0.0626"/>
      <inertia ixx="1.915E-05" ixy="1.343E-06" ixz="-6.8259E-07" iyy="2.7722E-05" iyz="2.0748E-07" izz="1.2248E-05"/>
    </inertial>
    <visual>
      <geometry>
        <mesh filename="package://airbot_play_description/meshes/gripper.obj"/>
      </geometry>
    </visual>
    <collision>
      <geometry>
        <mesh filename="package://airbot_play_description/meshes/gripper.obj"/>
      </geometry>
    </collision>
  </link>
  <joint name="right_endright" type="prismatic">
    <origin rpy="0 -1.5708 0"/>
    <parent link="right_link6"/>
    <child link="right_right"/>
    <axis xyz="0 -1 0"/>
    <limit effort="100" lower="0" upper="0.04" velocity="2"/>
    <mimic joint="right_gripper_joint" multiplier="1" offset="0"/>
  </joint>
  <link name="right_gripper_center"/>
  <joint name="right_joint_custom_end" type="fixed">
    <origin rpy="0 -1.5708 0" xyz="0 0 0.02"/>
    <parent link="right_link6"/>
    <child link="right_gripper_center"/>
  </joint>
  <link name="right_camera_link"/>
  <joint name="right_camera_joint" type="fixed">
    <origin rpy="0 -1.046 0" xyz="-0.105 0 -0.111"/>
    <parent link="right_link6"/>
    <child link="right_camera_link"/>
  </joint>
</robot>
