<?xml version="1.0" ?>
<!-- =================================================================================== -->
<!-- |    This document was autogenerated by xacro from urdf/genie.robot.xacro         | -->
<!-- |    EDITING THIS FILE BY HAND IS NOT RECOMMENDED                                 | -->
<!-- =================================================================================== -->
<robot name="genie" xmlns:xacro="http://www.ros.org/wiki/xacro">
	<!-- Base links -->

	<link name="base_footprint"/>

	<joint name="base_footprint_joint" type="fixed">
		<origin xyz="0 0 0.211"/>
		<parent link="base_footprint"/>
		<child link="base_link"/>
	</joint>

	<link name="base_link">
		<inertial>
			<origin xyz="-0.00804486971267798 0 -0.120076754329413"/>
			<mass value="65.2085382238952"/>
			<inertia ixx="0.386955641760608" ixy="0.000135417314593726" ixz="0.00669301645720665" iyy="0.366800407621218"
							 iyz="0.000105713634260505" izz="0.546852919828475"/>
		</inertial>
		<visual>
			<geometry>
				<mesh filename="file://$(find agibot_g1_description)/meshes/base/base.obj"/>
			</geometry>
		</visual>
		<collision>
			<origin xyz="-0.10913086 0.0 0.5971875"/>
			<geometry>
				<box size="0.29833984 0.3376392 1.0"/>
			</geometry>
		</collision>
		<collision>
			<origin xyz="0.01 0.0 -0.045"/>
			<geometry>
				<box size="0.5796094 0.449 0.27073438"/>
			</geometry>
		</collision>

		<collision>
			<origin xyz="0.22 0.14 -0.175245"/>
			<geometry>
				<sphere radius="0.038"/>
			</geometry>
		</collision>
		<collision>
			<origin xyz="0.22 -0.14 -0.175245"/>
			<geometry>
				<sphere radius="0.038"/>
			</geometry>
		</collision>
		<collision>
			<origin xyz="-0.18 0.14 -0.175245"/>
			<geometry>
				<sphere radius="0.038"/>
			</geometry>
		</collision>
		<collision>
			<origin xyz="-0.18 -0.14 -0.175245"/>
			<geometry>
				<sphere radius="0.038"/>
			</geometry>
		</collision>
	</link>

	<link name="left_wheel">
		<inertial>
			<origin xyz="-5.2736E-16 -0.033322 1.1102E-16"/>
			<mass value="5.8637"/>
			<inertia
					ixx="0.0051541"
					ixy="-3.3734E-17"
					ixz="1.0772E-17"
					iyy="0.0090798"
					iyz="5.0454E-18"
					izz="0.0051541"/>
		</inertial>
		<collision>
			<origin rpy="1.5708 0 0"/>
			<geometry>
				<cylinder radius="0.07948" length="0.034"/>
			</geometry>
		</collision>
	</link>
	<joint name="left_wheel_joint" type="continuous">
		<parent link="base_link"/>
		<child link="left_wheel"/>
		<origin xyz="0.016 0.1865 -0.133845"/>
		<axis xyz="0 1 0"/>
	</joint>

	<link name="scan"/>
	<joint name="scan_joint" type="fixed">
		<parent link="base_link"/>
		<child link="scan"/>
		<origin xyz="0.24 0 0.0145"/>
	</joint>

	<link name="imu"/>
	<joint name="imu_joint" type="fixed">
		<parent link="base_link"/>
		<child link="imu"/>
		<origin xyz="0.016 0 0.0145"/>
	</joint>

	<link name="right_wheel">
		<inertial>
			<origin xyz="-5.2736E-16 -0.033322 1.1102E-16"/>
			<mass value="5.8637"/>
			<inertia
					ixx="0.0051541"
					ixy="-3.3734E-17"
					ixz="1.0772E-17"
					iyy="0.0090798"
					iyz="5.0454E-18"
					izz="0.0051541"/>
		</inertial>
		<collision>
			<origin rpy="1.5708 0 0"/>
			<geometry>
				<cylinder radius="0.07948" length="0.034"/>
			</geometry>
		</collision>
	</link>
	<joint name="right_wheel_joint" type="continuous">
		<parent link="base_link"/>
		<child link="right_wheel"/>
		<origin xyz="0.016 -0.1865 -0.133845"/>
		<axis xyz="0 1 0"/>
	</joint>

	<link name="body_link1">
		<inertial>
			<origin xyz="0.0338351537064605 -0.00248044044451858 0.000838431095422365"/>
			<mass value="3.26275452360108"/>
			<inertia ixx="0.0128301877197417" ixy="8.24967996575627e-06" ixz="1.38254543337324e-05" iyy="0.006104110250297"
							 iyz="-7.99392548994692e-06" izz="0.0111721084996867"/>
		</inertial>
		<visual>
			<geometry>
				<mesh filename="file://$(find agibot_g1_description)/meshes/base/body_link1.obj"/>
			</geometry>
		</visual>
		<collision>
			<origin xyz="0.10278320000000002 0.1 -0.013671875"/>
			<geometry>
				<box size="0.16064453 0.05555534399999999 0.1328125"/>
			</geometry>
		</collision>
		<collision>
			<origin xyz="0.10180664 -0.1 0.0"/>
			<geometry>
				<box size="0.16259765999999998 0.04375648500000001 0.16015625"/>
			</geometry>
		</collision>
	</link>

	<link name="body_link2">
		<inertial>
			<origin xyz="-0.000484180179482319 -0.193733558855111 -0.00124011422952511"/>
			<mass value="7.53199207979272"/>
			<inertia
					ixx="0.0788874639537613"
					ixy="5.46530938736686E-10"
					ixz="0.00286825206797472"
					iyy="0.0515041942141216"
					iyz="3.46275348004213E-07"
					izz="0.0448953474115628"/>
		</inertial>
		<visual>
			<geometry>
				<mesh filename="file://$(find agibot_g1_description)/meshes/base/body_link2.obj"/>
			</geometry>
			<origin rpy="0.0 0.0 -1.5707963267948966"/>
		</visual>
		<collision>
			<origin xyz="0.0068359375 -0.00034356117 0.0"/>
			<geometry>
				<cylinder radius="0.09662318" length="0.08697056999999997"/>
			</geometry>
		</collision>
		<collision>
			<origin xyz="0.0068359375 -0.00034356117 0.043485284999999985"/>
			<geometry>
				<sphere radius="0.09662318"/>
			</geometry>
		</collision>
		<collision>
			<origin
					xyz="0.0068359375 -0.00034356117 -0.043485284999999985"/>
			<geometry>
				<sphere radius="0.09662318"/>
			</geometry>
		</collision>
		<collision>
			<origin
					rpy="0.0 0.0 -1.5708"
					xyz="0.008 -0.248 0.0"/>
			<geometry>
				<box size="0.34570312 0.18107724 0.3125"/>
			</geometry>
		</collision>
	</link>

	<link name="head_link1">
		<inertial>
			<origin xyz="0.0446068140025754 0.00241753143645124 0.0528373754603559"/>
			<mass value="0.414342871921048"/>
			<inertia ixx="0.000158695728344024" ixy="-1.04590928109554e-06" ixz="-6.58530903139189e-06"
							 iyy="0.000117742864399469" iyz="-2.65011299996072e-06" izz="0.000170947040827065"/>
		</inertial>
		<visual>
			<geometry>
				<mesh filename="file://$(find agibot_g1_description)/meshes/base/head_link1.obj"/>
			</geometry>
		</visual>
	</link>

	<link name="head_link2">
		<inertial>
			<origin xyz="0.0257009265816389 0.0316254080188787 -3.77390122592164e-05"/>
			<mass value="0.707063977171202"/>
			<inertia ixx="0.00205409595373573" ixy="0.000347730118005016" ixz="-2.13857752451204e-06"
							 iyy="0.00200357281313449" iyz="5.16150600423908e-08" izz="0.00184999028444405"/>
		</inertial>
		<visual>
			<geometry>
				<mesh filename="file://$(find agibot_g1_description)/meshes/base/head_link2.obj"/>
			</geometry>
			<origin rpy="-3.141592653589793 0.0 0.0"/>
		</visual>
		<collision>
			<geometry>
				<sphere radius="0.11257068650657154"/>
			</geometry>
			<origin xyz="0.011500973396434619 -0.0252600143348118 0.0008537154007319386"/>
		</collision>
	</link>

	<!-- Base joints -->
	<joint name="body_joint1" type="prismatic">
		<parent link="base_link"/>
		<child link="body_link1"/>
		<origin xyz="0.0 0.0 0.4285"/>
		<axis xyz="0.0 0.0 1.0"/>
		<limit effort="1000" lower="0.0" upper="0.5" velocity="0.1"/>
	</joint>

	<joint name="body_joint2" type="revolute">
		<parent link="body_link1"/>
		<child link="body_link2"/>
		<origin rpy="-1.5707963267948966 0.0 0.0" xyz="0.131 0.0 0.0"/>
		<axis xyz="0.0 0.0 1.0"/>
		<limit effort="100.0" lower="0.0" upper="1.5707963267948966" velocity="0.5"/>
	</joint>

	<!-- Head joints -->
	<joint name="head_joint1" type="revolute">
		<parent link="body_link2"/>
		<child link="head_link1"/>
		<origin rpy="1.5707963267948966 0.0 0.0" xyz="0.0 -0.441 0.0"/>
		<axis xyz="0.0 0.0 1.0"/>
		<limit effort="50.0" lower="-1.5707963267948966" upper="1.5707963267948966" velocity="1.0"/>
	</joint>

	<joint name="head_joint2" type="revolute">
		<parent link="head_link1"/>
		<child link="head_link2"/>
		<origin rpy="-1.5707963267948966 0.0 0.0" xyz="0.050238 0.0 0.060065"/>
		<axis xyz="0.0 0.0 1.0"/>
		<limit effort="50.0" lower="-0.3490658503988659" upper="0.5235987755982988" velocity="1.0"/>
	</joint>

	<link name="head_camera"/>
	<joint name="head_camera_joint" type="fixed">
		<parent link="head_link2"/>
		<child link="head_camera"/>
		<origin xyz="0.103 -0.0421 0.0" rpy="1.5707963267948966 0 0"/>
	</joint>

</robot>

