<?xml version="1.0" ?>
<!-- =================================================================================== -->
<!-- |    This document was autogenerated by xacro from robot.xacro                    | -->
<!-- |    EDITING THIS FILE BY HAND IS NOT RECOMMENDED                                 | -->
<!-- =================================================================================== -->
<robot name="Panthera">
  <link name="base_link">
    <inertial>
      <origin xyz="-5.22421768267327E-17 -4.9646319201852E-06 0.00682594884114425"/>
      <mass value="1.00980967249859"/>
      <inertia ixx="0.00110668630953746" ixy="1.28862263174568E-19" ixz="-3.2127004428854E-21" iyy="0.0011065522944672" iyz="-8.45296879697751E-08" izz="0.00216887903845609"/>
    </inertial>
    <visual>
      <geometry>
        <mesh filename="package://panthera_description/meshes/visual/base_link.obj"/>
      </geometry>
    </visual>
    <collision>
      <geometry>
        <mesh filename="package://panthera_description/meshes/collision/base_link_0.obj"/>
      </geometry>
    </collision>
    <collision>
      <geometry>
        <mesh filename="package://panthera_description/meshes/collision/base_link_1.obj"/>
      </geometry>
    </collision>
  </link>
  <link name="link1">
    <inertial>
      <origin xyz="-0.000140138460727448 -0.0115178455380478 -0.0189175974816606"/>
      <mass value="0.433540348958132"/>
      <inertia ixx="0.000278935703826545" ixy="1.25625050632852E-06" ixz="6.95888805367088E-08" iyy="0.000266771663216221" iyz="6.1414956964764E-05" izz="0.000227700191108933"/>
    </inertial>
    <visual>
      <geometry>
        <mesh filename="package://panthera_description/meshes/visual/link1.obj"/>
      </geometry>
    </visual>
    <collision>
      <geometry>
        <mesh filename="package://panthera_description/meshes/collision/link1_0.obj"/>
      </geometry>
    </collision>
    <collision>
      <geometry>
        <mesh filename="package://panthera_description/meshes/collision/link1_1.obj"/>
      </geometry>
    </collision>
    <collision>
      <geometry>
        <mesh filename="package://panthera_description/meshes/collision/link1_2.obj"/>
      </geometry>
    </collision>
  </link>
  <joint name="joint1" type="revolute">
    <origin xyz="0 0 0.1005"/>
    <parent link="base_link"/>
    <child link="link1"/>
    <axis xyz="0 0 1"/>
    <limit effort="30" lower="-3.14" upper="3.14" velocity="1"/>
  </joint>
  <link name="link2">
    <inertial>
      <origin xyz="0.106425438295557 -3.80251385934116E-12 0.0236077558477278"/>
      <mass value="0.618785138060723"/>
      <inertia ixx="0.000203520214080601" ixy="2.79264055058398E-19" ixz="-1.05315902249166E-07" iyy="0.00224499671569178" iyz="1.32814298453241E-20" izz="0.00238696841123224"/>
    </inertial>
    <visual>
      <geometry>
        <mesh filename="package://panthera_description/meshes/visual/link2.obj"/>
      </geometry>
    </visual>
    <collision>
      <geometry>
        <mesh filename="package://panthera_description/meshes/collision/link2_0.obj"/>
      </geometry>
    </collision>
    <collision>
      <geometry>
        <mesh filename="package://panthera_description/meshes/collision/link2_1.obj"/>
      </geometry>
    </collision>
  </link>
  <joint name="joint2" type="revolute">
    <origin rpy="1.5707963267949 0 3.14159265358979" xyz="0 0 0"/>
    <parent link="link1"/>
    <child link="link2"/>
    <axis xyz="0 0 1"/>
    <limit effort="30" lower="-3.14" upper="3.14" velocity="1"/>
  </joint>
  <link name="link3">
    <inertial>
      <origin xyz="0.112947841031452 0.0109257169593898 0.0234930652223882"/>
      <mass value="0.578438290721478"/>
      <inertia ixx="0.000268057561475191" ixy="2.74601930728987E-05" ixz="3.17939972597626E-08" iyy="0.00216726923713696" iyz="1.00402096614883E-07" izz="0.0023748322005515"/>
    </inertial>
    <visual>
      <geometry>
        <mesh filename="package://panthera_description/meshes/visual/link3.obj"/>
      </geometry>
    </visual>
    <collision>
      <geometry>
        <mesh filename="package://panthera_description/meshes/collision/link3_0.obj"/>
      </geometry>
    </collision>
    <collision>
      <geometry>
        <mesh filename="package://panthera_description/meshes/collision/link3_1.obj"/>
      </geometry>
    </collision>
    <collision>
      <geometry>
        <mesh filename="package://panthera_description/meshes/collision/link3_2.obj"/>
      </geometry>
    </collision>
  </link>
  <joint name="joint3" type="revolute">
    <origin rpy="3.14159265358979 0 2.83491633418811" xyz="0.179999999999998 0 0"/>
    <parent link="link2"/>
    <child link="link3"/>
    <axis xyz="0 0 1"/>
    <limit effort="30" lower="-3.14" upper="3.14" velocity="1"/>
  </joint>
  <link name="link4">
    <inertial>
      <origin xyz="0.0513406245602283 -0.0329058384127011 0.00868209734629183"/>
      <mass value="0.399529174718196"/>
      <inertia ixx="0.000329818055330246" ixy="0.000104110882896881" ixz="8.09376058698959E-05" iyy="0.0003603735383472" iyz="-6.00949681992951E-05" izz="0.000376825850928194"/>
    </inertial>
    <visual>
      <geometry>
        <mesh filename="package://panthera_description/meshes/visual/link4.obj"/>
      </geometry>
    </visual>
    <collision>
      <geometry>
        <mesh filename="package://panthera_description/meshes/collision/link4_0.obj"/>
      </geometry>
    </collision>
    <collision>
      <geometry>
        <mesh filename="package://panthera_description/meshes/collision/link4_1.obj"/>
      </geometry>
    </collision>
    <collision>
      <geometry>
        <mesh filename="package://panthera_description/meshes/collision/link4_2.obj"/>
      </geometry>
    </collision>
    <collision>
      <geometry>
        <mesh filename="package://panthera_description/meshes/collision/link4_3.obj"/>
      </geometry>
    </collision>
  </link>
  <joint name="joint4" type="revolute">
    <origin rpy="3.14159265358979 0 -0.306676319401685" xyz="0.188809427730714 0 0"/>
    <parent link="link3"/>
    <child link="link4"/>
    <axis xyz="0 0 1"/>
    <limit effort="30" lower="-3.14" upper="3.14" velocity="1"/>
  </joint>
  <link name="link5">
    <inertial>
      <origin xyz="2.62314297356869E-16 -0.0160776069634142 -0.0180581657290753"/>
      <mass value="0.321861622200536"/>
      <inertia ixx="0.000192352594219116" ixy="-9.24994896376521E-20" ixz="2.36149112675264E-21" iyy="0.000171651346378433" iyz="4.05707603604006E-05" izz="0.000185377128431133"/>
    </inertial>
    <visual>
      <geometry>
        <mesh filename="package://panthera_description/meshes/visual/link5.obj"/>
      </geometry>
    </visual>
    <collision>
      <geometry>
        <mesh filename="package://panthera_description/meshes/collision/link5_0.obj"/>
      </geometry>
    </collision>
    <collision>
      <geometry>
        <mesh filename="package://panthera_description/meshes/collision/link5_1.obj"/>
      </geometry>
    </collision>
    <collision>
      <geometry>
        <mesh filename="package://panthera_description/meshes/collision/link5_2.obj"/>
      </geometry>
    </collision>
  </link>
  <joint name="joint5" type="revolute">
    <origin rpy="-1.5708 1.5708 0" xyz="0.08 0 0"/>
    <parent link="link4"/>
    <child link="link5"/>
    <axis xyz="0 0 1"/>
    <limit effort="30" lower="-3.14" upper="3.14" velocity="1"/>
  </joint>
  <link name="link6">
    <inertial>
      <origin xyz="-4.35824622879912E-15 -2.3037127760972E-15 -0.0025000000000041"/>
      <mass value="0.00434717883440458"/>
      <inertia ixx="3.56917077685088E-07" ixy="1.21411373112006E-21" ixz="-8.99654936865443E-22" iyy="3.56917077685087E-07" iyz="2.51615306815575E-22" izz="6.95720910226822E-07"/>
    </inertial>
    <visual>
      <geometry>
        <mesh filename="package://panthera_description/meshes/visual/link6.obj"/>
      </geometry>
    </visual>
  </link>
  <joint name="joint6" type="revolute">
    <origin rpy="1.5708 0 0" xyz="0 -0.036 0"/>
    <parent link="link5"/>
    <child link="link6"/>
    <axis xyz="0 0 1"/>
    <limit effort="30" lower="-3.14" upper="3.14" velocity="1"/>
  </joint>
  <link name="gripper_center">
    <inertial>
      <origin xyz="-0.107107907434468 -0.000284330630565321 -3.59780083918573E-09"/>
      <mass value="0.105344961426715"/>
      <inertia ixx="0.000121501833753841" ixy="-5.32591777920033E-07" ixz="-1.30991455486E-12" iyy="0.000131132833025858" iyz="-1.22715670298721E-16" izz="3.14014892995729E-05"/>
    </inertial>
    <visual>
      <geometry>
        <mesh filename="package://panthera_description/meshes/visual/gripper_center_link.obj"/>
      </geometry>
    </visual>
    <collision>
      <geometry>
        <mesh filename="package://panthera_description/meshes/collision/gripper_center_0.obj"/>
      </geometry>
    </collision>
    <collision>
      <geometry>
        <mesh filename="package://panthera_description/meshes/collision/gripper_center_1.obj"/>
      </geometry>
    </collision>
    <collision>
      <geometry>
        <mesh filename="package://panthera_description/meshes/collision/gripper_center_2.obj"/>
      </geometry>
    </collision>
  </link>
  <joint name="gripper_center_joint" type="fixed">
    <origin rpy="0 -1.5708 1.5708" xyz="0 0 0.148"/>
    <parent link="link6"/>
    <child link="gripper_center"/>
    <limit effort="30" lower="-3.14" upper="3.14" velocity="1"/>
  </joint>
  <link name="gripper_1_link">
    <inertial>
      <origin xyz="-0.0574118738630709 0.00266477929541095 0.00735600840817693"/>
      <mass value="0.0426889603072748"/>
      <inertia ixx="1.52455723699562E-05" ixy="6.72945744056607E-07" ixz="6.51636208168844E-07" iyy="1.58145426336727E-05" iyz="8.66924269315344E-07" izz="1.07532838710952E-05"/>
    </inertial>
    <visual>
      <geometry>
        <mesh filename="package://panthera_description/meshes/visual/gripper_pad.obj"/>
      </geometry>
    </visual>
    <collision>
      <geometry>
        <mesh filename="package://panthera_description/meshes/collision/gripper_pad.obj"/>
      </geometry>
    </collision>
  </link>
  <joint name="gripper_joint" type="prismatic">
    <parent link="gripper_center"/>
    <child link="gripper_1_link"/>
    <axis xyz="0 1 0"/>
    <limit effort="0.18" lower="0" upper="0.06" velocity="1"/>
  </joint>
  <link name="gripper_2_link">
    <inertial>
      <origin xyz="-0.0573873207529981 -0.00294326456557495 -0.00756965143896882"/>
      <mass value="0.0427537416759649"/>
      <inertia ixx="1.51969338433752E-05" ixy="-6.97375756939916E-07" ixz="-6.45626526757555E-07" iyy="1.56092033290293E-05" iyz="8.99148024231464E-07" izz="1.09238615980533E-05"/>
    </inertial>
    <visual>
      <geometry>
        <mesh filename="package://panthera_description/meshes/visual/gripper_pad.obj" scale="1 -1 1"/>
      </geometry>
    </visual>
    <collision>
      <geometry>
        <mesh filename="package://panthera_description/meshes/collision/gripper_pad.obj" scale="1 -1 1"/>
      </geometry>
    </collision>
  </link>
  <joint name="gripper_2_joint" type="prismatic">
    <parent link="gripper_center"/>
    <child link="gripper_2_link"/>
    <axis xyz="0 -1 0"/>
    <limit effort="0.18" lower="0" upper="0.06" velocity="1"/>
    <mimic joint="gripper_joint" multiplier="1" offset="0"/>
  </joint>
</robot>
