<?xml version="1.0" encoding="utf-8"?>
<robot xmlns:xacro="http://www.ros.org/wiki/xacro">
	<link name="base_link">
		<inertial>
			<origin xyz="0.0718033657159837 -0.0016279349766449 0.128750850965126"/>
			<mass value="25.114"/>
			<inertia
					ixx="0.190993086908409"
					ixy="7.01153963312701E-05"
					ixz="-0.00785937977791519"
					iyy="0.152035922355254"
					iyz="-0.000494758898409346"
					izz="0.29121889848538"/>
		</inertial>
		<visual>
			<geometry>
				<mesh filename="file://$(find galaxea_r1lite_description)/meshes/visual/base.obj"/>
			</geometry>
		</visual>
		<collision>
			<geometry>
				<mesh filename="file://$(find galaxea_r1lite_description)/meshes/collision/base.stl"/>
			</geometry>
		</collision>
	</link>

	<link name="steer_motor_link1">
		<inertial>
			<origin xyz="-1.76196610579549E-07 -7.75116053202478E-05 -0.0852489956386505"/>
			<mass value="1.5"/>
			<inertia
					ixx="0.000338657650556839"
					ixy="6.14197589167664E-09"
					ixz="6.6056392682533E-09"
					iyy="0.000503900951850049"
					iyz="3.6051622873431E-08"
					izz="0.000211486748436409"/>
		</inertial>
		<visual>
			<geometry>
				<mesh filename="file://$(find galaxea_r1lite_description)/meshes/visual/steer_motor.obj"/>
			</geometry>
		</visual>
	</link>

	<joint name="steer_motor_joint1" type="fixed">
		<origin xyz="0.29183 -0.0014897 0.18165"/>
		<parent link="base_link"/>
		<child link="steer_motor_link1"/>
		<axis xyz="0 0 1"/>
		<limit lower="${-PI}" upper="${PI}" effort="20" velocity="20"/>
	</joint>

	<link name="wheel_motor_link1">
		<inertial>
			<origin xyz="0 -9.99250577455509E-13 -2.34534613952064E-15"/>
			<mass value="1.5"/>
			<inertia ixx="0.00104702497304016" ixy="2.02186210571336E-18" ixz="-8.67361737988254E-20" iyy="0.00181031135070458" iyz="3.54126040189266E-17" izz="0.00104702497304016"/>
		</inertial>
		<visual>
			<geometry>
				<mesh filename="file://$(find galaxea_r1lite_description)/meshes/visual/wheel.obj"/>
			</geometry>
		</visual>
		<collision>
			<geometry>
				<mesh filename="file://$(find galaxea_r1lite_description)/meshes/visual/wheel.obj"/>
			</geometry>
		</collision>
	</link>

	<joint name="wheel_motor_joint1" type="fixed">
		<origin xyz="0 0 -0.11165"/>
		<parent link="steer_motor_link1"/>
		<child link="wheel_motor_link1"/>
		<axis xyz="0 1 0"/>
	</joint>
	<link name="steer_motor_link2">
		<inertial>
			<origin xyz="1.76196610607304E-07 7.75116053202962E-05 -0.0852489956386505"/>
			<mass value="1.5"/>
			<inertia ixx="0.000338657650556839" ixy="6.1419758916829E-09" ixz="-6.6056392682485E-09" iyy="0.000503900951850049" iyz="-3.60516228734399E-08" izz="0.000211486748436408"/>
		</inertial>
		<visual>
			<geometry>
				<mesh filename="file://$(find galaxea_r1lite_description)/meshes/visual/steer_motor.obj"/>
			</geometry>
		</visual>
	</link>
	<joint name="steer_motor_joint2" type="fixed">
		<origin xyz="-0.16817 0.23851 0.18165"/>
		<parent link="base_link"/>
		<child link="steer_motor_link2"/>
		<axis xyz="0 0 1"/>
		<limit lower="${-PI}" upper="${PI}" effort="20" velocity="20"/>
	</joint>
	<link name="wheel_motor_link2">
		<inertial>
			<origin xyz="2.77555756156289E-17 -1.94289029309402E-16 -2.34621350125863E-15"/>
			<mass value="1.5"/>
			<inertia ixx="0.00104702497304016" ixy="2.01102008398851E-18" ixz="-8.67361737988254E-20" iyy="0.00181031135070458" iyz="3.54092952964764E-17" izz="0.00104702497304016"/>
		</inertial>
		<visual>
			<geometry>
				<mesh filename="file://$(find galaxea_r1lite_description)/meshes/visual/wheel.obj"/>
			</geometry>
		</visual>
		<collision>
			<geometry>
				<mesh filename="file://$(find galaxea_r1lite_description)/meshes/visual/wheel.obj"/>
			</geometry>
		</collision>
	</link>
	<joint name="wheel_motor_joint2" type="fixed">
		<origin xyz="0 0 -0.11165"/>
		<parent link="steer_motor_link2"/>
		<child link="wheel_motor_link2"/>
		<axis xyz="0 1 0"/>
	</joint>
	<link name="steer_motor_link3">
		<inertial>
			<origin xyz="1.76196610579549E-07 7.75116053202407E-05 -0.0852489956386505"/>
			<mass value="1.5"/>
			<inertia ixx="0.000338657650556839" ixy="6.14197589167356E-09" ixz="-6.60563926825079E-09" iyy="0.000503900951850049" iyz="-3.60516228734413E-08" izz="0.000211486748436408"/>
		</inertial>
		<visual>
			<geometry>
				<mesh filename="file://$(find galaxea_r1lite_description)/meshes/visual/steer_motor.obj"/>
			</geometry>
		</visual>
	</link>

	<joint name="steer_motor_joint3" type="fixed">
		<origin xyz="-0.16817 -0.24149 0.18165"/>
		<parent link="base_link"/>
		<child link="steer_motor_link3"/>
		<axis xyz="0 0 1"/>
		<limit lower="${-PI}" upper="${PI}" effort="20" velocity="20"/>
	</joint>

	<link name="wheel_motor_link3">
		<inertial>
			<origin xyz="0 -1.94289029309402E-16 -2.34274405430668E-15"/>
			<mass value="1.5"/>
			<inertia ixx="0.00104702497304016" ixy="2.00017806226365E-18" ixz="-8.67361737988255E-20" iyy="0.00181031135070458" iyz="3.53868224535946E-17" izz="0.00104702497304016"/>
		</inertial>
		<visual>
			<geometry>
				<mesh filename="file://$(find galaxea_r1lite_description)/meshes/visual/wheel.obj"/>
			</geometry>
		</visual>
		<collision>
			<geometry>
				<mesh filename="file://$(find galaxea_r1lite_description)/meshes/visual/wheel.obj"/>
			</geometry>
		</collision>
	</link>

	<joint name="wheel_motor_joint3" type="fixed">
		<origin xyz="0 0 -0.11165"/>
		<parent link="steer_motor_link3"/>
		<child link="wheel_motor_link3"/>
		<axis xyz="0 1 0"/>
	</joint>

	<link name="torso_link1">
		<inertial>
			<origin xyz="0.00321196798398059 0.0116566745256909 0.100697975240297"/>
			<mass value="4.807"/>
			<inertia ixx="0.00310511493924453" ixy="3.89455548949465E-06" ixz="-0.000112029811012738" iyy="0.00326868759782864" iyz="4.14882596510336E-05" izz="0.000354993987137864"/>
		</inertial>
		<visual>
			<geometry>
				<mesh filename="file://$(find galaxea_r1lite_description)/meshes/visual/torso1.obj"/>
			</geometry>
		</visual>
		<collision>
			<geometry>
				<mesh filename="file://$(find galaxea_r1lite_description)/meshes/collision/torso1.stl"/>
			</geometry>
		</collision>
	</link>

	<joint name="torso_joint1" type="revolute">
		<origin xyz="0.091831 0.00036033 0.14865"/>
		<parent link="base_link"/>
		<child link="torso_link1"/>
		<axis xyz="0 1 0"/>
		<limit lower="${-PI/2}" upper="0.436333" effort="100" velocity="2.5"/>
	</joint>

	<link name="torso_link2">
		<inertial>
			<origin xyz="0.00627300956924463 0.00536087570300695 0.184118796618929"/>
			<mass value="2.779"/>
			<inertia ixx="0.0309540761907757" ixy="-5.57959685881806E-07" ixz="0.000297952176364751" iyy="0.032517017639908" iyz="9.00096610164517E-07" izz="0.00185256464591929"/>
		</inertial>
		<visual>
			<geometry>
				<mesh filename="file://$(find galaxea_r1lite_description)/meshes/visual/torso2.obj"/>
			</geometry>
		</visual>
		<collision>
			<geometry>
				<mesh filename="file://$(find galaxea_r1lite_description)/meshes/collision/torso2.stl"/>
			</geometry>
		</collision>
	</link>

	<joint name="torso_joint2" type="revolute">
		<origin xyz="0 -0.00185 0.35"/>
		<parent link="torso_link1"/>
		<child link="torso_link2"/>
		<axis xyz="0 1 0"/>
		<limit lower="-2.705262" upper="2.705262" effort="100" velocity="2.5"/>
	</joint>

	<link name="torso_link3">
		<inertial>
			<origin xyz="-0.0416383086406449 0.000484599582373232 0.051111008977659"/>
			<mass value="5.833"/>
			<inertia ixx="0.00647219350010978" ixy="-4.51460802718021E-07" ixz="-1.28687447342324E-05" iyy="0.0054231706909373" iyz="-1.67510995383755E-07" izz="0.00845061936347779"/>
		</inertial>
		<visual>
			<geometry>
				<mesh filename="file://$(find galaxea_r1lite_description)/meshes/visual/torso3.obj"/>
			</geometry>
		</visual>
		<collision>
			<geometry>
				<mesh filename="file://$(find galaxea_r1lite_description)/meshes/collision/torso3.stl"/>
			</geometry>
		</collision>
	</link>

	<joint name="torso_joint3" type="revolute">
		<origin xyz="9.6485E-05 0 0.35"/>
		<parent link="torso_link2"/>
		<child link="torso_link3"/>
		<axis xyz="0 -1 0"/>
		<limit lower="${-PI/2}" upper="${PI/2}" effort="100" velocity="2.5"/>
	</joint>

	<link name="camera_head_left_link"/>
	<joint name="camera_head_left_joint" type="fixed">
		<origin xyz="0.054947 0.03149 0.63214" rpy="${-2*PI/3} 4.1972E-05 ${-PI/2}"/>
		<parent link="torso_link3"/>
		<child link="camera_head_left_link"/>
	</joint>

	<link name="camera_head_right_link"/>
	<joint name="camera_head_right_joint" type="fixed">
		<origin xyz="0.054943 -0.03351 0.63214" rpy="${-2*PI/3} 4.1972E-05 ${-PI/2}"/>
		<parent link="torso_link3"/>
		<child link="camera_head_right_link"/>
	</joint>

	<joint name="left_arm_base_joint" type="fixed">
		<origin xyz="0 0.335 0.12306"/>
		<parent link="torso_link3"/>
		<child link="left_base_link"/>
	</joint>

	<joint name="right_arm_base_joint" type="fixed">
		<origin xyz="0 -0.335 0.12306"/>
		<parent link="torso_link3"/>
		<child link="right_base_link"/>
	</joint>
</robot>
