<?xml version="1.0" ?>
<!-- =================================================================================== -->
<!-- |    This document was autogenerated by xacro from robot.xacro                    | -->
<!-- |    EDITING THIS FILE BY HAND IS NOT RECOMMENDED                                 | -->
<!-- =================================================================================== -->
<robot name="OpenArm">
  <!-- Arm base link -->
  <link name="base_link">
    <visual>
      <geometry>
        <mesh filename="package://openarm_description/meshes/arm/visual/base.obj" scale="1 1 1"/>
      </geometry>
    </visual>
    <collision>
      <geometry>
        <mesh filename="package://openarm_description/meshes/arm/collision/base.stl"/>
      </geometry>
    </collision>
    <inertial>
      <origin xyz="-0.0009483362816297526 0.0001580207020448382 0.03076860287587199"/>
      <mass value="1.1432284943239561"/>
      <inertia ixx="0.001128" ixy="-4e-06" ixz="-3.3e-05" iyy="0.000962" iyz="-7e-06" izz="0.00147"/>
    </inertial>
  </link>
  <!-- Link 1 -->
  <link name="link1">
    <visual>
      <geometry>
        <mesh filename="package://openarm_description/meshes/arm/visual/link1.obj" scale="1 1 1"/>
      </geometry>
    </visual>
    <collision>
      <geometry>
        <mesh filename="package://openarm_description/meshes/arm/collision/link1.stl" scale="1 1 1"/>
      </geometry>
    </collision>
    <inertial>
      <origin xyz="0.0011467657911800769 3.319987657026362e-05 0.05395284380736254"/>
      <mass value="1.1416684646202298"/>
      <inertia ixx="0.001567" ixy="-1e-06" ixz="-2.9e-05" iyy="0.001273" iyz="1e-06" izz="0.001016"/>
    </inertial>
  </link>
  <joint name="joint1" type="revolute">
    <origin xyz="0.0 0.0 0.0625"/>
    <parent link="base_link"/>
    <child link="link1"/>
    <axis xyz="0 0 1"/>
    <limit effort="40" lower="-1.396263" upper="3.490659" velocity="16.754666"/>
  </joint>
  <!-- Link 2 -->
  <link name="link2">
    <visual>
      <geometry>
        <mesh filename="package://openarm_description/meshes/arm/visual/link2.obj" scale="1 1 1"/>
      </geometry>
    </visual>
    <collision>
      <!-- <origin xyz="0.0301 0.0 -0.1225"/> -->
      <geometry>
        <mesh filename="package://openarm_description/meshes/arm/collision/link2.stl" scale="1 1 1"/>
      </geometry>
    </collision>
    <inertial>
      <origin xyz="0.00839629182351943 -2.0145102027597523e-08 0.03256649300522363"/>
      <mass value="0.2775092746011571"/>
      <inertia ixx="0.000359" ixy="1e-06" ixz="-0.000109" iyy="0.000376" iyz="1e-06" izz="0.000232"/>
    </inertial>
  </link>
  <joint name="joint2" type="revolute">
    <origin xyz="-0.0301 0.0 0.06"/>
    <parent link="link1"/>
    <child link="link2"/>
    <axis xyz="-1 0 0"/>
    <limit effort="40" lower="-0.17453267320510335" upper="3.3161253267948965" velocity="16.754666"/>
  </joint>
  <!-- Link 3 -->
  <link name="link3">
    <visual>
      <geometry>
        <mesh filename="package://openarm_description/meshes/arm/visual/link3.obj" scale="1 1 1"/>
      </geometry>
    </visual>
    <collision>
      <geometry>
        <mesh filename="package://openarm_description/meshes/arm/collision/link3.stl" scale="1 1 1"/>
      </geometry>
    </collision>
    <inertial>
      <origin xyz="-0.002104752099628911 -0.0005549085042607548 0.09047470545721961"/>
      <mass value="1.073863338202347"/>
      <inertia ixx="0.004372" ixy="1e-06" ixz="1.1e-05" iyy="0.004319" iyz="-3.6e-05" izz="0.000661"/>
    </inertial>
  </link>
  <joint name="joint3" type="revolute">
    <origin xyz="0.0301 0.0 0.06625"/>
    <parent link="link2"/>
    <child link="link3"/>
    <axis xyz="0 0 1"/>
    <limit effort="27" lower="-1.570796" upper="1.570796" velocity="5.445426"/>
  </joint>
  <!-- Link 4 -->
  <link name="link4">
    <visual>
      <geometry>
        <mesh filename="package://openarm_description/meshes/arm/visual/link4.obj"/>
      </geometry>
    </visual>
    <collision>
      <geometry>
        <mesh filename="package://openarm_description/meshes/arm/collision/link4.stl"/>
      </geometry>
    </collision>
    <inertial>
      <origin xyz="-0.0029006831074562967 -0.03030575826634669 0.06339637422196209"/>
      <mass value="0.6348534566833373"/>
      <inertia ixx="0.000623" ixy="-1e-06" ixz="-1.9e-05" iyy="0.000511" iyz="3.8e-05" izz="0.000334"/>
    </inertial>
  </link>
  <joint name="joint4" type="revolute">
    <origin xyz="-0.0 0.0315 0.15375"/>
    <parent link="link3"/>
    <child link="link4"/>
    <axis xyz="0 1 0"/>
    <limit effort="27" lower="0.0" upper="2.443461" velocity="5.445426"/>
  </joint>
  <!-- Link 5 -->
  <link name="link5">
    <visual>
      <geometry>
        <mesh filename="package://openarm_description/meshes/arm/visual/link5.obj" scale="1 1 1"/>
      </geometry>
    </visual>
    <collision>
      <geometry>
        <mesh filename="package://openarm_description/meshes/arm/collision/link5.stl" scale="1 1 1"/>
      </geometry>
    </collision>
    <inertial>
      <origin xyz="-0.003049665024221911 0.0008866902457326625 0.043079803024980934"/>
      <mass value="0.6156588026168502"/>
      <inertia ixx="0.000423" ixy="-8e-06" ixz="6e-06" iyy="0.000445" iyz="-6e-06" izz="0.000324"/>
    </inertial>
  </link>
  <joint name="joint5" type="revolute">
    <origin xyz="0.0 -0.0315 0.0955"/>
    <parent link="link4"/>
    <child link="link5"/>
    <axis xyz="0 0 1"/>
    <limit effort="7" lower="-1.570796" upper="1.570796" velocity="20.943946"/>
  </joint>
  <!-- Link 6 -->
  <link name="link6">
    <visual>
      <geometry>
        <mesh filename="package://openarm_description/meshes/arm/visual/link6.obj" scale="1 1 1"/>
      </geometry>
    </visual>
    <collision>
      <geometry>
        <mesh filename="package://openarm_description/meshes/arm/collision/link6.stl" scale="1 1 1"/>
      </geometry>
    </collision>
    <inertial>
      <origin xyz="-0.037136587005447405 0.00033230528343419053 -9.498374522309838e-05"/>
      <mass value="0.475202773187987"/>
      <inertia ixx="0.000143" ixy="1e-06" ixz="1e-06" iyy="0.000157" iyz="1e-06" izz="0.000159"/>
    </inertial>
  </link>
  <joint name="joint6" type="revolute">
    <origin xyz="0.0375 0.0 0.1205"/>
    <parent link="link5"/>
    <child link="link6"/>
    <axis xyz="1 0 0"/>
    <limit effort="7" lower="-0.785398" upper="0.785398" velocity="20.943946"/>
  </joint>
  <!-- Link 7 -->
  <link name="link7">
    <visual>
      <geometry>
        <mesh filename="package://openarm_description/meshes/arm/visual/link7.obj" scale="1 1 1"/>
      </geometry>
    </visual>
    <collision>
      <geometry>
        <mesh filename="package://openarm_description/meshes/arm/collision/link7.stl" scale="1 1 1"/>
      </geometry>
    </collision>
    <inertial>
      <origin xyz="6.875510271106056e-05 0.01266175250761268 0.06951945409987448"/>
      <mass value="0.4659771327380578"/>
      <inertia ixx="0.000639" ixy="1e-06" ixz="1e-06" iyy="0.000497" iyz="8.9e-05" izz="0.000342"/>
    </inertial>
  </link>
  <joint name="joint7" type="revolute">
    <origin xyz="-0.0375 0.0 0.0"/>
    <parent link="link6"/>
    <child link="link7"/>
    <axis xyz="0 1 0"/>
    <limit effort="7" lower="-1.570796" upper="1.570796" velocity="20.943946"/>
  </joint>
  <joint name="hand_joint" type="fixed">
    <parent link="link7"/>
    <child link="hand"/>
    <origin xyz="0 -0.0 0.1001"/>
  </joint>
  <!-- Hand base link -->
  <link name="hand">
    <visual>
      <geometry>
        <mesh filename="package://openarm_description/meshes/gripper/visual/hand.obj"/>
      </geometry>
    </visual>
    <collision>
      <geometry>
        <mesh filename="package://openarm_description/meshes/gripper/collision/hand.stl"/>
      </geometry>
    </collision>
    <inertial>
      <origin xyz="0.0 0.002 0.03"/>
      <mass value="0.35"/>
      <inertia ixx="0.0002473" ixy="1e-06" ixz="1e-06" iyy="1.763e-05" iyz="1e-06" izz="0.0002521"/>
    </inertial>
  </link>
  <!-- Hand TCP frame -->
  <link name="hand_tcp"/>
  <joint name="hand_tcp_joint" type="fixed">
    <origin xyz="0 -0.0 0.08"/>
    <parent link="hand"/>
    <child link="hand_tcp"/>
  </joint>
  <!-- Left finger (from gripper perspective) -->
  <link name="left_finger">
    <visual>
      <geometry>
        <mesh filename="package://openarm_description/meshes/gripper/visual/finger.obj"/>
      </geometry>
    </visual>
    <collision>
      <geometry>
        <mesh filename="package://openarm_description/meshes/gripper/collision/finger.stl"/>
      </geometry>
    </collision>
    <inertial>
      <origin xyz="0.0064528 0.01702 0.0219685"/>
      <mass value="0.03602545343277134"/>
      <inertia ixx="0.0001" ixy="0" ixz="0" iyy="0.0001" iyz="0" izz="0.0001"/>
    </inertial>
  </link>
  <!-- Right finger (from gripper perspective) -->
  <link name="right_finger">
    <inertial>
      <origin xyz="0.0064528 -0.01702 0.0219685"/>
      <mass value="0.03602545343277134"/>
      <inertia ixx="0.0001" ixy="0" ixz="0" iyy="0.0001" iyz="0" izz="0.0001"/>
    </inertial>
    <visual>
      <geometry>
        <mesh filename="package://openarm_description/meshes/gripper/visual/finger.obj" scale="1 -1 1"/>
      </geometry>
    </visual>
    <collision>
      <geometry>
        <mesh filename="package://openarm_description/meshes/gripper/collision/finger.stl" scale="1 -1 1"/>
      </geometry>
    </collision>
  </link>
  <!-- Finger joints -->
  <joint name="gripper_joint" type="prismatic">
    <parent link="hand"/>
    <child link="right_finger"/>
    <origin xyz="0 -0.006 0.015"/>
    <axis xyz="0 -1 0"/>
    <limit effort="333" lower="0.0" upper="0.044" velocity="10.0"/>
  </joint>
  <joint name="finger_joint2" type="prismatic">
    <parent link="hand"/>
    <child link="left_finger"/>
    <origin xyz="0 0.006 0.015"/>
    <axis xyz="0 1 0"/>
    <limit effort="333" lower="0.0" upper="0.044" velocity="10.0"/>
    <mimic joint="gripper_joint"/>
  </joint>
</robot>
