<?xml version="1.0" ?>
<!-- =================================================================================== -->
<!-- |    This document was autogenerated by xacro from robot.xacro                    | -->
<!-- |    EDITING THIS FILE BY HAND IS NOT RECOMMENDED                                 | -->
<!-- =================================================================================== -->
<robot name="R1Pro">
  <!-- Base Link -->
  <link name="base_link">
    <inertial>
      <origin xyz="-0.0024126 -8.9626E-05 0.13736"/>
      <mass value="47.63"/>
      <inertia ixx="1.578" ixy="-1.2021E-05" ixz="0.053642" iyy="1.462" iyz="7.297E-06" izz="2.8318"/>
    </inertial>
    <visual>
      <geometry>
        <mesh filename="package://galaxea_r1_description/meshes/base_link.obj"/>
      </geometry>
    </visual>
    <collision>
      <geometry>
        <mesh filename="package://galaxea_r1_description/meshes/base_link.obj"/>
      </geometry>
    </collision>
  </link>
  <!-- Steer Motor Link 1 -->
  <link name="steer_motor_link1">
    <inertial>
      <origin xyz="0.00098921 -0.034312 -0.034597"/>
      <mass value="1.2"/>
      <inertia ixx="8.8522E-05" ixy="-3.7755E-06" ixz="4.5456E-09" iyy="7.5352E-05" iyz="-7.0316E-07" izz="0.00010165"/>
    </inertial>
    <visual>
      <geometry>
        <mesh filename="package://galaxea_r1_description/meshes/steer_motor.obj"/>
      </geometry>
    </visual>
    <collision>
      <geometry>
        <mesh filename="package://galaxea_r1_description/meshes/steer_motor.obj"/>
      </geometry>
    </collision>
  </link>
  <!-- Steer Motor Joint 1: Base to Steer Motor 1 -->
  <joint name="steer_motor_joint1" type="revolute">
    <origin xyz="0.21516 0.28 0.12375"/>
    <parent link="base_link"/>
    <child link="steer_motor_link1"/>
    <axis xyz="0 0 1"/>
    <limit effort="44" lower="-1.5708" upper="1.5708" velocity="3.1416"/>
  </joint>
  <!-- Wheel Motor Link 1 -->
  <link name="wheel_motor_link1">
    <inertial>
      <origin xyz="-2.6184E-06 0.0015607 1.6575E-07"/>
      <mass value="5"/>
      <inertia ixx="0.00089952" ixy="6.916E-08" ixz="7.5501E-10" iyy="0.0015854" iyz="7.6011E-12" izz="0.00089958"/>
    </inertial>
    <visual>
      <geometry>
        <mesh filename="package://galaxea_r1_description/meshes/wheel_motor.obj"/>
      </geometry>
    </visual>
    <collision>
      <geometry>
        <mesh filename="package://galaxea_r1_description/meshes/wheel_motor.obj"/>
      </geometry>
    </collision>
  </link>
  <!-- Wheel Motor Joint 1: Steer Motor 1 to Wheel Motor 1 -->
  <joint name="wheel_motor_joint1" type="continuous">
    <origin rpy="0 0 3.14159" xyz="0 0 -0.09525"/>
    <parent link="steer_motor_link1"/>
    <child link="wheel_motor_link1"/>
    <axis xyz="0 1 0"/>
  </joint>
  <!-- Steer Motor Link 2 -->
  <link name="steer_motor_link2">
    <inertial>
      <origin xyz="0.00098879 0.034317 -0.034601"/>
      <mass value="1.2"/>
      <inertia ixx="8.8509E-05" ixy="3.7728E-06" ixz="4.584E-09" iyy="7.5337E-05" iyz="7.0145E-07" izz="0.00010162"/>
    </inertial>
    <visual>
      <origin rpy="0 0 3.14159"/>
      <geometry>
        <mesh filename="package://galaxea_r1_description/meshes/steer_motor.obj"/>
      </geometry>
    </visual>
    <collision>
      <origin rpy="0 0 3.14159"/>
      <geometry>
        <mesh filename="package://galaxea_r1_description/meshes/steer_motor.obj"/>
      </geometry>
    </collision>
  </link>
  <!-- Steer Motor Joint 2: Base to Steer Motor 2 -->
  <joint name="steer_motor_joint2" type="revolute">
    <origin xyz="0.21516 -0.28 0.12375"/>
    <parent link="base_link"/>
    <child link="steer_motor_link2"/>
    <axis xyz="0 0 1"/>
    <limit effort="44" lower="-1.5708" upper="1.5708" velocity="3.1416"/>
  </joint>
  <!-- Wheel Motor Link 2 -->
  <link name="wheel_motor_link2">
    <inertial>
      <origin xyz="2.6199E-06 -0.0015607 1.6573E-07"/>
      <mass value="5"/>
      <inertia ixx="0.00089952" ixy="6.9163E-08" ixz="-7.5368E-10" iyy="0.0015854" iyz="-7.6749E-12" izz="0.00089958"/>
    </inertial>
    <visual>
      <geometry>
        <mesh filename="package://galaxea_r1_description/meshes/wheel_motor.obj"/>
      </geometry>
    </visual>
    <collision>
      <geometry>
        <mesh filename="package://galaxea_r1_description/meshes/wheel_motor.obj"/>
      </geometry>
    </collision>
  </link>
  <!-- Wheel Motor Joint 2: Steer Motor 2 to Wheel Motor 2 -->
  <joint name="wheel_motor_joint2" type="continuous">
    <origin xyz="0 0 -0.09525"/>
    <parent link="steer_motor_link2"/>
    <child link="wheel_motor_link2"/>
    <axis xyz="0 1 0"/>
  </joint>
  <!-- Steer Motor Link 3 -->
  <link name="steer_motor_link3">
    <inertial>
      <origin xyz="-0.00098879 -0.034317 -0.034601"/>
      <mass value="1.2"/>
      <inertia ixx="8.8509E-05" ixy="3.7728E-06" ixz="-4.584E-09" iyy="7.5337E-05" iyz="-7.0145E-07" izz="0.00010162"/>
    </inertial>
    <visual>
      <geometry>
        <mesh filename="package://galaxea_r1_description/meshes/steer_motor.obj"/>
      </geometry>
    </visual>
    <collision>
      <geometry>
        <mesh filename="package://galaxea_r1_description/meshes/steer_motor.obj"/>
      </geometry>
    </collision>
  </link>
  <!-- Steer Motor Joint 3: Base to Steer Motor 3 -->
  <joint name="steer_motor_joint3" type="revolute">
    <origin xyz="-0.28084 0 0.12375"/>
    <parent link="base_link"/>
    <child link="steer_motor_link3"/>
    <axis xyz="0 0 1"/>
    <limit effort="44" lower="-1.5708" upper="1.5708" velocity="3.1416"/>
  </joint>
  <!-- Wheel Motor Link 3 -->
  <link name="wheel_motor_link3">
    <inertial>
      <origin xyz="2.6203E-06 0.0015607 -1.6564E-07"/>
      <mass value="5"/>
      <inertia ixx="0.00089952" ixy="-6.9072E-08" ixz="7.5036E-10" iyy="0.0015854" iyz="-7.845E-12" izz="0.00089958"/>
    </inertial>
    <visual>
      <geometry>
        <mesh filename="package://galaxea_r1_description/meshes/wheel_motor.obj"/>
      </geometry>
    </visual>
    <collision>
      <geometry>
        <mesh filename="package://galaxea_r1_description/meshes/wheel_motor.obj"/>
      </geometry>
    </collision>
  </link>
  <!-- Wheel Motor Joint 3: Steer Motor 3 to Wheel Motor 3 -->
  <joint name="wheel_motor_joint3" type="continuous">
    <origin rpy="0 0 3.14159" xyz="0 0 -0.09525"/>
    <parent link="steer_motor_link3"/>
    <child link="wheel_motor_link3"/>
    <axis xyz="0 1 0"/>
  </joint>
  <!-- Torso Link 1 -->
  <link name="torso_link1">
    <inertial>
      <origin xyz="0.00065636 0.0032247 0.23142"/>
      <mass value="5.72"/>
      <inertia ixx="0.10931" ixy="7.7893E-06" ixz="-0.00017473" iyy="0.10736" iyz="0.00013763" izz="0.0081222"/>
    </inertial>
    <visual>
      <geometry>
        <mesh filename="package://galaxea_r1_description/meshes/torso_link1.obj"/>
      </geometry>
    </visual>
    <collision>
      <geometry>
        <mesh filename="package://galaxea_r1_description/meshes/torso_link1.obj"/>
      </geometry>
    </collision>
  </link>
  <!-- Torso Joint 1: Base to Torso 1 -->
  <joint name="torso_joint1" type="revolute">
    <origin xyz="-0.032845 0 0.301"/>
    <parent link="base_link"/>
    <child link="torso_link1"/>
    <axis xyz="0 1 0"/>
    <limit effort="500" lower="-1.1345" upper="1.8326" velocity="2.5"/>
  </joint>
  <!-- Torso Link 2 -->
  <link name="torso_link2">
    <inertial>
      <origin xyz="0.0052517 0.014412 0.15711"/>
      <mass value="3.5"/>
      <inertia ixx="0.026081" ixy="-3.3406E-07" ixz="0.00024541" iyy="0.027574" iyz="3.8474E-07" izz="0.0018515"/>
    </inertial>
    <visual>
      <geometry>
        <mesh filename="package://galaxea_r1_description/meshes/torso_link2.obj"/>
      </geometry>
    </visual>
    <collision>
      <geometry>
        <mesh filename="package://galaxea_r1_description/meshes/torso_link2.obj"/>
      </geometry>
    </collision>
  </link>
  <!-- Torso Joint 2: Torso 1 to Torso 2 -->
  <joint name="torso_joint2" type="revolute">
    <origin xyz="0 0 0.4"/>
    <parent link="torso_link1"/>
    <child link="torso_link2"/>
    <axis xyz="0 1 0"/>
    <limit effort="500" lower="-2.7925" upper="2.5307" velocity="2.5"/>
  </joint>
  <!-- Torso Link 3 -->
  <link name="torso_link3">
    <inertial>
      <origin xyz="-7.551E-06 -0.0092667 0.0042124"/>
      <mass value="3.4"/>
      <inertia ixx="0.0014058" ixy="3.5487E-07" ixz="9.0955E-08" iyy="0.0021992" iyz="1.6338E-05" izz="0.0013332"/>
    </inertial>
    <visual>
      <geometry>
        <mesh filename="package://galaxea_r1_description/meshes/torso_link3.obj"/>
      </geometry>
    </visual>
    <collision>
      <geometry>
        <mesh filename="package://galaxea_r1_description/meshes/torso_link3.obj"/>
      </geometry>
    </collision>
  </link>
  <!-- Torso Joint 3: Torso 2 to Torso 3 -->
  <joint name="torso_joint3" type="revolute">
    <origin xyz="0 0 0.3"/>
    <parent link="torso_link2"/>
    <child link="torso_link3"/>
    <axis xyz="0 -1 0"/>
    <limit effort="500" lower="-1.8326" upper="1.5708" velocity="2.5"/>
  </joint>
  <!-- Torso Link 4 -->
  <link name="torso_link4">
    <inertial>
      <origin xyz="-3.7511E-08 5.2756E-07 0.018688"/>
      <mass value="7.4"/>
      <inertia ixx="0.0014989" ixy="2.9183E-08" ixz="-7.7884E-10" iyy="0.001499" iyz="-1.2513E-10" izz="0.0019043"/>
    </inertial>
    <visual>
      <geometry>
        <mesh filename="package://galaxea_r1_description/meshes/torso_link4.obj"/>
      </geometry>
    </visual>
    <collision>
      <geometry>
        <mesh filename="package://galaxea_r1_description/meshes/torso_link4.obj"/>
      </geometry>
    </collision>
  </link>
  <!-- Torso Joint 4: Torso 3 to Torso 4 -->
  <joint name="torso_joint4" type="revolute">
    <origin xyz="0 0 0.09962"/>
    <parent link="torso_link3"/>
    <child link="torso_link4"/>
    <axis xyz="0 0 1"/>
    <limit effort="500" lower="-3.0543" upper="3.0543" velocity="2.5"/>
  </joint>
  <!-- ZED Camera Link -->
  <link name="zed_link">
    <inertial>
      <origin xyz="0.060004 0.015906 -0.068413"/>
      <mass value="2.05"/>
      <inertia ixx="0.010375" ixy="1.9044E-07" ixz="1.5997E-08" iyy="0.014618" iyz="0.00028961" izz="0.012229"/>
    </inertial>
    <visual>
      <geometry>
        <mesh filename="package://galaxea_r1_description/meshes/zed_link.obj"/>
      </geometry>
    </visual>
    <collision>
      <geometry>
        <mesh filename="package://galaxea_r1_description/meshes/zed_link.obj"/>
      </geometry>
    </collision>
  </link>
  <!-- ZED Joint: Torso 4 to ZED -->
  <joint name="zed_joint" type="fixed">
    <origin rpy="-1.9199 0 -1.5708" xyz="0.065512 0.060005 0.47598"/>
    <parent link="torso_link4"/>
    <child link="zed_link"/>
    <axis xyz="0 0 0"/>
  </joint>
  <link name="left_base_link">
    <inertial>
      <origin xyz="0.00026981 0.034587 0"/>
      <mass value="1.48"/>
      <inertia ixx="0.0010298" ixy="5.2194E-06" ixz="-1.2182E-07" iyy="0.0014076" iyz="-3.9334E-09" izz="0.0010201"/>
    </inertial>
    <visual>
      <geometry>
        <mesh filename="package://galaxea_r1pro_description/meshes/pro_arm/base.obj" scale="1 1 1"/>
      </geometry>
    </visual>
    <collision>
      <geometry>
        <mesh filename="package://galaxea_r1pro_description/meshes/pro_arm/base.obj" scale="1 1 1"/>
      </geometry>
    </collision>
  </link>
  <!-- Arm Link 1 -->
  <link name="left_link1">
    <inertial>
      <origin xyz="0.00042258 0.074131 7.9156E-05"/>
      <mass value="1.135"/>
      <inertia ixx="0.00061603" ixy="-1.1635E-06" ixz="-6.9725E-07" iyy="0.00030259" iyz="-6.2894E-07" izz="0.00047136"/>
    </inertial>
    <visual>
      <geometry>
        <mesh filename="package://galaxea_r1pro_description/meshes/pro_arm/link1.obj" scale="1 1 1"/>
      </geometry>
    </visual>
    <collision>
      <geometry>
        <mesh filename="package://galaxea_r1pro_description/meshes/pro_arm/link1.obj" scale="1 1 1"/>
      </geometry>
    </collision>
  </link>
  <!-- Arm Link 2 -->
  <link name="left_link2">
    <inertial>
      <origin xyz="-0.026826 -0.0040392 -0.031835"/>
      <mass value="0.92"/>
      <inertia ixx="0.00037378" ixy="-7.5909E-07" ixz="2.9042E-06" iyy="0.00033872" iyz="1.2166E-05" izz="0.00032361"/>
    </inertial>
    <visual>
      <geometry>
        <mesh filename="package://galaxea_r1pro_description/meshes/pro_arm/link2.obj" scale="1 1 1"/>
      </geometry>
    </visual>
    <collision>
      <geometry>
        <mesh filename="package://galaxea_r1pro_description/meshes/pro_arm/link2.obj" scale="1 1 1"/>
      </geometry>
    </collision>
  </link>
  <!-- Arm Link 3 -->
  <link name="left_link3">
    <inertial>
      <origin xyz="0.0053849 -0.00086892 -0.1126"/>
      <mass value="1.245"/>
      <inertia ixx="0.00072339" ixy="-3.3477E-06" ixz="-0.00012824" iyy="0.00073856" iyz="-8.3574E-06" izz="0.00037352"/>
    </inertial>
    <visual>
      <geometry>
        <mesh filename="package://galaxea_r1pro_description/meshes/pro_arm/link3.obj"/>
      </geometry>
    </visual>
    <collision>
      <geometry>
        <mesh filename="package://galaxea_r1pro_description/meshes/pro_arm/link3.obj"/>
      </geometry>
    </collision>
  </link>
  <!-- Arm Link 4 -->
  <link name="left_link4">
    <inertial>
      <origin xyz="-0.0011018 -0.036243 -0.042164"/>
      <mass value="0.827"/>
      <inertia ixx="0.00013884" ixy="7.8394E-08" ixz="3.5926E-06" iyy="0.00019751" iyz="1.4227E-06" izz="0.00010229"/>
    </inertial>
    <visual>
      <geometry>
        <mesh filename="package://galaxea_r1pro_description/meshes/pro_arm/link4.obj"/>
      </geometry>
    </visual>
    <collision>
      <geometry>
        <mesh filename="package://galaxea_r1pro_description/meshes/pro_arm/link4.obj"/>
      </geometry>
    </collision>
  </link>
  <!-- Arm Link 5 -->
  <link name="left_link5">
    <inertial>
      <origin xyz="0 -0.0028035 -0.062981"/>
      <mass value="0.939"/>
      <inertia ixx="0.00070496" ixy="1.4329E-08" ixz="-2.9036E-09" iyy="0.00067006" iyz="-5.1951E-05" izz="0.00032998"/>
    </inertial>
    <visual>
      <geometry>
        <mesh filename="package://galaxea_r1pro_description/meshes/pro_arm/link5.obj" scale="1 1 1"/>
      </geometry>
    </visual>
    <collision>
      <geometry>
        <mesh filename="package://galaxea_r1pro_description/meshes/pro_arm/link5.obj" scale="1 1 1"/>
      </geometry>
    </collision>
  </link>
  <!-- Arm Link 6 -->
  <link name="left_link6">
    <inertial>
      <origin xyz="0.0017919 0.027487 0.00025471"/>
      <mass value="0.527"/>
      <inertia ixx="8.5442E-05" ixy="-1.5351E-07" ixz="8.3797E-07" iyy="8.1186E-05" iyz="-2.1972E-08" izz="8.2736E-05"/>
    </inertial>
    <visual>
      <geometry>
        <mesh filename="package://galaxea_r1pro_description/meshes/pro_arm/link6.obj" scale="1 1 1"/>
      </geometry>
    </visual>
    <collision>
      <geometry>
        <mesh filename="package://galaxea_r1pro_description/meshes/pro_arm/link6.obj" scale="1 1 1"/>
      </geometry>
    </collision>
  </link>
  <!-- Arm Link 7 -->
  <link name="left_link7">
    <inertial>
      <origin xyz="-0.022945 0 -0.056525"/>
      <mass value="0.185"/>
      <inertia ixx="4.2564E-05" ixy="-2.1577E-09" ixz="-6.9368E-06" iyy="4.5515E-05" iyz="-1.9389E-09" izz="4.7946E-05"/>
    </inertial>
    <visual>
      <geometry>
        <mesh filename="package://galaxea_r1pro_description/meshes/pro_arm/link7.obj"/>
      </geometry>
    </visual>
    <collision>
      <geometry>
        <mesh filename="package://galaxea_r1pro_description/meshes/pro_arm/link7.obj"/>
      </geometry>
    </collision>
  </link>
  <!-- Arm Joints and Links -->
  <joint name="left_base_joint" type="fixed">
    <origin xyz="-0.00048618 0.097234 0.30302"/>
    <parent link="torso_link4"/>
    <child link="left_base_link"/>
  </joint>
  <!-- Arm Joints -->
  <joint name="left_joint1" type="revolute">
    <origin xyz="0 0.0735 0"/>
    <parent link="left_base_link"/>
    <child link="left_link1"/>
    <axis xyz="0 1 0"/>
    <limit effort="55" lower="-4.4506" upper="1.3090" velocity="7.1209"/>
  </joint>
  <joint name="left_joint2" type="revolute">
    <origin xyz="0.025012 0.081265 0"/>
    <parent link="left_link1"/>
    <child link="left_link2"/>
    <axis xyz="1 0 0"/>
    <limit effort="55" lower="-0.1745" upper="3.1416" velocity="7.1209"/>
  </joint>
  <joint name="left_joint3" type="revolute">
    <origin xyz="-0.025012 0 -0.1155"/>
    <parent link="left_link2"/>
    <child link="left_link3"/>
    <axis xyz="0 0 1"/>
    <limit effort="25" lower="-2.356196" upper="2.356196" velocity="8.3776"/>
  </joint>
  <joint name="left_joint4" type="revolute">
    <origin xyz="0 0.035065 -0.1945"/>
    <parent link="left_link3"/>
    <child link="left_link4"/>
    <axis xyz="0 1 0"/>
    <limit effort="25" lower="-2.0944" upper="0.3491" velocity="8.3776"/>
  </joint>
  <joint name="left_joint5" type="revolute">
    <origin xyz="0 -0.035065 -0.095"/>
    <parent link="left_link4"/>
    <child link="left_link5"/>
    <axis xyz="0 0 1"/>
    <limit effort="18" lower="-2.356196" upper="2.356196" velocity="10.4720"/>
  </joint>
  <joint name="left_joint6" type="revolute">
    <origin xyz="0 -0.028 -0.16305"/>
    <parent link="left_link5"/>
    <child link="left_link6"/>
    <axis xyz="0 1 0"/>
    <limit effort="18" lower="-1.047198" upper="1.047198" velocity="10.4720"/>
  </joint>
  <joint name="left_joint7" type="revolute">
    <origin xyz="0.0295 0.028 0"/>
    <parent link="left_link6"/>
    <child link="left_link7"/>
    <axis xyz="1 0 0"/>
    <limit effort="18" lower="-1.5708" upper="1.5708" velocity="10.4720"/>
  </joint>
  <link name="left_gripper_base">
    <inertial>
      <origin xyz="-0.0311072323899603 1.17979991887118E-08 7.93394685505433E-08"/>
      <mass value="0.604"/>
      <inertia ixx="0.000175881544189539" ixy="-6.06026450851008E-11" ixz="5.30643405624365E-10" iyy="9.86379407701341E-05" iyz="-8.18686692495892E-08" izz="0.000165121280580029"/>
    </inertial>
    <visual>
      <geometry>
        <mesh filename="package://galaxea_a1_description/meshes/gripper/gripper_link.obj"/>
      </geometry>
    </visual>
    <collision>
      <geometry>
        <mesh filename="package://galaxea_a1_description/meshes/gripper/gripper_link.obj"/>
      </geometry>
    </collision>
  </link>
  <link name="left_finger1">
    <inertial>
      <origin xyz="-0.0195895895552112 -0.0151136845490034 0.00542254359093075"/>
      <mass value="0.027"/>
      <inertia ixx="2.40569358477209E-06" ixy="3.9898459609048E-07" ixz="5.12152762183641E-08" iyy="5.71079298307516E-06" iyz="6.19467902008363E-08" izz="6.48482183930358E-06"/>
    </inertial>
    <visual>
      <geometry>
        <mesh filename="package://galaxea_a1_description/meshes/gripper/finger.obj"/>
      </geometry>
    </visual>
    <collision>
      <geometry>
        <mesh filename="package://galaxea_a1_description/meshes/gripper/finger.obj"/>
      </geometry>
    </collision>
  </link>
  <joint name="left_gripper_joint" type="prismatic">
    <origin xyz="0.03689 0.013453 0.00012059"/>
    <parent link="left_gripper_base"/>
    <child link="left_finger1"/>
    <axis xyz="0 1 0"/>
    <limit effort="100" lower="0" upper="0.05" velocity="0.25"/>
  </joint>
  <link name="left_finger2">
    <inertial>
      <origin xyz="-0.0195895857999098 0.0151136893508115 -0.00542254357246619"/>
      <mass value="0.027"/>
      <inertia ixx="2.40569340151687E-06" ixy="-3.98983784827124E-07" ixz="-5.12152683073981E-08" iyy="5.71079321589929E-06" iyz="6.19467953006536E-08" izz="6.48482187274222E-06"/>
    </inertial>
    <visual>
      <geometry>
        <mesh filename="package://galaxea_a1_description/meshes/gripper/finger.obj" scale="1 -1 -1"/>
      </geometry>
    </visual>
    <collision>
      <geometry>
        <mesh filename="package://galaxea_a1_description/meshes/gripper/finger.obj" scale="1 -1 -1"/>
      </geometry>
    </collision>
  </link>
  <joint name="left_gripper_joint2" type="prismatic">
    <origin xyz="0.03689 -0.013453 -0.00012059"/>
    <parent link="left_gripper_base"/>
    <child link="left_finger2"/>
    <axis xyz="0 -1 0"/>
    <limit effort="100" lower="0" upper="0.05" velocity="0.25"/>
    <mimic joint="left_gripper_joint" multiplier="1" offset="0"/>
  </joint>
  <link name="left_gripper_center"/>
  <joint name="left_gripper_center_joint" type="fixed">
    <origin xyz="0.03689 0 -0.00012059"/>
    <parent link="left_gripper_base"/>
    <child link="left_gripper_center"/>
  </joint>
  <joint name="left_gripper_base_joint" type="fixed">
    <origin rpy="0 1.5708 0" xyz="-0.0295 0 -0.16065"/>
    <parent link="left_link7"/>
    <child link="left_gripper_base"/>
  </joint>
  <link name="right_base_link">
    <inertial>
      <origin xyz="0.00026981 -0.034587 0"/>
      <mass value="1.48"/>
      <inertia ixx="0.0010298" ixy="5.2194E-06" ixz="-1.2182E-07" iyy="0.0014076" iyz="-3.9334E-09" izz="0.0010201"/>
    </inertial>
    <visual>
      <geometry>
        <mesh filename="package://galaxea_r1pro_description/meshes/pro_arm/base.obj" scale="1 -1 1"/>
      </geometry>
    </visual>
    <collision>
      <geometry>
        <mesh filename="package://galaxea_r1pro_description/meshes/pro_arm/base.obj" scale="1 -1 1"/>
      </geometry>
    </collision>
  </link>
  <!-- Arm Link 1 -->
  <link name="right_link1">
    <inertial>
      <origin xyz="0.00042258 -0.074131 7.9156E-05"/>
      <mass value="1.135"/>
      <inertia ixx="0.00061603" ixy="-1.1635E-06" ixz="-6.9725E-07" iyy="0.00030259" iyz="-6.2894E-07" izz="0.00047136"/>
    </inertial>
    <visual>
      <geometry>
        <mesh filename="package://galaxea_r1pro_description/meshes/pro_arm/link1.obj" scale="1 -1 1"/>
      </geometry>
    </visual>
    <collision>
      <geometry>
        <mesh filename="package://galaxea_r1pro_description/meshes/pro_arm/link1.obj" scale="1 -1 1"/>
      </geometry>
    </collision>
  </link>
  <!-- Arm Link 2 -->
  <link name="right_link2">
    <inertial>
      <origin xyz="-0.026826 0.0040392 -0.031835"/>
      <mass value="0.92"/>
      <inertia ixx="0.00037378" ixy="-7.5909E-07" ixz="2.9042E-06" iyy="0.00033872" iyz="1.2166E-05" izz="0.00032361"/>
    </inertial>
    <visual>
      <geometry>
        <mesh filename="package://galaxea_r1pro_description/meshes/pro_arm/link2.obj" scale="1 -1 1"/>
      </geometry>
    </visual>
    <collision>
      <geometry>
        <mesh filename="package://galaxea_r1pro_description/meshes/pro_arm/link2.obj" scale="1 -1 1"/>
      </geometry>
    </collision>
  </link>
  <!-- Arm Link 3 -->
  <link name="right_link3">
    <inertial>
      <origin xyz="0.0053849 -0.00086892 -0.1126"/>
      <mass value="1.245"/>
      <inertia ixx="0.00072339" ixy="-3.3477E-06" ixz="-0.00012824" iyy="0.00073856" iyz="-8.3574E-06" izz="0.00037352"/>
    </inertial>
    <visual>
      <geometry>
        <mesh filename="package://galaxea_r1pro_description/meshes/pro_arm/link3.obj"/>
      </geometry>
    </visual>
    <collision>
      <geometry>
        <mesh filename="package://galaxea_r1pro_description/meshes/pro_arm/link3.obj"/>
      </geometry>
    </collision>
  </link>
  <!-- Arm Link 4 -->
  <link name="right_link4">
    <inertial>
      <origin xyz="-0.0011018 -0.036243 -0.042164"/>
      <mass value="0.827"/>
      <inertia ixx="0.00013884" ixy="7.8394E-08" ixz="3.5926E-06" iyy="0.00019751" iyz="1.4227E-06" izz="0.00010229"/>
    </inertial>
    <visual>
      <geometry>
        <mesh filename="package://galaxea_r1pro_description/meshes/pro_arm/link4.obj"/>
      </geometry>
    </visual>
    <collision>
      <geometry>
        <mesh filename="package://galaxea_r1pro_description/meshes/pro_arm/link4.obj"/>
      </geometry>
    </collision>
  </link>
  <!-- Arm Link 5 -->
  <link name="right_link5">
    <inertial>
      <origin xyz="0 0.0028035 -0.062981"/>
      <mass value="0.939"/>
      <inertia ixx="0.00070496" ixy="1.4329E-08" ixz="-2.9036E-09" iyy="0.00067006" iyz="-5.1951E-05" izz="0.00032998"/>
    </inertial>
    <visual>
      <geometry>
        <mesh filename="package://galaxea_r1pro_description/meshes/pro_arm/link5.obj" scale="1 -1 1"/>
      </geometry>
    </visual>
    <collision>
      <geometry>
        <mesh filename="package://galaxea_r1pro_description/meshes/pro_arm/link5.obj" scale="1 -1 1"/>
      </geometry>
    </collision>
  </link>
  <!-- Arm Link 6 -->
  <link name="right_link6">
    <inertial>
      <origin xyz="0.0017919 -0.027487 0.00025471"/>
      <mass value="0.527"/>
      <inertia ixx="8.5442E-05" ixy="-1.5351E-07" ixz="8.3797E-07" iyy="8.1186E-05" iyz="-2.1972E-08" izz="8.2736E-05"/>
    </inertial>
    <visual>
      <geometry>
        <mesh filename="package://galaxea_r1pro_description/meshes/pro_arm/link6.obj" scale="1 -1 1"/>
      </geometry>
    </visual>
    <collision>
      <geometry>
        <mesh filename="package://galaxea_r1pro_description/meshes/pro_arm/link6.obj" scale="1 -1 1"/>
      </geometry>
    </collision>
  </link>
  <!-- Arm Link 7 -->
  <link name="right_link7">
    <inertial>
      <origin xyz="-0.022945 0 -0.056525"/>
      <mass value="0.185"/>
      <inertia ixx="4.2564E-05" ixy="-2.1577E-09" ixz="-6.9368E-06" iyy="4.5515E-05" iyz="-1.9389E-09" izz="4.7946E-05"/>
    </inertial>
    <visual>
      <geometry>
        <mesh filename="package://galaxea_r1pro_description/meshes/pro_arm/link7.obj"/>
      </geometry>
    </visual>
    <collision>
      <geometry>
        <mesh filename="package://galaxea_r1pro_description/meshes/pro_arm/link7.obj"/>
      </geometry>
    </collision>
  </link>
  <!-- Arm Joints and Links -->
  <joint name="right_base_joint" type="fixed">
    <origin xyz="-0.00048618 -0.097234 0.30302"/>
    <parent link="torso_link4"/>
    <child link="right_base_link"/>
  </joint>
  <!-- Arm Joints -->
  <joint name="right_joint1" type="revolute">
    <origin xyz="0 -0.0735 0"/>
    <parent link="right_base_link"/>
    <child link="right_link1"/>
    <axis xyz="0 1 0"/>
    <limit effort="55" lower="-4.4506" upper="1.3090" velocity="7.1209"/>
  </joint>
  <joint name="right_joint2" type="revolute">
    <origin xyz="0.025012 -0.081265 0"/>
    <parent link="right_link1"/>
    <child link="right_link2"/>
    <axis xyz="-1 0 0"/>
    <limit effort="55" lower="-0.1745" upper="3.1416" velocity="7.1209"/>
  </joint>
  <joint name="right_joint3" type="revolute">
    <origin xyz="-0.025012 0 -0.1155"/>
    <parent link="right_link2"/>
    <child link="right_link3"/>
    <axis xyz="0 0 1"/>
    <limit effort="25" lower="-2.356196" upper="2.356196" velocity="8.3776"/>
  </joint>
  <joint name="right_joint4" type="revolute">
    <origin xyz="0 0.035065 -0.1945"/>
    <parent link="right_link3"/>
    <child link="right_link4"/>
    <axis xyz="0 1 0"/>
    <limit effort="25" lower="-2.0944" upper="0.3491" velocity="8.3776"/>
  </joint>
  <joint name="right_joint5" type="revolute">
    <origin xyz="0 -0.035065 -0.095"/>
    <parent link="right_link4"/>
    <child link="right_link5"/>
    <axis xyz="0 0 1"/>
    <limit effort="18" lower="-2.356196" upper="2.356196" velocity="10.4720"/>
  </joint>
  <joint name="right_joint6" type="revolute">
    <origin xyz="0 0.028 -0.16305"/>
    <parent link="right_link5"/>
    <child link="right_link6"/>
    <axis xyz="0 1 0"/>
    <limit effort="18" lower="-1.047198" upper="1.047198" velocity="10.4720"/>
  </joint>
  <joint name="right_joint7" type="revolute">
    <origin xyz="0.0295 -0.028 0"/>
    <parent link="right_link6"/>
    <child link="right_link7"/>
    <axis xyz="1 0 0"/>
    <limit effort="18" lower="-1.5708" upper="1.5708" velocity="10.4720"/>
  </joint>
  <link name="right_gripper_base">
    <inertial>
      <origin xyz="-0.0311072323899603 1.17979991887118E-08 7.93394685505433E-08"/>
      <mass value="0.604"/>
      <inertia ixx="0.000175881544189539" ixy="-6.06026450851008E-11" ixz="5.30643405624365E-10" iyy="9.86379407701341E-05" iyz="-8.18686692495892E-08" izz="0.000165121280580029"/>
    </inertial>
    <visual>
      <geometry>
        <mesh filename="package://galaxea_a1_description/meshes/gripper/gripper_link.obj"/>
      </geometry>
    </visual>
    <collision>
      <geometry>
        <mesh filename="package://galaxea_a1_description/meshes/gripper/gripper_link.obj"/>
      </geometry>
    </collision>
  </link>
  <link name="right_finger1">
    <inertial>
      <origin xyz="-0.0195895895552112 -0.0151136845490034 0.00542254359093075"/>
      <mass value="0.027"/>
      <inertia ixx="2.40569358477209E-06" ixy="3.9898459609048E-07" ixz="5.12152762183641E-08" iyy="5.71079298307516E-06" iyz="6.19467902008363E-08" izz="6.48482183930358E-06"/>
    </inertial>
    <visual>
      <geometry>
        <mesh filename="package://galaxea_a1_description/meshes/gripper/finger.obj"/>
      </geometry>
    </visual>
    <collision>
      <geometry>
        <mesh filename="package://galaxea_a1_description/meshes/gripper/finger.obj"/>
      </geometry>
    </collision>
  </link>
  <joint name="right_gripper_joint" type="prismatic">
    <origin xyz="0.03689 0.013453 0.00012059"/>
    <parent link="right_gripper_base"/>
    <child link="right_finger1"/>
    <axis xyz="0 1 0"/>
    <limit effort="100" lower="0" upper="0.05" velocity="0.25"/>
  </joint>
  <link name="right_finger2">
    <inertial>
      <origin xyz="-0.0195895857999098 0.0151136893508115 -0.00542254357246619"/>
      <mass value="0.027"/>
      <inertia ixx="2.40569340151687E-06" ixy="-3.98983784827124E-07" ixz="-5.12152683073981E-08" iyy="5.71079321589929E-06" iyz="6.19467953006536E-08" izz="6.48482187274222E-06"/>
    </inertial>
    <visual>
      <geometry>
        <mesh filename="package://galaxea_a1_description/meshes/gripper/finger.obj" scale="1 -1 -1"/>
      </geometry>
    </visual>
    <collision>
      <geometry>
        <mesh filename="package://galaxea_a1_description/meshes/gripper/finger.obj" scale="1 -1 -1"/>
      </geometry>
    </collision>
  </link>
  <joint name="right_gripper_joint2" type="prismatic">
    <origin xyz="0.03689 -0.013453 -0.00012059"/>
    <parent link="right_gripper_base"/>
    <child link="right_finger2"/>
    <axis xyz="0 -1 0"/>
    <limit effort="100" lower="0" upper="0.05" velocity="0.25"/>
    <mimic joint="right_gripper_joint" multiplier="1" offset="0"/>
  </joint>
  <link name="right_gripper_center"/>
  <joint name="right_gripper_center_joint" type="fixed">
    <origin xyz="0.03689 0 -0.00012059"/>
    <parent link="right_gripper_base"/>
    <child link="right_gripper_center"/>
  </joint>
  <joint name="right_gripper_base_joint" type="fixed">
    <origin rpy="0 1.5708 0" xyz="-0.0295 0 -0.16065"/>
    <parent link="right_link7"/>
    <child link="right_gripper_base"/>
  </joint>
  <!-- RealSense Camera Link -->
  <link name="left_realsense_link">
    <inertial>
      <origin xyz="0.022169 0.0060171 -0.017353"/>
      <mass value="0.175"/>
      <inertia ixx="6.965E-06" ixy="2.6612E-06" ixz="1.2797E-06" iyy="2.3281E-05" iyz="-1.4268E-06" izz="2.5513E-05"/>
    </inertial>
    <visual>
      <geometry>
        <mesh filename="package://galaxea_r1_description/meshes/camera_link.obj"/>
      </geometry>
    </visual>
    <collision>
      <geometry>
        <mesh filename="package://galaxea_r1_description/meshes/camera_link.obj"/>
      </geometry>
    </collision>
  </link>
  <!-- RealSense Joint: Arm 7 to Camera -->
  <joint name="left_realsense_joint" type="fixed">
    <origin rpy="2.70516 -0.0077831 -1.5708" xyz="0.02101 0.0028934 -0.1555183"/>
    <parent link="left_link7"/>
    <child link="left_realsense_link"/>
  </joint>
  <!-- RealSense Camera Link -->
  <link name="right_realsense_link">
    <inertial>
      <origin xyz="0.022169 0.0060171 -0.017353"/>
      <mass value="0.175"/>
      <inertia ixx="6.965E-06" ixy="2.6612E-06" ixz="1.2797E-06" iyy="2.3281E-05" iyz="-1.4268E-06" izz="2.5513E-05"/>
    </inertial>
    <visual>
      <geometry>
        <mesh filename="package://galaxea_r1_description/meshes/camera_link.obj"/>
      </geometry>
    </visual>
    <collision>
      <geometry>
        <mesh filename="package://galaxea_r1_description/meshes/camera_link.obj"/>
      </geometry>
    </collision>
  </link>
  <!-- RealSense Joint: Arm 7 to Camera -->
  <joint name="right_realsense_joint" type="fixed">
    <origin rpy="2.70516 -0.0077831 -1.5708" xyz="0.02101 0.0028934 -0.1555183"/>
    <parent link="right_link7"/>
    <child link="right_realsense_link"/>
  </joint>
</robot>
