<?xml version="1.0" encoding="utf-8"?>
<robot xmlns:xacro="http://www.ros.org/wiki/xacro">
  <xacro:macro name="Body">

    <link name="lift_link">
      <inertial>
        <origin xyz="-0.13956899916103924 0 0.07323798891482189"/>
        <mass value="17.38744536890084"/>
        <inertia ixx="0.187458" ixy="-0.000206" ixz="0.023942" iyy="0.178157" iyz="-0.000153" izz="0.29708"/>
      </inertial>
      <visual>
        <geometry>
          <mesh filename="file://$(find arx_lift_description)/meshes/lift.obj"/>
        </geometry>
      </visual>
      <collision>
        <geometry>
          <mesh filename="file://$(find arx_lift_description)/meshes/lift.obj"/>
        </geometry>
      </collision>
    </link>

    <joint name="joint_lift" type="prismatic">
      <origin xyz="0.022199 0 0.233"/>
      <parent link="base"/>
      <child link="lift_link"/>
      <axis xyz="0.0 0.0 1.0"/>
      <limit effort="1000" lower="0.0" upper="0.86" velocity="100"/>
    </joint>

    <link name="h_base_link">
      <inertial>
        <origin xyz="-0.0020743076738515215 -1.5307881645835308e-08 -0.024619861716967787"/>
        <mass value="0.9930933606993821"/>
        <inertia ixx="0.000391" ixy="-0.0" ixz="1.7e-05" iyy="0.000452" iyz="0.0" izz="0.000532"/>
      </inertial>
      <visual>
        <geometry>
          <mesh filename="file://$(find arx_lift_description)/meshes/h_base.obj"/>
        </geometry>
      </visual>
      <collision>
        <geometry>
          <mesh filename="file://$(find arx_lift_description)/meshes/h_base.obj"/>
        </geometry>
      </collision>
    </link>

    <link name="h_link1_1">
      <inertial>
        <origin xyz="-1.3121512495483172e-08 -0.0017956601536253606 -0.0404485568834118"/>
        <mass value="1.1585686692835446"/>
        <inertia ixx="0.000714" ixy="-0.0" ixz="0.0" iyy="0.000677" iyz="3.4e-05" izz="0.000524"/>
      </inertial>
      <visual>
        <geometry>
          <mesh filename="file://$(find arx_lift_description)/meshes/h_link1.obj"/>
        </geometry>
      </visual>
      <collision>
        <geometry>
          <mesh filename="file://$(find arx_lift_description)/meshes/h_link1.obj"/>
        </geometry>
      </collision>
    </link>

    <link name="h_link2_1">
      <inertial>
        <origin xyz="0.03081593597576142 -0.022504711493597663 -0.0659240377971316"/>
        <mass value="1.5752562353484625"/>
        <inertia ixx="0.004555" ixy="0.000214" ixz="0.000252" iyy="0.004541" iyz="-0.000299" izz="0.00636"/>
      </inertial>
      <visual>
        <geometry>
          <mesh filename="file://$(find arx_lift_description)/meshes/h_link2.obj"/>
        </geometry>
      </visual>
      <collision>
        <geometry>
          <mesh filename="file://$(find arx_lift_description)/meshes/h_link2.obj"/>
        </geometry>
      </collision>
    </link>

    <joint name="joint_h_1" type="continuous">
      <origin xyz="0.0 0.0 -0.046"/>
      <parent link="h_base_link"/>
      <child link="h_link1_1"/>
      <axis xyz="0.0 -0.0 1.0"/>
      <limit effort="100" lower="-1.570796" upper="1.570796" velocity="100"/>
    </joint>

    <joint name="joint_h_2" type="continuous">
      <origin xyz="0.0 0.025 -0.047"/>
      <parent link="h_link1_1"/>
      <child link="h_link2_1"/>
      <axis xyz="-0.0 -1.0 0.0"/>
      <limit effort="100" lower="-0.785398" upper="0.785398" velocity="100"/>
    </joint>

    <joint name="h_fixed" type="fixed">
      <parent link="lift_link"/>
      <child link="h_base_link"/>
      <origin rpy="0 3.1415926 0" xyz="-0.258786 0 0.220008"/>
    </joint>

  </xacro:macro>
</robot>