<?xml version="1.0" ?>
<!-- =================================================================================== -->
<!-- |    Astribot S1 Base Description                                                 | -->
<!-- |    This file includes the base chassis, torso and head                          | -->
<!-- =================================================================================== -->
<robot xmlns:xacro="http://www.ros.org/wiki/xacro">
	
	<!-- Base link (底盘基础连杆) -->
	<link name="base_link">
		<inertial>
			<origin xyz="-0.062784 0.007017 0.035375"/>
			<mass value="39.24781"/>
			<inertia ixx="1.071997" ixy="0.015889" ixz="-0.058447" iyy="1.218431" iyz="-0.002015" izz="1.489411"/>
		</inertial>
		<visual>
			<geometry>
				<mesh filename="file://$(find astribot_s1_description)/meshes/s1_torso/base.obj"/>
			</geometry>
		</visual>
		<collision>
			<origin xyz="0 0 -0.05"/>
			<geometry>
				<cylinder length="0.1" radius="0.3"/>
			</geometry>
		</collision>
	</link>

	<!-- 轮子定义 - 右前轮 -->
	<link name="wheel_RF_Link">
		<inertial>
			<origin xyz="2.7624E-07 -1.7583E-07 0.014539"/>
			<mass value="0.56418"/>
			<inertia ixx="0.00083188" ixy="3.5362E-09" ixz="-2.2361E-10" iyy="0.00083188" iyz="1.788E-10" izz="0.0015639"/>
		</inertial>
		<visual>
			<geometry>
				<mesh filename="file://$(find astribot_s1_description)/meshes/s1_torso/wheel.obj"/>
			</geometry>
			<material name="">
				<color rgba="0.75294 0.75294 0.75294 1"/>
			</material>
		</visual>
	</link>
	<joint name="wheel_RF_Joint" type="continuous">
		<origin rpy="2.35619 -1.5708 0" xyz="0.21634675 -0.21634675 -0.015"/>
		<parent link="base_link"/>
		<child link="wheel_RF_Link"/>
		<axis xyz="0 0 1"/>
	</joint>

	<!-- 轮子定义 - 左前轮 -->
	<link name="wheel_LF_Link">
		<inertial>
			<origin xyz="2.7617E-07 -1.7589E-07 0.014539"/>
			<mass value="0.56418"/>
			<inertia ixx="0.00083188" ixy="3.5366E-09" ixz="-2.2387E-10" iyy="0.00083188" iyz="1.782E-10" izz="0.0015639"/>
		</inertial>
		<visual>
			<geometry>
				<mesh filename="file://$(find astribot_s1_description)/meshes/s1_torso/wheel.obj"/>
			</geometry>
			<material name="">
				<color rgba="0.79216 0.81961 0.93333 1"/>
			</material>
		</visual>
	</link>
	<joint name="wheel_LF_Joint" type="continuous">
		<origin rpy="-2.35619 -1.5708 0" xyz="0.21634675 0.21634675 -0.015"/>
		<parent link="base_link"/>
		<child link="wheel_LF_Link"/>
		<axis xyz="0 0 1"/>
	</joint>

	<!-- 轮子定义 - 右后轮 -->
	<link name="wheel_RR_Link">
		<inertial>
			<origin xyz="-2.7619E-07 1.7583E-07 0.014539"/>
			<mass value="0.56418"/>
			<inertia ixx="0.00083188" ixy="3.5357E-09" ixz="2.2361E-10" iyy="0.00083188" iyz="-1.7877E-10" izz="0.0015639"/>
		</inertial>
		<visual>
			<geometry>
				<mesh filename="file://$(find astribot_s1_description)/meshes/s1_torso/wheel.obj"/>
			</geometry>
			<material name="">
				<color rgba="0.79216 0.81961 0.93333 1"/>
			</material>
		</visual>
	</link>
	<joint name="wheel_RR_Joint" type="continuous">
		<origin rpy="0.785398 -1.5708 0" xyz="-0.21634675 -0.21134675 -0.015"/>
		<parent link="base_link"/>
		<child link="wheel_RR_Link"/>
		<axis xyz="0 0 1"/>
	</joint>

	<!-- 轮子定义 - 左后轮 -->
	<link name="wheel_LR_Link">
		<inertial>
			<origin xyz="0.0019998 -0.0070713 0.014539"/>
			<mass value="0.56418"/>
			<inertia ixx="0.00083188" ixy="-3.5327E-09" ixz="1.7812E-10" iyy="0.00083188" iyz="2.2432E-10" izz="0.0015639"/>
		</inertial>
		<visual>
			<geometry>
				<mesh filename="file://$(find astribot_s1_description)/meshes/s1_torso/wheel.obj"/>
			</geometry>
			<material name="">
				<color rgba="0.79216 0.81961 0.93333 1"/>
			</material>
		</visual>
	</link>
	<joint name="wheel_LR_Joint" type="continuous">
		<origin rpy="-0.785398 -1.5708 0" xyz="-0.21634675 0.21134675 -0.015"/>
		<parent link="base_link"/>
		<child link="wheel_LR_Link"/>
		<axis xyz="0 0 1"/>
	</joint>

	<!-- 躯干连杆1 -->
	<link name="torso_link_1">
		<inertial>
			<origin xyz="-0.15249 0.00021066 -0.0033476"/>
			<mass value="7.3766"/>
			<inertia ixx="0.028834" ixy="-0.0052759" ixz="0.00010767" iyy="0.1483" iyz="1.1652E-05" izz="0.14268"/>
		</inertial>
		<visual>
			<geometry>
				<mesh filename="file://$(find astribot_s1_description)/meshes/s1_torso/link1.obj"/>
			</geometry>
			<material name="">
				<color rgba="0.89804 0.91765 0.92941 1"/>
			</material>
		</visual>
		<collision>
			<origin rpy="0 1.57 0" xyz="-0.15 0 0"/>
			<geometry>
				<cylinder length="0.3" radius="0.1"/>
			</geometry>
		</collision>
	</link>
	<joint name="torso_joint_1" type="revolute">
		<origin rpy="-1.5708 1.5708 0" xyz="0 0 0.12"/>
		<parent link="base_link"/>
		<child link="torso_link_1"/>
		<axis xyz="0 0 1"/>
		<limit effort="500" lower="-0.04" upper="1.3" velocity="1.8"/>
	</joint>

	<!-- 躯干连杆2 -->
	<link name="torso_link_2">
		<inertial>
			<origin xyz="-0.22214 0.028873 0.00059024"/>
			<mass value="5.6183"/>
			<inertia ixx="0.0082545" ixy="0.0011523" ixz="0.00035614" iyy="0.012677" iyz="-5.8287E-05" izz="0.017512"/>
		</inertial>
		<visual>
			<geometry>
				<mesh filename="file://$(find astribot_s1_description)/meshes/s1_torso/link2.obj"/>
			</geometry>
			<material name="">
				<color rgba="0.89804 0.91765 0.92941 1"/>
			</material>
		</visual>
		<collision>
			<origin rpy="0 1.57 -0.25" xyz="-0.15 0.03 0"/>
			<geometry>
				<cylinder length="0.3" radius="0.1"/>
			</geometry>
		</collision>
	</link>
	<joint name="torso_joint_2" type="revolute">
		<origin xyz="-0.38 0 0"/>
		<parent link="torso_link_1"/>
		<child link="torso_link_2"/>
		<axis xyz="0 0 1"/>
		<limit effort="500" lower="-2.3" upper="0.06" velocity="1.8"/>
	</joint>

	<!-- 躯干连杆3 -->
	<link name="torso_link_3">
		<inertial>
			<origin xyz="-0.017519 0.00059523 0.00025821"/>
			<mass value="0.49013"/>
			<inertia ixx="0.00022212" ixy="-2.6767E-07" ixz="4.3987E-07" iyy="0.00036522" iyz="3.8834E-07" izz="0.00038039"/>
		</inertial>
		<visual>
			<geometry>
				<mesh filename="file://$(find astribot_s1_description)/meshes/s1_torso/link3.obj"/>
			</geometry>
		</visual>
		<collision>
			<origin rpy="0 1.57 0" xyz="-0.18 0.01 0"/>
			<geometry>
				<cylinder length="0.35" radius="0.09"/>
			</geometry>
		</collision>
	</link>
	<joint name="torso_joint_3" type="revolute">
		<origin xyz="-0.390 0 0"/>
		<parent link="torso_link_2"/>
		<child link="torso_link_3"/>
		<axis xyz="0 0 1"/>
		<limit effort="500" lower="-0.4" upper="2.3" velocity="1.8"/>
	</joint>

	<!-- 躯干连杆4 -->
	<link name="torso_link_4">
		<inertial>
			<origin xyz="0.00476227191516749 -4.56966810241128E-05 0.242912573510671"/>
			<mass value="3.55695635704638"/>
			<inertia ixx="0.0165768322563514" ixy="-9.94098112646385E-06" ixz="-0.000100011483384926" iyy="0.014904355097835"
							 iyz="9.86752047032885E-07" izz="0.0110629318711333"/>
		</inertial>
		<visual>
			<geometry>
				<mesh filename="file://$(find astribot_s1_description)/meshes/s1_torso/link4.obj"/>
			</geometry>
		</visual>
	</link>
	<joint name="torso_joint_4" type="revolute">
		<origin rpy="1.5708 0 -1.5708" xyz="0 0 0"/>
		<parent link="torso_link_3"/>
		<child link="torso_link_4"/>
		<axis xyz="0 0 1"/>
		<limit effort="500" lower="-1.2" upper="1.2" velocity="1.8"/>
	</joint>

	<!-- 躯干末端执行器 -->
	<link name="torso_end_effector">
		<inertial>
			<mass value="0"/>
			<inertia ixx="0" ixy="0" ixz="0" iyy="0" iyz="0" izz="0"/>
		</inertial>
	</link>
	<joint name="torso_end_effector_fixed_joint" type="fixed">
		<origin rpy="0.0 0.0 0.0" xyz="0 0 0.34475"/>
		<parent link="torso_link_4"/>
		<child link="torso_end_effector"/>
	</joint>

	<!-- 头部基座连杆 -->
	<link name="head_base_link">
		<inertial>
			<origin xyz="-0.02816247 -0.00023176 -0.05211965"/>
			<mass value="0.39541440"/>
			<inertia ixx="0.00036025" ixy="-0.00003505" ixz="0.00004865" iyy="0.00049377" iyz="0.00000243" izz="0.00074441"/>
		</inertial>
		<visual>
			<geometry>
				<mesh filename="file://$(find astribot_s1_description)/meshes/s1_head/base.obj"/>
			</geometry>
		</visual>
	</link>
	<joint name="head_fixed_joint" type="fixed">
		<parent link="torso_end_effector"/>
		<child link="head_base_link"/>
		<origin xyz="0 0 0.1229"/>
	</joint>

	<!-- 头部连杆1 -->
	<link name="head_link_1">
		<inertial>
			<origin xyz="0.00003191 -0.00038566 -0.02579910"/>
			<mass value="0.13910581"/>
			<inertia ixx="0.00004567" ixy="0.00000003" ixz="0.00000004" iyy="0.00004789" iyz="-0.00000091" izz="0.00003779"/>
		</inertial>
		<visual>
			<geometry>
				<mesh filename="file://$(find astribot_s1_description)/meshes/s1_head/link1.obj"/>
			</geometry>
		</visual>
	</link>
	<joint name="head_joint_1" type="revolute">
		<parent link="head_base_link"/>
		<child link="head_link_1"/>
		<axis xyz="0 0 1"/>
		<limit effort="100" lower="-1.57" upper="1.57" velocity="4.0"/>
	</joint>

	<!-- 头部连杆2 -->
	<link name="head_link_2">
		<inertial>
			<origin xyz="0.00705824 -0.14472601 -0.00061724"/>
			<mass value="0.97012447"/>
			<inertia ixx="0.00555660" ixy="-0.00041600" ixz="-0.00000036" iyy="0.00151908" iyz="-0.00012043"
							 izz="0.00544493"/>
		</inertial>
		<visual>
			<geometry>
				<mesh filename="file://$(find astribot_s1_description)/meshes/s1_head/link2.obj"/>
			</geometry>
		</visual>
		<collision>
			<origin xyz="0 -0.15 0"/>
			<geometry>
				<sphere radius="0.11"/>
			</geometry>
		</collision>
	</link>
	<joint name="head_joint_2" type="revolute">
		<origin rpy="-1.5708 0 0" xyz="0 0 0"/>
		<parent link="head_link_1"/>
		<child link="head_link_2"/>
		<axis xyz="0 0 1"/>
		<limit effort="100" lower="-1.22" upper="1.22" velocity="4.0"/>
	</joint>

</robot>

