<?xml version="1.0" ?>
<!-- =================================================================================== -->
<!-- |    This document was autogenerated by xacro from robot.xacro                    | -->
<!-- |    EDITING THIS FILE BY HAND IS NOT RECOMMENDED                                 | -->
<!-- =================================================================================== -->
<robot name="SO-Arm">
  <!-- Materials -->
  <material name="3d_printed">
    <color rgba="0.4 0.8196 0.945 1.0"/>
  </material>
  <material name="sts3215">
    <color rgba="0.1 0.1 0.1 1.0"/>
  </material>
  <joint name="base_joint" type="fixed">
    <origin xyz="0 0 0.0025"/>
    <parent link="base_link"/>
    <child link="base"/>
  </joint>
  <link name="base_link"/>
  <link name="base">
    <inertial>
      <origin xyz="-0.01371 0 0.03348"/>
      <mass value="0.147"/>
      <inertia ixx="0.000136117" ixy="4.59787e-07" ixz="9.75275e-08" iyy="0.000114686" iyz="-4.97151e-06" izz="0.000130364"/>
    </inertial>
    <visual>
      <geometry>
        <mesh filename="package://so_arm_description/meshes/so101/base_motor_holder.stl"/>
      </geometry>
      <material name="3d_printed"/>
    </visual>
    <collision>
      <geometry>
        <mesh filename="package://so_arm_description/meshes/so101/base_motor_holder.stl"/>
      </geometry>
    </collision>
    <visual>
      <geometry>
        <mesh filename="package://so_arm_description/meshes/so101/base.stl"/>
      </geometry>
      <material name="3d_printed"/>
    </visual>
    <collision>
      <geometry>
        <mesh filename="package://so_arm_description/meshes/so101/base.stl"/>
      </geometry>
    </collision>
    <visual>
      <geometry>
        <mesh filename="package://so_arm_description/meshes/so101/base_waveshare_mounting_plate.stl"/>
      </geometry>
      <material name="3d_printed"/>
    </visual>
    <collision>
      <geometry>
        <mesh filename="package://so_arm_description/meshes/so101/base_waveshare_mounting_plate.stl"/>
      </geometry>
    </collision>
  </link>
  <link name="motor1">
    <visual>
      <geometry>
        <mesh filename="package://so_arm_description/meshes/so101/sts3215_03a_v1.stl"/>
      </geometry>
      <material name="sts3215"/>
    </visual>
  </link>
  <joint name="motor1_joint" type="fixed">
    <origin xyz="0.0263345 0 0.0437"/>
    <parent link="base"/>
    <child link="motor1"/>
  </joint>
  <!-- Link shoulder -->
  <link name="shoulder">
    <inertial>
      <origin xyz="-0.0307604 -1.66727e-05 -0.0252713"/>
      <mass value="0.100006"/>
      <inertia ixx="8.3759e-05" ixy="7.55525e-08" ixz="-1.16342e-06" iyy="8.10403e-05" iyz="1.54663e-07" izz="2.39783e-05"/>
    </inertial>
    <!-- Part motor_holder_base_v1 -->
    <visual>
      <geometry>
        <mesh filename="package://so_arm_description/meshes/so101/motor_holder_base.stl"/>
      </geometry>
      <material name="3d_printed"/>
    </visual>
    <collision>
      <geometry>
        <mesh filename="package://so_arm_description/meshes/so101/motor_holder_base.stl"/>
      </geometry>
    </collision>
    <!-- Part rotation_pitch_so101_v1 -->
    <visual>
      <geometry>
        <mesh filename="package://so_arm_description/meshes/so101/rotation_pitch.stl"/>
      </geometry>
      <material name="3d_printed"/>
    </visual>
    <collision>
      <geometry>
        <mesh filename="package://so_arm_description/meshes/so101/rotation_pitch.stl"/>
      </geometry>
    </collision>
  </link>
  <link name="motor2">
    <visual>
      <geometry>
        <mesh filename="package://so_arm_description/meshes/so101/sts3215_03a_v1.stl"/>
      </geometry>
      <material name="sts3215"/>
    </visual>
  </link>
  <joint name="motor2_joint" type="fixed">
    <origin rpy="1.5708 1.5708 0" xyz="-0.0303992 0.000422241 -0.0417"/>
    <parent link="shoulder"/>
    <child link="motor2"/>
  </joint>
  <!-- Joint from base to shoulder -->
  <joint name="shoulder_pan" type="revolute">
    <origin rpy="-3.14159 0 3.14159" xyz="0.0388353 0 0.0624"/>
    <parent link="base"/>
    <child link="shoulder"/>
    <axis xyz="0 0 1"/>
    <limit effort="10" lower="-1.91986" upper="1.91986" velocity="10"/>
  </joint>
  <!-- Link upper_arm -->
  <link name="upper_arm">
    <inertial>
      <origin xyz="-0.0898471 -0.00838224 0.0184089"/>
      <mass value="0.103"/>
      <inertia ixx="4.08002e-05" ixy="-1.97819e-05" ixz="-4.03016e-08" iyy="0.000147318" iyz="8.97326e-09" izz="0.000142487"/>
    </inertial>
    <visual>
      <geometry>
        <mesh filename="package://so_arm_description/meshes/so101/upper_arm.stl"/>
      </geometry>
      <material name="3d_printed"/>
    </visual>
    <collision>
      <geometry>
        <mesh filename="package://so_arm_description/meshes/so101/upper_arm.stl"/>
      </geometry>
    </collision>
  </link>
  <link name="motor3">
    <visual>
      <geometry>
        <mesh filename="package://so_arm_description/meshes/so101/sts3215_03a_v1.stl"/>
      </geometry>
      <material name="sts3215"/>
    </visual>
  </link>
  <joint name="motor3_joint" type="fixed">
    <origin rpy="-3.14159 -6.8695e-16 -1.5708" xyz="-0.11257 -0.0155 0.0187"/>
    <parent link="upper_arm"/>
    <child link="motor3"/>
  </joint>
  <!-- Joint from shoulder to upper_arm -->
  <joint name="shoulder_lift" type="revolute">
    <origin rpy="-1.5708 -1.5708 0" xyz="-0.0303992 -0.0182778 -0.0542"/>
    <parent link="shoulder"/>
    <child link="upper_arm"/>
    <axis xyz="0 0 1"/>
    <limit effort="10" lower="-1.74533" upper="1.74533" velocity="10"/>
  </joint>
  <!-- Link lower_arm -->
  <link name="lower_arm">
    <inertial>
      <origin xyz="-0.0980701 0.00324376 0.0182831"/>
      <mass value="0.104"/>
      <inertia ixx="2.87438e-05" ixy="7.41152e-06" ixz="1.26409e-06" iyy="0.000159844" iyz="-4.90188e-08" izz="0.00014529"/>
    </inertial>
    <!-- Part under_arm_so101_v1 -->
    <visual>
      <geometry>
        <mesh filename="package://so_arm_description/meshes/so101/under_arm.stl"/>
      </geometry>
      <material name="3d_printed"/>
    </visual>
    <collision>
      <geometry>
        <mesh filename="package://so_arm_description/meshes/so101/under_arm.stl"/>
      </geometry>
    </collision>
    <!-- Part motor_holder_wrist_v1 -->
    <visual>
      <geometry>
        <mesh filename="package://so_arm_description/meshes/so101/motor_holder_wrist.stl"/>
      </geometry>
      <material name="3d_printed"/>
    </visual>
    <collision>
      <geometry>
        <mesh filename="package://so_arm_description/meshes/so101/motor_holder_wrist.stl"/>
      </geometry>
    </collision>
  </link>
  <link name="motor4">
    <visual>
      <geometry>
        <mesh filename="package://so_arm_description/meshes/so101/sts3215_03a_v1.stl"/>
      </geometry>
      <material name="sts3215"/>
    </visual>
  </link>
  <joint name="motor4_joint" type="fixed">
    <origin rpy="-3.14159 -3.58047e-15 -3.14159" xyz="-0.1224 0.0052 0.0187"/>
    <parent link="lower_arm"/>
    <child link="motor4"/>
  </joint>
  <!-- Joint from upper_arm to lower_arm -->
  <!-- Note: 5-degree calibration offset applied to joint limits -->
  <joint name="elbow_flex" type="revolute">
    <origin rpy="-1.22818e-15 5.75928e-16 1.5708" xyz="-0.11257 -0.028 2.46331e-16"/>
    <parent link="upper_arm"/>
    <child link="lower_arm"/>
    <axis xyz="0 0 1"/>
    <limit effort="10" lower="-1.69" upper="1.69" velocity="10"/>
  </joint>
  <!-- Link wrist -->
  <link name="wrist">
    <inertial>
      <origin xyz="-0.000103312 -0.0386143 0.0281156"/>
      <mass value="0.079"/>
      <inertia ixx="3.68263e-05" ixy="1.7893e-08" ixz="-5.28128e-08" iyy="2.5391e-05" iyz="3.6412e-06" izz="2.1e-05"/>
    </inertial>
    <!-- Part wrist_roll_pitch_so101_v2 -->
    <visual>
      <geometry>
        <mesh filename="package://so_arm_description/meshes/so101/wrist_roll_pitch.stl"/>
      </geometry>
      <material name="3d_printed"/>
    </visual>
    <collision>
      <geometry>
        <mesh filename="package://so_arm_description/meshes/so101/wrist_roll_pitch.stl"/>
      </geometry>
    </collision>
  </link>
  <link name="motor5">
    <visual>
      <geometry>
        <mesh filename="package://so_arm_description/meshes/so101/sts3215_03a_v1.stl"/>
      </geometry>
      <material name="sts3215"/>
    </visual>
  </link>
  <joint name="motor5_joint" type="fixed">
    <origin rpy="1.5708 1.5708 0" xyz="5.55112e-17 -0.0424 0.0306"/>
    <parent link="wrist"/>
    <child link="motor5"/>
  </joint>
  <!-- Joint from lower_arm to wrist -->
  <joint name="wrist_flex" type="revolute">
    <origin rpy="3.2474e-15 2.86219e-15 -1.5708" xyz="-0.1349 0.0052 1.65232e-16"/>
    <parent link="lower_arm"/>
    <child link="wrist"/>
    <axis xyz="0 0 1"/>
    <limit effort="10" lower="-1.65806" upper="1.65806" velocity="10"/>
  </joint>
  <!-- Link gripper -->
  <link name="gripper">
    <inertial>
      <origin xyz="0.000213627 0.000245138 -0.025187"/>
      <mass value="0.087"/>
      <inertia ixx="2.75087e-05" ixy="-3.35241e-07" ixz="-5.7352e-06" iyy="4.33657e-05" iyz="-5.17847e-08" izz="3.45059e-05"/>
    </inertial>
    <!-- Part wrist_roll_follower_so101_v1 -->
    <visual>
      <geometry>
        <mesh filename="package://so_arm_description/meshes/so101/wrist_roll_follower/wrist_roll_follower.stl"/>
      </geometry>
      <material name="3d_printed"/>
    </visual>
    <collision>
      <geometry>
        <mesh filename="package://so_arm_description/meshes/so101/wrist_roll_follower/wrist_roll_follower_collision_0.obj"/>
      </geometry>
    </collision>
    <collision>
      <geometry>
        <mesh filename="package://so_arm_description/meshes/so101/wrist_roll_follower/wrist_roll_follower_collision_1.obj"/>
      </geometry>
    </collision>
    <collision>
      <geometry>
        <mesh filename="package://so_arm_description/meshes/so101/wrist_roll_follower/wrist_roll_follower_collision_2.obj"/>
      </geometry>
    </collision>
  </link>
  <link name="motor6">
    <visual>
      <geometry>
        <mesh filename="package://so_arm_description/meshes/so101/sts3215_03a_v1.stl"/>
      </geometry>
      <material name="sts3215"/>
    </visual>
  </link>
  <joint name="motor6_joint" type="fixed">
    <origin rpy="-1.5708 -5.55112e-17 -1.38213e-14" xyz="0.0077 0.0001 -0.0234"/>
    <parent link="gripper"/>
    <child link="motor6"/>
  </joint>
  <link name="camera_support">
    <visual>
      <geometry>
        <mesh filename="package://so_arm_description/meshes/so101/camera_support.stl"/>
      </geometry>
      <material name="3d_printed"/>
    </visual>
    <collision>
      <geometry>
        <mesh filename="package://so_arm_description/meshes/so101/camera_support.stl"/>
      </geometry>
    </collision>
  </link>
  <joint name="camera_support_joint" type="fixed">
    <origin rpy="-1.5708 1.5708 0" xyz="-0.001 0.025 -0.023"/>
    <parent link="gripper"/>
    <child link="camera_support"/>
  </joint>
  <link name="camera">
    <visual>
      <geometry>
        <mesh filename="package://so_arm_description/meshes/so101/camera.obj"/>
      </geometry>
    </visual>
    <collision>
      <geometry>
        <mesh filename="package://so_arm_description/meshes/so101/camera.obj"/>
      </geometry>
    </collision>
  </link>
  <joint name="camera_joint" type="fixed">
    <origin rpy="0 0.611 0" xyz="0.024 0 0.0375"/>
    <parent link="camera_support"/>
    <child link="camera"/>
  </joint>
  <link name="camera_len"/>
  <joint name="camera_len_joint" type="fixed">
    <origin xyz="0.02 0 0"/>
    <parent link="camera"/>
    <child link="camera_len"/>
  </joint>
  <!-- Joint from wrist to gripper -->
  <joint name="wrist_roll" type="revolute">
    <origin rpy="1.5708 -9.38083e-08 3.14159" xyz="0 -0.0611 0.0181"/>
    <parent link="wrist"/>
    <child link="gripper"/>
    <axis xyz="0 0 1"/>
    <limit effort="10" lower="-2.74385" upper="2.84121" velocity="10"/>
  </joint>
  <link name="moving_jaw">
    <inertial>
      <origin xyz="-0.00157495 -0.0300244 0.0192755"/>
      <mass value="0.012"/>
      <inertia ixx="6.61427e-06" ixy="-3.19807e-07" ixz="-5.90717e-09" iyy="1.89032e-06" iyz="-1.09945e-07" izz="5.28738e-06"/>
    </inertial>
    <visual>
      <geometry>
        <mesh filename="package://so_arm_description/meshes/so101/moving_jaw/moving_jaw.stl"/>
      </geometry>
      <material name="3d_printed"/>
    </visual>
    <collision>
      <geometry>
        <mesh filename="package://so_arm_description/meshes/so101/moving_jaw/moving_jaw_collision_0.obj"/>
      </geometry>
    </collision>
    <collision>
      <geometry>
        <mesh filename="package://so_arm_description/meshes/so101/moving_jaw/moving_jaw_collision_1.obj"/>
      </geometry>
    </collision>
    <collision>
      <geometry>
        <mesh filename="package://so_arm_description/meshes/so101/moving_jaw/moving_jaw_collision_2.obj"/>
      </geometry>
    </collision>
  </link>
  <joint name="gripper" type="revolute">
    <origin rpy="1.5708 -5.14108e-17 -1.38655e-14" xyz="0.0202 0.0188 -0.0234"/>
    <parent link="gripper"/>
    <child link="moving_jaw"/>
    <axis xyz="0 0 1"/>
    <limit effort="10" lower="-0.174533" upper="1.74533" velocity="10"/>
  </joint>
  <!-- Frame gripperframe (dummy link + fixed joint) -->
  <link name="fixed_jaw_tip"/>
  <joint name="fixed_jaw_tip_joint" type="fixed">
    <origin rpy="0 1.5708 0" xyz="-0.0079 -0.000218121 -0.0981274"/>
    <parent link="gripper"/>
    <child link="fixed_jaw_tip"/>
  </joint>
  <joint name="moving_Jaw_tip_joint" type="fixed">
    <origin xyz="-0.01 -0.0745 0.019"/>
    <parent link="moving_jaw"/>
    <child link="moving_jaw_tip"/>
  </joint>
  <link name="moving_jaw_tip"/>
</robot>
