<?xml version="1.0" ?>
<!-- =================================================================================== -->
<!-- |    This document was autogenerated by xacro from robot.xacro                    | -->
<!-- |    EDITING THIS FILE BY HAND IS NOT RECOMMENDED                                 | -->
<!-- =================================================================================== -->
<robot name="DobotCR5">
  <!-- Arm Base Link -->
  <link name="base_link">
    <inertial>
      <mass value="2.4"/>
      <inertia ixx="0.00397965" ixy="0.00000303" ixz="0.00000035" iyy="0.00315361" iyz="0.00002442" izz="0.00357979"/>
      <origin xyz="2.6805e-05 0.0011749210000000002 0.171179958"/>
    </inertial>
    <visual>
      <geometry>
        <mesh filename="package://rokae_ar5_description/meshes/base.obj" scale="1 1 1"/>
      </geometry>
    </visual>
    <collision>
      <geometry>
        <mesh filename="package://rokae_ar5_description/meshes/base.obj" scale="1 1 1"/>
      </geometry>
    </collision>
  </link>
  <!-- Joint 1 -->
  <joint name="joint1" type="revolute">
    <parent link="base_link"/>
    <child link="link1"/>
    <limit effort="108" lower="-3.1414" upper="3.1414" velocity="3.9269908169872414"/>
    <axis xyz="0 0 1"/>
    <origin rpy="0 0 1.5708" xyz="0.0 0.0 0.1745"/>
  </joint>
  <!-- Arm Link 1 -->
  <link name="link1">
    <inertial>
      <mass value="2.4"/>
      <inertia ixx="0.00397965" ixy="0.00000303" ixz="0.00000035" iyy="0.00315361" iyz="0.00002442" izz="0.00357979"/>
      <origin xyz="2.6805e-05 0.0011749210000000002 0.171179958"/>
    </inertial>
    <visual>
      <geometry>
        <mesh filename="package://rokae_ar5_description/meshes/link1.obj" scale="1 1 1"/>
      </geometry>
    </visual>
    <collision>
      <geometry>
        <mesh filename="package://rokae_ar5_description/meshes/link1.obj" scale="1 1 1"/>
      </geometry>
    </collision>
  </link>
  <!-- Joint 2 -->
  <joint name="joint2" type="revolute">
    <parent link="link1"/>
    <child link="link2"/>
    <limit effort="108" lower="-2.1293" upper="2.1293" velocity="3.9269908169872414"/>
    <axis xyz="0 -1 0"/>
  </joint>
  <!-- Arm Link 2 -->
  <link name="link2">
    <inertial>
      <mass value="2.26"/>
      <inertia ixx="0.00998456" ixy="0.00000011" ixz="-0.00000049" iyy="0.00864243" iyz="0.00070944" izz="0.00397909"/>
      <origin xyz="1.0382e-05 -0.003330598 0.100666568"/>
    </inertial>
    <visual>
      <geometry>
        <mesh filename="package://rokae_ar5_description/meshes/link2.obj" scale="1 1 1"/>
      </geometry>
    </visual>
    <collision>
      <geometry>
        <mesh filename="package://rokae_ar5_description/meshes/link2.obj" scale="1 1 1"/>
      </geometry>
    </collision>
  </link>
  <!-- Joint 3 -->
  <joint name="joint3" type="revolute">
    <parent link="link2"/>
    <child link="link3"/>
    <limit effort="66" lower="-3.1416" upper="3.1416" velocity="5.235987755982989"/>
    <axis xyz="0 0 1"/>
    <origin rpy="0 0 3.1415926535" xyz="0.0 0.0 0.305"/>
  </joint>
  <!-- Arm Link 3 -->
  <link name="link3">
    <inertial>
      <mass value="1.85"/>
      <inertia ixx="0.00514901" ixy="0.00000705" ixz="0.00033523" iyy="0.00455840" iyz="0.00005313" izz="0.00249866"/>
      <origin xyz="-0.007574792 0.001848523 -0.017501298"/>
    </inertial>
    <visual>
      <geometry>
        <mesh filename="package://rokae_ar5_description/meshes/link3.obj" scale="1 1 1"/>
      </geometry>
    </visual>
    <collision>
      <geometry>
        <mesh filename="package://rokae_ar5_description/meshes/link3.obj" scale="1 1 1"/>
      </geometry>
    </collision>
  </link>
  <!-- Joint 4 -->
  <joint name="joint4" type="revolute">
    <parent link="link3"/>
    <child link="link4"/>
    <limit effort="66" lower="-1.3963" upper="2.5307" velocity="5.235987755982989"/>
    <axis xyz="0 1 0"/>
    <origin xyz="0.01 0.0 0.0"/>
  </joint>
  <!-- Arm Link 4 -->
  <link name="link4">
    <inertial>
      <mass value="1.19"/>
      <inertia ixx="0.00358515" ixy="-0.00005009" ixz="-0.00016645" iyy="0.00288820" iyz="0.00041392" izz="0.00173347"/>
      <origin xyz="0.007943048 -0.005043471 0.070013368"/>
    </inertial>
    <visual>
      <geometry>
        <mesh filename="package://rokae_ar5_description/meshes/link4.obj" scale="1 1 1"/>
      </geometry>
    </visual>
    <collision>
      <geometry>
        <mesh filename="package://rokae_ar5_description/meshes/link4.obj" scale="1 1 1"/>
      </geometry>
    </collision>
  </link>
  <!-- Joint 5 -->
  <joint name="joint5" type="revolute">
    <parent link="link4"/>
    <child link="link5"/>
    <limit effort="19" lower="-3.1416" upper="3.1416" velocity="4.1887902047863905"/>
    <axis xyz="0 0 1"/>
    <origin xyz="-0.01 0.0 0.179"/>
  </joint>
  <!-- Arm Link 5 -->
  <link name="link5">
    <inertial>
      <mass value="0.95"/>
      <inertia ixx="0.00094370" ixy="0.00000057" ixz="0.00000060" iyy="0.00071483" iyz="0.00000919" izz="0.00086730"/>
      <origin xyz="1.2128e-05 0.001731178 -0.0026525620000000002"/>
    </inertial>
    <visual>
      <geometry>
        <mesh filename="package://rokae_ar5_description/meshes/link5.obj" scale="1 1 1"/>
      </geometry>
    </visual>
    <collision>
      <geometry>
        <mesh filename="package://rokae_ar5_description/meshes/link5.obj" scale="1 1 1"/>
      </geometry>
    </collision>
  </link>
  <!-- Joint 6 -->
  <joint name="joint6" type="revolute">
    <parent link="link5"/>
    <child link="link6"/>
    <limit effort="19" lower="-1.9722" upper="1.9722" velocity="4.1887902047863905"/>
    <axis xyz="0 1 0"/>
  </joint>
  <!-- Arm Link 6 -->
  <link name="link6">
    <inertial>
      <mass value="1.06"/>
      <inertia ixx="0.00230759" ixy="-0.00000067" ixz="0.00000072" iyy="0.00195677" iyz="0.00018711" izz="0.00103394"/>
      <origin xyz="-5.3371e-05 -0.0023381310000000002 0.07615395800000001"/>
    </inertial>
    <visual>
      <geometry>
        <mesh filename="package://rokae_ar5_description/meshes/link6.obj" scale="1 1 1"/>
      </geometry>
    </visual>
    <collision>
      <geometry>
        <mesh filename="package://rokae_ar5_description/meshes/link6.obj" scale="1 1 1"/>
      </geometry>
    </collision>
  </link>
  <!-- Joint 7 -->
  <joint name="joint7" type="revolute">
    <parent link="link6"/>
    <child link="link7"/>
    <limit effort="19" lower="-3.1416" upper="3.1416" velocity="4.1887902047863905"/>
    <axis xyz="0 0 1"/>
    <origin xyz="0.0 0.0 0.166"/>
  </joint>
  <!-- Arm Link 7 -->
  <link name="link7">
    <inertial>
      <mass value="0.18"/>
      <inertia ixx="0.00009976" ixy="0.00000139" ixz="0.00000025" iyy="0.00009671" iyz="0.00000036" izz="0.00014828"/>
      <origin xyz="-0.000158025 3.6244e-05 -0.017928215"/>
    </inertial>
    <visual>
      <geometry>
        <mesh filename="package://rokae_ar5_description/meshes/link7.obj" scale="1 1 1"/>
      </geometry>
    </visual>
    <collision>
      <geometry>
        <mesh filename="package://rokae_ar5_description/meshes/link7.obj" scale="1 1 1"/>
      </geometry>
    </collision>
  </link>
</robot>
