<?xml version="1.0" ?>
<!-- =================================================================================== -->
<!-- |    This document was autogenerated by xacro from robot.xacro                    | -->
<!-- |    EDITING THIS FILE BY HAND IS NOT RECOMMENDED                                 | -->
<!-- =================================================================================== -->
<robot name="R1">
  <!-- Base Link -->
  <link name="base_link">
    <inertial>
      <origin xyz="-0.0024126 -8.9626E-05 0.13736"/>
      <mass value="47.63"/>
      <inertia ixx="1.578" ixy="-1.2021E-05" ixz="0.053642" iyy="1.462" iyz="7.297E-06" izz="2.8318"/>
    </inertial>
    <visual>
      <geometry>
        <mesh filename="package://galaxea_r1_description/meshes/base_link.obj"/>
      </geometry>
    </visual>
    <collision>
      <geometry>
        <mesh filename="package://galaxea_r1_description/meshes/base_link.obj"/>
      </geometry>
    </collision>
  </link>
  <!-- Steer Motor Link 1 -->
  <link name="steer_motor_link1">
    <inertial>
      <origin xyz="0.00098921 -0.034312 -0.034597"/>
      <mass value="1.2"/>
      <inertia ixx="8.8522E-05" ixy="-3.7755E-06" ixz="4.5456E-09" iyy="7.5352E-05" iyz="-7.0316E-07" izz="0.00010165"/>
    </inertial>
    <visual>
      <geometry>
        <mesh filename="package://galaxea_r1_description/meshes/steer_motor.obj"/>
      </geometry>
    </visual>
    <collision>
      <geometry>
        <mesh filename="package://galaxea_r1_description/meshes/steer_motor.obj"/>
      </geometry>
    </collision>
  </link>
  <!-- Steer Motor Joint 1: Base to Steer Motor 1 -->
  <joint name="steer_motor_joint1" type="revolute">
    <origin xyz="0.21516 0.28 0.12375"/>
    <parent link="base_link"/>
    <child link="steer_motor_link1"/>
    <axis xyz="0 0 1"/>
    <limit effort="44" lower="-1.5707963267948966" upper="1.5707963267948966" velocity="3.141592653589793"/>
  </joint>
  <!-- Wheel Motor Link 1 -->
  <link name="wheel_motor_link1">
    <inertial>
      <origin xyz="-2.6184E-06 0.0015607 1.6575E-07"/>
      <mass value="5"/>
      <inertia ixx="0.00089952" ixy="6.916E-08" ixz="7.5501E-10" iyy="0.0015854" iyz="7.6011E-12" izz="0.00089958"/>
    </inertial>
    <visual>
      <geometry>
        <mesh filename="package://galaxea_r1_description/meshes/wheel_motor.obj"/>
      </geometry>
    </visual>
    <collision>
      <geometry>
        <mesh filename="package://galaxea_r1_description/meshes/wheel_motor.obj"/>
      </geometry>
    </collision>
  </link>
  <!-- Wheel Motor Joint 1: Steer Motor 1 to Wheel Motor 1 -->
  <joint name="wheel_motor_joint1" type="continuous">
    <origin rpy="0 0 3.141592653589793" xyz="0 0 -0.09525"/>
    <parent link="steer_motor_link1"/>
    <child link="wheel_motor_link1"/>
    <axis xyz="0 1 0"/>
  </joint>
  <!-- Steer Motor Link 2 -->
  <link name="steer_motor_link2">
    <inertial>
      <origin xyz="0.00098879 0.034317 -0.034601"/>
      <mass value="1.2"/>
      <inertia ixx="8.8509E-05" ixy="3.7728E-06" ixz="4.584E-09" iyy="7.5337E-05" iyz="7.0145E-07" izz="0.00010162"/>
    </inertial>
    <visual>
      <origin rpy="0 0 3.141592653589793"/>
      <geometry>
        <mesh filename="package://galaxea_r1_description/meshes/steer_motor.obj"/>
      </geometry>
    </visual>
    <collision>
      <origin rpy="0 0 3.141592653589793"/>
      <geometry>
        <mesh filename="package://galaxea_r1_description/meshes/steer_motor.obj"/>
      </geometry>
    </collision>
  </link>
  <!-- Steer Motor Joint 2: Base to Steer Motor 2 -->
  <joint name="steer_motor_joint2" type="revolute">
    <origin xyz="0.21516 -0.28 0.12375"/>
    <parent link="base_link"/>
    <child link="steer_motor_link2"/>
    <axis xyz="0 0 1"/>
    <limit effort="44" lower="-1.5707963267948966" upper="1.5707963267948966" velocity="3.141592653589793"/>
  </joint>
  <!-- Wheel Motor Link 2 -->
  <link name="wheel_motor_link2">
    <inertial>
      <origin xyz="2.6199E-06 -0.0015607 1.6573E-07"/>
      <mass value="5"/>
      <inertia ixx="0.00089952" ixy="6.9163E-08" ixz="-7.5368E-10" iyy="0.0015854" iyz="-7.6749E-12" izz="0.00089958"/>
    </inertial>
    <visual>
      <geometry>
        <mesh filename="package://galaxea_r1_description/meshes/wheel_motor.obj"/>
      </geometry>
    </visual>
    <collision>
      <geometry>
        <mesh filename="package://galaxea_r1_description/meshes/wheel_motor.obj"/>
      </geometry>
    </collision>
  </link>
  <!-- Wheel Motor Joint 2: Steer Motor 2 to Wheel Motor 2 -->
  <joint name="wheel_motor_joint2" type="continuous">
    <origin xyz="0 0 -0.09525"/>
    <parent link="steer_motor_link2"/>
    <child link="wheel_motor_link2"/>
    <axis xyz="0 1 0"/>
  </joint>
  <!-- Steer Motor Link 3 -->
  <link name="steer_motor_link3">
    <inertial>
      <origin xyz="-0.00098879 -0.034317 -0.034601"/>
      <mass value="1.2"/>
      <inertia ixx="8.8509E-05" ixy="3.7728E-06" ixz="-4.584E-09" iyy="7.5337E-05" iyz="-7.0145E-07" izz="0.00010162"/>
    </inertial>
    <visual>
      <geometry>
        <mesh filename="package://galaxea_r1_description/meshes/steer_motor.obj"/>
      </geometry>
    </visual>
    <collision>
      <geometry>
        <mesh filename="package://galaxea_r1_description/meshes/steer_motor.obj"/>
      </geometry>
    </collision>
  </link>
  <!-- Steer Motor Joint 3: Base to Steer Motor 3 -->
  <joint name="steer_motor_joint3" type="revolute">
    <origin xyz="-0.28084 0 0.12375"/>
    <parent link="base_link"/>
    <child link="steer_motor_link3"/>
    <axis xyz="0 0 1"/>
    <limit effort="44" lower="-1.5707963267948966" upper="1.5707963267948966" velocity="3.141592653589793"/>
  </joint>
  <!-- Wheel Motor Link 3 -->
  <link name="wheel_motor_link3">
    <inertial>
      <origin xyz="2.6203E-06 0.0015607 -1.6564E-07"/>
      <mass value="5"/>
      <inertia ixx="0.00089952" ixy="-6.9072E-08" ixz="7.5036E-10" iyy="0.0015854" iyz="-7.845E-12" izz="0.00089958"/>
    </inertial>
    <visual>
      <geometry>
        <mesh filename="package://galaxea_r1_description/meshes/wheel_motor.obj"/>
      </geometry>
    </visual>
    <collision>
      <geometry>
        <mesh filename="package://galaxea_r1_description/meshes/wheel_motor.obj"/>
      </geometry>
    </collision>
  </link>
  <!-- Wheel Motor Joint 3: Steer Motor 3 to Wheel Motor 3 -->
  <joint name="wheel_motor_joint3" type="continuous">
    <origin rpy="0 0 3.141592653589793" xyz="0 0 -0.09525"/>
    <parent link="steer_motor_link3"/>
    <child link="wheel_motor_link3"/>
    <axis xyz="0 1 0"/>
  </joint>
  <!-- Torso Link 1 -->
  <link name="torso_link1">
    <inertial>
      <origin xyz="0.00065636 0.0032247 0.23142"/>
      <mass value="5.72"/>
      <inertia ixx="0.10931" ixy="7.7893E-06" ixz="-0.00017473" iyy="0.10736" iyz="0.00013763" izz="0.0081222"/>
    </inertial>
    <visual>
      <geometry>
        <mesh filename="package://galaxea_r1_description/meshes/torso_link1.obj"/>
      </geometry>
    </visual>
    <collision>
      <geometry>
        <mesh filename="package://galaxea_r1_description/meshes/torso_link1.obj"/>
      </geometry>
    </collision>
  </link>
  <!-- Torso Joint 1: Base to Torso 1 -->
  <joint name="torso_joint1" type="revolute">
    <origin xyz="-0.032845 0 0.301"/>
    <parent link="base_link"/>
    <child link="torso_link1"/>
    <axis xyz="0 1 0"/>
    <limit effort="500" lower="-1.1345" upper="1.8326" velocity="2.5"/>
  </joint>
  <!-- Torso Link 2 -->
  <link name="torso_link2">
    <inertial>
      <origin xyz="0.0052517 0.014412 0.15711"/>
      <mass value="3.5"/>
      <inertia ixx="0.026081" ixy="-3.3406E-07" ixz="0.00024541" iyy="0.027574" iyz="3.8474E-07" izz="0.0018515"/>
    </inertial>
    <visual>
      <geometry>
        <mesh filename="package://galaxea_r1_description/meshes/torso_link2.obj"/>
      </geometry>
    </visual>
    <collision>
      <geometry>
        <mesh filename="package://galaxea_r1_description/meshes/torso_link2.obj"/>
      </geometry>
    </collision>
  </link>
  <!-- Torso Joint 2: Torso 1 to Torso 2 -->
  <joint name="torso_joint2" type="revolute">
    <origin xyz="0 0 0.4"/>
    <parent link="torso_link1"/>
    <child link="torso_link2"/>
    <axis xyz="0 1 0"/>
    <limit effort="500" lower="-2.7925" upper="2.5307" velocity="2.5"/>
  </joint>
  <!-- Torso Link 3 -->
  <link name="torso_link3">
    <inertial>
      <origin xyz="-7.551E-06 -0.0092667 0.0042124"/>
      <mass value="3.4"/>
      <inertia ixx="0.0014058" ixy="3.5487E-07" ixz="9.0955E-08" iyy="0.0021992" iyz="1.6338E-05" izz="0.0013332"/>
    </inertial>
    <visual>
      <geometry>
        <mesh filename="package://galaxea_r1_description/meshes/torso_link3.obj"/>
      </geometry>
    </visual>
    <collision>
      <geometry>
        <mesh filename="package://galaxea_r1_description/meshes/torso_link3.obj"/>
      </geometry>
    </collision>
  </link>
  <!-- Torso Joint 3: Torso 2 to Torso 3 -->
  <joint name="torso_joint3" type="revolute">
    <origin xyz="0 0 0.3"/>
    <parent link="torso_link2"/>
    <child link="torso_link3"/>
    <axis xyz="0 -1 0"/>
    <limit effort="500" lower="-1.8326" upper="1.5707963267948966" velocity="2.5"/>
  </joint>
  <!-- Torso Link 4 -->
  <link name="torso_link4">
    <inertial>
      <origin xyz="-3.7511E-08 5.2756E-07 0.018688"/>
      <mass value="7.4"/>
      <inertia ixx="0.0014989" ixy="2.9183E-08" ixz="-7.7884E-10" iyy="0.001499" iyz="-1.2513E-10" izz="0.0019043"/>
    </inertial>
    <visual>
      <geometry>
        <mesh filename="package://galaxea_r1_description/meshes/torso_link4.obj"/>
      </geometry>
    </visual>
    <collision>
      <geometry>
        <mesh filename="package://galaxea_r1_description/meshes/torso_link4.obj"/>
      </geometry>
    </collision>
  </link>
  <!-- Torso Joint 4: Torso 3 to Torso 4 -->
  <joint name="torso_joint4" type="revolute">
    <origin xyz="0 0 0.09962"/>
    <parent link="torso_link3"/>
    <child link="torso_link4"/>
    <axis xyz="0 0 1"/>
    <limit effort="500" lower="-3.0543" upper="3.0543" velocity="2.5"/>
  </joint>
  <!-- ZED Camera Link -->
  <link name="zed_link">
    <inertial>
      <origin xyz="0.060004 0.015906 -0.068413"/>
      <mass value="2.05"/>
      <inertia ixx="0.010375" ixy="1.9044E-07" ixz="1.5997E-08" iyy="0.014618" iyz="0.00028961" izz="0.012229"/>
    </inertial>
    <visual>
      <geometry>
        <mesh filename="package://galaxea_r1_description/meshes/zed_link.obj"/>
      </geometry>
    </visual>
    <collision>
      <geometry>
        <mesh filename="package://galaxea_r1_description/meshes/zed_link.obj"/>
      </geometry>
    </collision>
  </link>
  <!-- ZED Joint: Torso 4 to ZED -->
  <joint name="zed_joint" type="fixed">
    <origin rpy="-1.9199 0 -1.5707963267948966" xyz="0.065512 0.060005 0.47598"/>
    <parent link="torso_link4"/>
    <child link="zed_link"/>
    <axis xyz="0 0 0"/>
  </joint>
  <!-- Base Link -->
  <link name="left_base_link">
    <inertial>
      <origin xyz="-0.0005634 0.038934 3.1874E-06"/>
      <mass value="1.658"/>
      <inertia ixx="0.0010597" ixy="1.9821E-05" ixz="-1.6752E-07" iyy="0.0011787" iyz="-1.9146E-07" izz="0.0010647"/>
    </inertial>
    <visual>
      <geometry>
        <mesh filename="package://galaxea_a1_description/meshes/a1/visual/base_link.obj"/>
      </geometry>
    </visual>
    <collision>
      <geometry>
        <mesh filename="package://galaxea_a1_description/meshes/a1/visual/base_link.obj"/>
      </geometry>
    </collision>
  </link>
  <!-- Link 1 -->
  <link name="left_link1">
    <inertial>
      <origin xyz="0.000015 0.105259 -0.001954"/>
      <mass value="1.164"/>
      <inertia ixx="0.001125" ixy="0.0" ixz="0.0" iyy="0.001084" iyz="-0.000023" izz="0.001158"/>
    </inertial>
    <visual>
      <geometry>
        <mesh filename="package://galaxea_a1_description/meshes/a1/visual/link1.obj"/>
      </geometry>
    </visual>
    <collision>
      <geometry>
        <mesh filename="package://galaxea_a1_description/meshes/a1/visual/link1.obj"/>
      </geometry>
    </collision>
  </link>
  <!-- Joint 1: Base to Link1 -->
  <joint name="left_joint1" type="revolute">
    <origin xyz="-0.0011147 0 0.0446"/>
    <parent link="left_base_link"/>
    <child link="left_link1"/>
    <axis xyz="0 0 1"/>
    <limit effort="100" lower="-2.8798" upper="2.8798" velocity="20.944"/>
  </joint>
  <!-- Link 2 -->
  <link name="left_link2">
    <inertial>
      <origin xyz="-0.23622 0.016352 -0.00013275"/>
      <mass value="1.3"/>
      <inertia ixx="0.00060638" ixy="0.00041817" ixz="0.00014956" iyy="0.0075936" iyz="-8.0916E-06" izz="0.0075712"/>
    </inertial>
    <visual>
      <geometry>
        <mesh filename="package://galaxea_a1_description/meshes/a1/visual/link2.obj"/>
      </geometry>
    </visual>
    <collision>
      <geometry>
        <mesh filename="package://galaxea_a1_description/meshes/a1/visual/link2.obj"/>
      </geometry>
    </collision>
  </link>
  <!-- Joint 2: Link1 to Link2 -->
  <joint name="left_joint2" type="revolute">
    <origin rpy="1.5707963267948966 0 0" xyz="0 0 0.1061"/>
    <parent link="left_link1"/>
    <child link="left_link2"/>
    <axis xyz="0 0 -1"/>
    <limit effort="100" lower="0" upper="3.2289" velocity="20.944"/>
  </joint>
  <!-- Link 3 -->
  <link name="left_link3">
    <inertial>
      <origin xyz="0.045114 0.054616 -0.00045593"/>
      <mass value="0.818"/>
      <inertia ixx="0.00060107" ixy="-0.00022467" ixz="-7.1194E-06" iyy="0.0013959" iyz="-9.7503E-06" izz="0.0015027"/>
    </inertial>
    <visual>
      <geometry>
        <mesh filename="package://galaxea_a1_description/meshes/a1/visual/link3.obj"/>
      </geometry>
    </visual>
    <collision>
      <geometry>
        <mesh filename="package://galaxea_a1_description/meshes/a1/visual/link3.obj"/>
      </geometry>
    </collision>
  </link>
  <!-- Joint 3: Link2 to Link3 -->
  <joint name="left_joint3" type="revolute">
    <origin xyz="-0.34928 0.019998 0"/>
    <parent link="left_link2"/>
    <child link="left_link3"/>
    <axis xyz="0 0 -1"/>
    <limit effort="100" lower="-3.3161" upper="0" velocity="7.5398"/>
  </joint>
  <!-- Link 4 -->
  <link name="left_link4">
    <inertial>
      <origin xyz="0.24285 0.0023784 1.279E-06"/>
      <mass value="0.698"/>
      <inertia ixx="8.45E-05" ixy="-8.2627E-07" ixz="-2.2607E-09" iyy="0.00010174" iyz="5.3612E-09" izz="9.7044E-05"/>
    </inertial>
    <visual>
      <geometry>
        <mesh filename="package://galaxea_a1_description/meshes/a1/visual/link4.obj"/>
      </geometry>
    </visual>
    <collision>
      <geometry>
        <mesh filename="package://galaxea_a1_description/meshes/a1/visual/link4.obj"/>
      </geometry>
    </collision>
  </link>
  <!-- Joint 4: Link3 to Link4 -->
  <joint name="left_joint4" type="revolute">
    <origin xyz="0.02735 0.069767 0"/>
    <parent link="left_link3"/>
    <child link="left_link4"/>
    <axis xyz="1 0 0"/>
    <limit effort="100" lower="-2.8798" upper="2.8798" velocity="25.133"/>
  </joint>
  <!-- Link 5 -->
  <link name="left_link5">
    <inertial>
      <origin xyz="0.054309 0.0041811 4.0699E-06"/>
      <mass value="0.417"/>
      <inertia ixx="8.3999E-05" ixy="1.6234E-05" ixz="7.4127E-08" iyy="9.8498E-05" iyz="-1.3811E-08" izz="0.00011333"/>
    </inertial>
    <visual>
      <geometry>
        <mesh filename="package://galaxea_a1_description/meshes/a1/visual/link5.obj"/>
      </geometry>
    </visual>
    <collision>
      <geometry>
        <mesh filename="package://galaxea_a1_description/meshes/a1/visual/link5.obj"/>
      </geometry>
    </collision>
  </link>
  <!-- Joint 5: Link4 to Link5 -->
  <joint name="left_joint5" type="revolute">
    <origin xyz="0.2463 -0.00049894 0"/>
    <parent link="left_link4"/>
    <child link="left_link5"/>
    <axis xyz="0 1 0"/>
    <limit effort="100" lower="-1.6581" upper="1.6581" velocity="25.133"/>
  </joint>
  <!-- Link 6 -->
  <link name="left_link6">
    <inertial>
      <origin xyz="0.028138 1.2134E-07 5.4049E-08"/>
      <mass value="0.037"/>
      <inertia ixx="3.5662E-06" ixy="6.6514E-12" ixz="2.9628E-12" iyy="2.0238E-06" iyz="-4.1666E-12" izz="2.0238E-06"/>
    </inertial>
    <visual>
      <geometry>
        <mesh filename="package://galaxea_a1_description/meshes/a1/visual/link6.obj"/>
      </geometry>
    </visual>
    <collision>
      <geometry>
        <mesh filename="package://galaxea_a1_description/meshes/a1/visual/link6.obj"/>
      </geometry>
    </collision>
  </link>
  <!-- Joint 6: Link5 to Link6 -->
  <joint name="left_joint6" type="revolute">
    <origin xyz="0.058249 0.00050025 0"/>
    <parent link="left_link5"/>
    <child link="left_link6"/>
    <axis xyz="1 0 0"/>
    <limit effort="100" lower="-2.8798" upper="2.8798" velocity="25.133"/>
  </joint>
  <link name="left_gripper_base">
    <inertial>
      <origin xyz="-0.0311072323899603 1.17979991887118E-08 7.93394685505433E-08"/>
      <mass value="0.604"/>
      <inertia ixx="0.000175881544189539" ixy="-6.06026450851008E-11" ixz="5.30643405624365E-10" iyy="9.86379407701341E-05" iyz="-8.18686692495892E-08" izz="0.000165121280580029"/>
    </inertial>
    <visual>
      <geometry>
        <mesh filename="package://galaxea_a1_description/meshes/gripper/gripper_link.obj"/>
      </geometry>
    </visual>
    <collision>
      <geometry>
        <mesh filename="package://galaxea_a1_description/meshes/gripper/gripper_link.obj"/>
      </geometry>
    </collision>
  </link>
  <link name="left_finger1">
    <inertial>
      <origin xyz="-0.0195895895552112 -0.0151136845490034 0.00542254359093075"/>
      <mass value="0.027"/>
      <inertia ixx="2.40569358477209E-06" ixy="3.9898459609048E-07" ixz="5.12152762183641E-08" iyy="5.71079298307516E-06" iyz="6.19467902008363E-08" izz="6.48482183930358E-06"/>
    </inertial>
    <visual>
      <geometry>
        <mesh filename="package://galaxea_a1_description/meshes/gripper/finger.obj"/>
      </geometry>
    </visual>
    <collision>
      <geometry>
        <mesh filename="package://galaxea_a1_description/meshes/gripper/finger.obj"/>
      </geometry>
    </collision>
  </link>
  <joint name="left_gripper_joint" type="prismatic">
    <origin xyz="0.03689 0.013453 0.00012059"/>
    <parent link="left_gripper_base"/>
    <child link="left_finger1"/>
    <axis xyz="0 1 0"/>
    <limit effort="100" lower="0" upper="0.05" velocity="0.25"/>
  </joint>
  <link name="left_finger2">
    <inertial>
      <origin xyz="-0.0195895857999098 0.0151136893508115 -0.00542254357246619"/>
      <mass value="0.027"/>
      <inertia ixx="2.40569340151687E-06" ixy="-3.98983784827124E-07" ixz="-5.12152683073981E-08" iyy="5.71079321589929E-06" iyz="6.19467953006536E-08" izz="6.48482187274222E-06"/>
    </inertial>
    <visual>
      <geometry>
        <mesh filename="package://galaxea_a1_description/meshes/gripper/finger.obj" scale="1 -1 -1"/>
      </geometry>
    </visual>
    <collision>
      <geometry>
        <mesh filename="package://galaxea_a1_description/meshes/gripper/finger.obj" scale="1 -1 -1"/>
      </geometry>
    </collision>
  </link>
  <joint name="left_gripper_joint2" type="prismatic">
    <origin xyz="0.03689 -0.013453 -0.00012059"/>
    <parent link="left_gripper_base"/>
    <child link="left_finger2"/>
    <axis xyz="0 -1 0"/>
    <limit effort="100" lower="0" upper="0.05" velocity="0.25"/>
    <mimic joint="left_gripper_joint" multiplier="1" offset="0"/>
  </joint>
  <link name="left_gripper_center"/>
  <joint name="left_gripper_center_joint" type="fixed">
    <origin xyz="0.03689 0 -0.00012059"/>
    <parent link="left_gripper_base"/>
    <child link="left_gripper_center"/>
  </joint>
  <origin rpy="0 0 0" xyz="0.1039 0 0"/>
  <!-- Gripper Base Joint -->
  <joint name="left_gripper_base_joint" type="fixed">
    <origin rpy="0 0 0" xyz="0.1039 0 0"/>
    <parent link="left_link6"/>
    <child link="left_gripper_base"/>
  </joint>
  <!-- Left Arm Base Joint: Torso 4 to Left Arm -->
  <joint name="left_arm_base_joint" type="fixed">
    <origin rpy="-1.5707963267948966 0 0" xyz="0.00077694 0.097234 0.30285"/>
    <parent link="torso_link4"/>
    <child link="left_base_link"/>
  </joint>
  <!-- RealSense Camera Link -->
  <link name="left_realsense_link">
    <inertial>
      <origin xyz="0.022169 0.0060171 -0.017353"/>
      <mass value="0.175"/>
      <inertia ixx="6.965E-06" ixy="2.6612E-06" ixz="1.2797E-06" iyy="2.3281E-05" iyz="-1.4268E-06" izz="2.5513E-05"/>
    </inertial>
    <visual>
      <geometry>
        <mesh filename="package://galaxea_r1_description/meshes/camera_link.obj"/>
      </geometry>
    </visual>
    <collision>
      <geometry>
        <mesh filename="package://galaxea_r1_description/meshes/camera_link.obj"/>
      </geometry>
    </collision>
  </link>
  <!-- RealSense Joint: Arm 6 to Camera -->
  <joint name="left_realsense_joint" type="fixed">
    <origin rpy="-2.0071 0.0077831 -1.5707963267948966" xyz="0.098768 0.0021071 0.05055"/>
    <parent link="left_link6"/>
    <child link="left_realsense_link"/>
  </joint>
  <!-- Base Link -->
  <link name="right_base_link">
    <inertial>
      <origin xyz="-0.0005634 0.038934 3.1874E-06"/>
      <mass value="1.658"/>
      <inertia ixx="0.0010597" ixy="1.9821E-05" ixz="-1.6752E-07" iyy="0.0011787" iyz="-1.9146E-07" izz="0.0010647"/>
    </inertial>
    <visual>
      <geometry>
        <mesh filename="package://galaxea_a1_description/meshes/a1/visual/base_link.obj"/>
      </geometry>
    </visual>
    <collision>
      <geometry>
        <mesh filename="package://galaxea_a1_description/meshes/a1/visual/base_link.obj"/>
      </geometry>
    </collision>
  </link>
  <!-- Link 1 -->
  <link name="right_link1">
    <inertial>
      <origin xyz="0.000015 0.105259 -0.001954"/>
      <mass value="1.164"/>
      <inertia ixx="0.001125" ixy="0.0" ixz="0.0" iyy="0.001084" iyz="-0.000023" izz="0.001158"/>
    </inertial>
    <visual>
      <geometry>
        <mesh filename="package://galaxea_a1_description/meshes/a1/visual/link1.obj"/>
      </geometry>
    </visual>
    <collision>
      <geometry>
        <mesh filename="package://galaxea_a1_description/meshes/a1/visual/link1.obj"/>
      </geometry>
    </collision>
  </link>
  <!-- Joint 1: Base to Link1 -->
  <joint name="right_joint1" type="revolute">
    <origin xyz="-0.0011147 0 0.0446"/>
    <parent link="right_base_link"/>
    <child link="right_link1"/>
    <axis xyz="0 0 1"/>
    <limit effort="100" lower="-2.8798" upper="2.8798" velocity="20.944"/>
  </joint>
  <!-- Link 2 -->
  <link name="right_link2">
    <inertial>
      <origin xyz="-0.23622 0.016352 -0.00013275"/>
      <mass value="1.3"/>
      <inertia ixx="0.00060638" ixy="0.00041817" ixz="0.00014956" iyy="0.0075936" iyz="-8.0916E-06" izz="0.0075712"/>
    </inertial>
    <visual>
      <geometry>
        <mesh filename="package://galaxea_a1_description/meshes/a1/visual/link2.obj"/>
      </geometry>
    </visual>
    <collision>
      <geometry>
        <mesh filename="package://galaxea_a1_description/meshes/a1/visual/link2.obj"/>
      </geometry>
    </collision>
  </link>
  <!-- Joint 2: Link1 to Link2 -->
  <joint name="right_joint2" type="revolute">
    <origin rpy="1.5707963267948966 0 0" xyz="0 0 0.1061"/>
    <parent link="right_link1"/>
    <child link="right_link2"/>
    <axis xyz="0 0 -1"/>
    <limit effort="100" lower="0" upper="3.2289" velocity="20.944"/>
  </joint>
  <!-- Link 3 -->
  <link name="right_link3">
    <inertial>
      <origin xyz="0.045114 0.054616 -0.00045593"/>
      <mass value="0.818"/>
      <inertia ixx="0.00060107" ixy="-0.00022467" ixz="-7.1194E-06" iyy="0.0013959" iyz="-9.7503E-06" izz="0.0015027"/>
    </inertial>
    <visual>
      <geometry>
        <mesh filename="package://galaxea_a1_description/meshes/a1/visual/link3.obj"/>
      </geometry>
    </visual>
    <collision>
      <geometry>
        <mesh filename="package://galaxea_a1_description/meshes/a1/visual/link3.obj"/>
      </geometry>
    </collision>
  </link>
  <!-- Joint 3: Link2 to Link3 -->
  <joint name="right_joint3" type="revolute">
    <origin xyz="-0.34928 0.019998 0"/>
    <parent link="right_link2"/>
    <child link="right_link3"/>
    <axis xyz="0 0 -1"/>
    <limit effort="100" lower="-3.3161" upper="0" velocity="7.5398"/>
  </joint>
  <!-- Link 4 -->
  <link name="right_link4">
    <inertial>
      <origin xyz="0.24285 0.0023784 1.279E-06"/>
      <mass value="0.698"/>
      <inertia ixx="8.45E-05" ixy="-8.2627E-07" ixz="-2.2607E-09" iyy="0.00010174" iyz="5.3612E-09" izz="9.7044E-05"/>
    </inertial>
    <visual>
      <geometry>
        <mesh filename="package://galaxea_a1_description/meshes/a1/visual/link4.obj"/>
      </geometry>
    </visual>
    <collision>
      <geometry>
        <mesh filename="package://galaxea_a1_description/meshes/a1/visual/link4.obj"/>
      </geometry>
    </collision>
  </link>
  <!-- Joint 4: Link3 to Link4 -->
  <joint name="right_joint4" type="revolute">
    <origin xyz="0.02735 0.069767 0"/>
    <parent link="right_link3"/>
    <child link="right_link4"/>
    <axis xyz="1 0 0"/>
    <limit effort="100" lower="-2.8798" upper="2.8798" velocity="25.133"/>
  </joint>
  <!-- Link 5 -->
  <link name="right_link5">
    <inertial>
      <origin xyz="0.054309 0.0041811 4.0699E-06"/>
      <mass value="0.417"/>
      <inertia ixx="8.3999E-05" ixy="1.6234E-05" ixz="7.4127E-08" iyy="9.8498E-05" iyz="-1.3811E-08" izz="0.00011333"/>
    </inertial>
    <visual>
      <geometry>
        <mesh filename="package://galaxea_a1_description/meshes/a1/visual/link5.obj"/>
      </geometry>
    </visual>
    <collision>
      <geometry>
        <mesh filename="package://galaxea_a1_description/meshes/a1/visual/link5.obj"/>
      </geometry>
    </collision>
  </link>
  <!-- Joint 5: Link4 to Link5 -->
  <joint name="right_joint5" type="revolute">
    <origin xyz="0.2463 -0.00049894 0"/>
    <parent link="right_link4"/>
    <child link="right_link5"/>
    <axis xyz="0 1 0"/>
    <limit effort="100" lower="-1.6581" upper="1.6581" velocity="25.133"/>
  </joint>
  <!-- Link 6 -->
  <link name="right_link6">
    <inertial>
      <origin xyz="0.028138 1.2134E-07 5.4049E-08"/>
      <mass value="0.037"/>
      <inertia ixx="3.5662E-06" ixy="6.6514E-12" ixz="2.9628E-12" iyy="2.0238E-06" iyz="-4.1666E-12" izz="2.0238E-06"/>
    </inertial>
    <visual>
      <geometry>
        <mesh filename="package://galaxea_a1_description/meshes/a1/visual/link6.obj"/>
      </geometry>
    </visual>
    <collision>
      <geometry>
        <mesh filename="package://galaxea_a1_description/meshes/a1/visual/link6.obj"/>
      </geometry>
    </collision>
  </link>
  <!-- Joint 6: Link5 to Link6 -->
  <joint name="right_joint6" type="revolute">
    <origin xyz="0.058249 0.00050025 0"/>
    <parent link="right_link5"/>
    <child link="right_link6"/>
    <axis xyz="1 0 0"/>
    <limit effort="100" lower="-2.8798" upper="2.8798" velocity="25.133"/>
  </joint>
  <link name="right_gripper_base">
    <inertial>
      <origin xyz="-0.0311072323899603 1.17979991887118E-08 7.93394685505433E-08"/>
      <mass value="0.604"/>
      <inertia ixx="0.000175881544189539" ixy="-6.06026450851008E-11" ixz="5.30643405624365E-10" iyy="9.86379407701341E-05" iyz="-8.18686692495892E-08" izz="0.000165121280580029"/>
    </inertial>
    <visual>
      <geometry>
        <mesh filename="package://galaxea_a1_description/meshes/gripper/gripper_link.obj"/>
      </geometry>
    </visual>
    <collision>
      <geometry>
        <mesh filename="package://galaxea_a1_description/meshes/gripper/gripper_link.obj"/>
      </geometry>
    </collision>
  </link>
  <link name="right_finger1">
    <inertial>
      <origin xyz="-0.0195895895552112 -0.0151136845490034 0.00542254359093075"/>
      <mass value="0.027"/>
      <inertia ixx="2.40569358477209E-06" ixy="3.9898459609048E-07" ixz="5.12152762183641E-08" iyy="5.71079298307516E-06" iyz="6.19467902008363E-08" izz="6.48482183930358E-06"/>
    </inertial>
    <visual>
      <geometry>
        <mesh filename="package://galaxea_a1_description/meshes/gripper/finger.obj"/>
      </geometry>
    </visual>
    <collision>
      <geometry>
        <mesh filename="package://galaxea_a1_description/meshes/gripper/finger.obj"/>
      </geometry>
    </collision>
  </link>
  <joint name="right_gripper_joint" type="prismatic">
    <origin xyz="0.03689 0.013453 0.00012059"/>
    <parent link="right_gripper_base"/>
    <child link="right_finger1"/>
    <axis xyz="0 1 0"/>
    <limit effort="100" lower="0" upper="0.05" velocity="0.25"/>
  </joint>
  <link name="right_finger2">
    <inertial>
      <origin xyz="-0.0195895857999098 0.0151136893508115 -0.00542254357246619"/>
      <mass value="0.027"/>
      <inertia ixx="2.40569340151687E-06" ixy="-3.98983784827124E-07" ixz="-5.12152683073981E-08" iyy="5.71079321589929E-06" iyz="6.19467953006536E-08" izz="6.48482187274222E-06"/>
    </inertial>
    <visual>
      <geometry>
        <mesh filename="package://galaxea_a1_description/meshes/gripper/finger.obj" scale="1 -1 -1"/>
      </geometry>
    </visual>
    <collision>
      <geometry>
        <mesh filename="package://galaxea_a1_description/meshes/gripper/finger.obj" scale="1 -1 -1"/>
      </geometry>
    </collision>
  </link>
  <joint name="right_gripper_joint2" type="prismatic">
    <origin xyz="0.03689 -0.013453 -0.00012059"/>
    <parent link="right_gripper_base"/>
    <child link="right_finger2"/>
    <axis xyz="0 -1 0"/>
    <limit effort="100" lower="0" upper="0.05" velocity="0.25"/>
    <mimic joint="right_gripper_joint" multiplier="1" offset="0"/>
  </joint>
  <link name="right_gripper_center"/>
  <joint name="right_gripper_center_joint" type="fixed">
    <origin xyz="0.03689 0 -0.00012059"/>
    <parent link="right_gripper_base"/>
    <child link="right_gripper_center"/>
  </joint>
  <origin rpy="3.141592653589793 0 0" xyz="0.1039 0 0"/>
  <!-- Gripper Base Joint -->
  <joint name="right_gripper_base_joint" type="fixed">
    <origin rpy="3.141592653589793 0 0" xyz="0.1039 0 0"/>
    <parent link="right_link6"/>
    <child link="right_gripper_base"/>
  </joint>
  <!-- Right Arm Base Joint: Torso 4 to Right Arm -->
  <joint name="right_arm_base_joint" type="fixed">
    <origin rpy="1.5707963267948966 0 0" xyz="0.00077778 -0.097235 0.30285"/>
    <parent link="torso_link4"/>
    <child link="right_base_link"/>
  </joint>
  <!-- RealSense Camera Link -->
  <link name="right_realsense_link">
    <inertial>
      <origin xyz="0.022169 0.0060171 -0.017353"/>
      <mass value="0.175"/>
      <inertia ixx="6.965E-06" ixy="2.6612E-06" ixz="1.2797E-06" iyy="2.3281E-05" iyz="-1.4268E-06" izz="2.5513E-05"/>
    </inertial>
    <visual>
      <geometry>
        <mesh filename="package://galaxea_r1_description/meshes/camera_link.obj"/>
      </geometry>
    </visual>
    <collision>
      <geometry>
        <mesh filename="package://galaxea_r1_description/meshes/camera_link.obj"/>
      </geometry>
    </collision>
  </link>
  <!-- RealSense Joint: Arm 6 to Camera -->
  <joint name="right_realsense_joint" type="fixed">
    <origin rpy="1.1344 -0.0077831 1.5707963267948966" xyz="0.098762 0.0021071 -0.05055"/>
    <parent link="right_link6"/>
    <child link="right_realsense_link"/>
  </joint>
</robot>
