<?xml version="1.0" encoding="utf-8"?>
<robot name="mmk2">
  <link name="base_link">
    <inertial>
      <origin xyz="-0.0400313721989715 -0.0226608008968248 0.756257223317173"/>
      <mass value="33.0267456398628"/>
      <inertia ixx="3.44838378637062" ixy="-0.00207943141138886" ixz="-0.0103091786755565" iyy="3.49493780774117"
               iyz="-0.00146679448998739" izz="0.21980548376876"/>
    </inertial>
    <visual>
      <geometry>
        <mesh filename="file://$(find airbot_mmk2_description)/meshes/base_link.obj"/>
      </geometry>
    </visual>
    <collision>
      <geometry>
        <mesh filename="file://$(find airbot_mmk2_description)/meshes/base_link.obj"/>
      </geometry>
    </collision>
  </link>

  <link name="lft_wheel_link">
    <inertial>
      <origin xyz="2.9309E-07 5.2077E-06 -0.029871"/>
      <mass value="1.1566"/>
      <inertia ixx="0.0021045" ixy="6.963E-10" ixz="-1.9831E-08" iyy="0.0021045" iyz="-3.5159E-07" izz="0.0035528"/>
    </inertial>
    <visual>
      <geometry>
        <mesh filename="file://$(find airbot_mmk2_description)/meshes/drive_wheel.obj"/>
      </geometry>
    </visual>
    <collision>
      <geometry>
        <mesh filename="file://$(find airbot_mmk2_description)/meshes/drive_wheel.obj"/>
      </geometry>
    </collision>
  </link>

  <joint name="lft_wheel_joint" type="continuous">
    <origin xyz="0 0.16325 0.08401" rpy="1.5708 1.5708 0"/>
    <parent link="base_link"/>
    <child link="lft_wheel_link"/>
    <axis xyz="0 0 -1"/>
  </joint>

  <link name="rgt_wheel_link">
    <inertial>
      <origin xyz="2.9312E-07 5.2196E-06 0.029871"/>
      <mass value="1.1566"/>
      <inertia ixx="0.0021045" ixy="-8.6762E-11" ixz="1.9824E-08" iyy="0.0021045" iyz="3.5159E-07" izz="0.0035528"/>
    </inertial>
    <visual>
      <geometry>
        <mesh filename="file://$(find airbot_mmk2_description)/meshes/drive_wheel.obj" scale="1 1 -1"/>
      </geometry>
    </visual>
    <collision>
      <geometry>
        <mesh filename="file://$(find airbot_mmk2_description)/meshes/drive_wheel.obj" scale="1 1 -1"/>
      </geometry>
    </collision>
  </link>

  <joint name="rgt_wheel_joint" type="continuous">
    <origin xyz="0 -0.16325 0.08401" rpy="1.5708 1.5708 0"/>
    <parent link="base_link"/>
    <child link="rgt_wheel_link"/>
    <axis xyz="0 0 -1"/>
  </joint>

  <link name="rgt_behind_wheel_link">
    <inertial>
      <origin xyz="0.0098797 -0.26998 -0.044087"/>
      <mass value="0.15002"/>
      <inertia ixx="0.00016534" ixy="1.4827E-07" ixz="-2.9264E-07" iyy="0.00014609" iyz="4.0633E-05" izz="9.3638E-05"/>
    </inertial>
    <visual>
      <geometry>
        <mesh filename="file://$(find airbot_mmk2_description)/meshes/support_wheel.obj"/>
      </geometry>
    </visual>
    <collision>
      <geometry>
        <mesh filename="file://$(find airbot_mmk2_description)/meshes/support_wheel.obj"/>
      </geometry>
    </collision>
  </link>

  <joint name="rgt_behind_wheel_joint" type="fixed">
    <origin xyz="-0.1315 0.1 0.097"/>
    <parent link="base_link"/>
    <child link="rgt_behind_wheel_link"/>
  </joint>

  <link name="lft_behind_wheel_link">
    <inertial>
      <origin xyz="-0.01012 -0.26998 -0.044087"/>
      <mass value="0.15002"/>
      <inertia ixx="0.00016534" ixy="1.4827E-07" ixz="-2.9264E-07" iyy="0.00014609" iyz="4.0633E-05" izz="9.3638E-05"/>
    </inertial>
    <visual>
      <geometry>
        <mesh filename="file://$(find airbot_mmk2_description)/meshes/support_wheel.obj"/>
      </geometry>
    </visual>
    <collision>
      <geometry>
        <mesh filename="file://$(find airbot_mmk2_description)/meshes/support_wheel.obj"/>
      </geometry>
    </collision>
  </link>

  <joint name="lft_behind_wheel_joint" type="fixed">
    <origin xyz="-0.1315 -0.1 0.097"/>
    <parent link="base_link"/>
    <child link="lft_behind_wheel_link"/>
  </joint>

  <link name="rgt_front_wheel_link">
    <inertial>
      <origin xyz="-0.01012 0.30602 -0.044087"/>
      <mass value="0.15002"/>
      <inertia ixx="0.00016534" ixy="1.4827E-07" ixz="-2.9264E-07" iyy="0.00014609" iyz="4.0633E-05" izz="9.3637E-05"/>
    </inertial>
    <visual>
      <geometry>
        <mesh filename="file://$(find airbot_mmk2_description)/meshes/support_wheel.obj"/>
      </geometry>
    </visual>
    <collision>
      <geometry>
        <mesh filename="file://$(find airbot_mmk2_description)/meshes/support_wheel.obj"/>
      </geometry>
    </collision>
  </link>

  <joint name="rgt_front_wheel_joint" type="fixed">
    <origin xyz="0.15482 -0.0895 0.097"/>
    <parent link="base_link"/>
    <child link="rgt_front_wheel_link"/>
  </joint>

  <link name="lft_front_wheel_link">
    <inertial>
      <origin xyz="0.0098797 0.30602 -0.044087"/>
      <mass value="0.15002"/>
      <inertia ixx="0.00016534" ixy="1.4827E-07" ixz="-2.9264E-07" iyy="0.00014609" iyz="4.0633E-05" izz="9.3637E-05"/>
    </inertial>
    <visual>
      <geometry>
        <mesh filename="file://$(find airbot_mmk2_description)/meshes/support_wheel.obj"/>
      </geometry>
    </visual>
    <collision>
      <geometry>
        <mesh filename="file://$(find airbot_mmk2_description)/meshes/support_wheel.obj"/>
      </geometry>
    </collision>
  </link>

  <joint name="lft_front_wheel_joint" type="fixed">
    <origin xyz="0.15482 0.0895 0.097"/>
    <parent link="base_link"/>
    <child link="lft_front_wheel_link"/>
  </joint>

  <link name="slide_link">
    <inertial>
      <origin xyz="-7.90494393625066E-05 0.067355217450789 0.10519083626064"/>
      <mass value="2.87043102920673"/>
      <inertia ixx="0.00899755064402379" ixy="6.09937870252811E-07" ixz="2.90775161414524E-06" iyy="0.0119634133355932"
               iyz="-0.000250919444280722" izz="0.00864817587777869"/>
    </inertial>
    <visual>
      <geometry>
        <mesh filename="file://$(find airbot_mmk2_description)/meshes/slide.obj"/>
      </geometry>
    </visual>
    <collision>
      <geometry>
        <mesh filename="file://$(find airbot_mmk2_description)/meshes/slide.obj"/>
      </geometry>
    </collision>
  </link>

  <joint name="slide_joint" type="prismatic">
    <origin xyz="0.033942 -0.00025 1.406" rpy="3.1416 0 1.5708"/>
    <parent link="base_link"/>
    <child link="slide_link"/>
    <axis xyz="0 0 1"/>
    <limit lower="-0.04" upper="0.87" effort="500" velocity="0.3"/>
  </joint>

  <link name="head_yaw_link">
    <inertial>
      <origin xyz="0.0118490941462296 0.000491254783341499 0.0390231494943873"/>
      <mass value="0.263127360420809"/>
      <inertia ixx="0.000185798854547827" ixy="2.64309797822853E-07" ixz="-2.93582511724902E-05"
               iyy="0.000173833362201622" iyz="-2.8054841555532E-06" izz="9.38655776831082E-05"/>
    </inertial>
    <visual>
      <geometry>
        <mesh filename="file://$(find airbot_mmk2_description)/meshes/head_yaw.obj"/>
      </geometry>

    </visual>
    <collision>
      <geometry>
        <mesh filename="file://$(find airbot_mmk2_description)/meshes/head_yaw.obj"/>
      </geometry>
    </collision>
  </link>

  <joint name="head_yaw_joint" type="revolute">
    <origin xyz="0 0.1735 0.07242" rpy="3.1416 0 0"/>
    <parent link="slide_link"/>
    <child link="head_yaw_link"/>
    <axis xyz="0 0 1"/>
    <limit lower="-0.5" upper="0.5" effort="2" velocity="0.2"/>
  </joint>

  <link name="head_pitch_link">
    <inertial>
      <origin xyz="0.0244659096221799 -0.108421751901101 -0.00311687659834824"/>
      <mass value="0.500765947013434"/>
      <inertia ixx="0.00157924187002826" ixy="2.16781765858799E-05" ixz="-1.02638171835218E-06"
               iyy="0.000804096450222595" iyz="1.48815549401623E-05" izz="0.00113048749298996"/>
    </inertial>
    <visual>
      <geometry>
        <mesh filename="file://$(find airbot_mmk2_description)/meshes/head_pitch.obj"/>
      </geometry>

    </visual>
    <collision>
      <geometry>
        <mesh filename="file://$(find airbot_mmk2_description)/meshes/head_pitch.obj"/>
      </geometry>
    </collision>
  </link>

  <joint name="head_pitch_joint" type="revolute">
    <origin xyz="0.00099952 3.1059E-05 0.058" rpy="-1.5708 0 -1.5397"/>
    <parent link="head_yaw_link"/>
    <child link="head_pitch_link"/>
    <axis xyz="0 0 1"/>
    <limit lower="-0.16" upper="1.18" effort="2" velocity="0.2"/>
  </joint>
</robot>